LAST SEEN   TYPE      REASON              OBJECT                         MESSAGE
7s          Normal    BackOff             pod/swebench-run-24406-12709   Back-off pulling image "us-central1-docker.pkg.dev/bsalmon-gke-dev/test-repo/sweperf:matplotlib__matplotlib-25311"
7s          Warning   Failed              pod/swebench-run-24406-12709   Error: ImagePullBackOff
19s         Normal    BackOff             pod/swebench-run-24407-32342   Back-off pulling image "us-central1-docker.pkg.dev/bsalmon-gke-dev/test-repo/sweperf:matplotlib__matplotlib-24970"
19s         Warning   Failed              pod/swebench-run-24407-32342   Error: ImagePullBackOff
11s         Normal    BackOff             pod/swebench-run-24408-13404   Back-off pulling image "us-central1-docker.pkg.dev/bsalmon-gke-dev/test-repo/sweperf:sympy__sympy-17139"
11s         Warning   Failed              pod/swebench-run-24408-13404   Error: ImagePullBackOff
10s         Normal    BackOff             pod/swebench-run-24409-10916   Back-off pulling image "us-central1-docker.pkg.dev/bsalmon-gke-dev/test-repo/sweperf:django__django-16899"
10s         Warning   Failed              pod/swebench-run-24409-10916   Error: ImagePullBackOff
9s          Normal    BackOff             pod/swebench-run-24410-15685   Back-off pulling image "us-central1-docker.pkg.dev/bsalmon-gke-dev/test-repo/sweperf:scikit-learn__scikit-learn-13142"
9s          Warning   Failed              pod/swebench-run-24410-15685   Error: ImagePullBackOff
12s         Normal    BackOff             pod/swebench-run-24411-17450   Back-off pulling image "us-central1-docker.pkg.dev/bsalmon-gke-dev/test-repo/sweperf:django__django-14315"
4m58s       Warning   Failed              pod/swebench-run-24411-17450   Error: ImagePullBackOff
3s          Normal    BackOff             pod/swebench-run-24412-12552   Back-off pulling image "us-central1-docker.pkg.dev/bsalmon-gke-dev/test-repo/sweperf:scikit-learn__scikit-learn-14629"
3s          Warning   Failed              pod/swebench-run-24412-12552   Error: ImagePullBackOff
4s          Normal    BackOff             pod/swebench-run-24413-28650   Back-off pulling image "us-central1-docker.pkg.dev/bsalmon-gke-dev/test-repo/sweperf:django__django-16429"
4m55s       Warning   Failed              pod/swebench-run-24413-28650   Error: ImagePullBackOff
11s         Normal    BackOff             pod/swebench-run-24414-4804    Back-off pulling image "us-central1-docker.pkg.dev/bsalmon-gke-dev/test-repo/sweperf:django__django-11400"
4m54s       Warning   Failed              pod/swebench-run-24414-4804    Error: ImagePullBackOff
5s          Normal    BackOff             pod/swebench-run-24415-1009    Back-off pulling image "us-central1-docker.pkg.dev/bsalmon-gke-dev/test-repo/sweperf:sphinx-doc__sphinx-8721"
4m57s       Warning   Failed              pod/swebench-run-24415-1009    Error: ImagePullBackOff
3m56s       Normal    BackOff             pod/swebench-run-24416-15644   Back-off pulling image "us-central1-docker.pkg.dev/bsalmon-gke-dev/test-repo/sweperf:django__django-12708"
4m48s       Warning   Failed              pod/swebench-run-24416-15644   Error: ImagePullBackOff
8s          Normal    BackOff             pod/swebench-run-24417-23703   Back-off pulling image "us-central1-docker.pkg.dev/bsalmon-gke-dev/test-repo/sweperf:django__django-12039"
4m52s       Warning   Failed              pod/swebench-run-24417-23703   Error: ImagePullBackOff
4m6s        Normal    BackOff             pod/swebench-run-24418-20899   Back-off pulling image "us-central1-docker.pkg.dev/bsalmon-gke-dev/test-repo/sweperf:django__django-16082"
4m44s       Warning   Failed              pod/swebench-run-24418-20899   Error: ImagePullBackOff
5s          Normal    BackOff             pod/swebench-run-24419-9260    Back-off pulling image "us-central1-docker.pkg.dev/bsalmon-gke-dev/test-repo/sweperf:django__django-15629"
4m49s       Warning   Failed              pod/swebench-run-24419-9260    Error: ImagePullBackOff
3m53s       Normal    BackOff             pod/swebench-run-24420-19870   Back-off pulling image "us-central1-docker.pkg.dev/bsalmon-gke-dev/test-repo/sweperf:pydata__xarray-4695"
4m43s       Warning   Failed              pod/swebench-run-24420-19870   Error: ImagePullBackOff
3s          Normal    BackOff             pod/swebench-run-24421-4731    Back-off pulling image "us-central1-docker.pkg.dev/bsalmon-gke-dev/test-repo/sweperf:django__django-17029"
4m44s       Warning   Failed              pod/swebench-run-24421-4731    Error: ImagePullBackOff
4m4s        Normal    BackOff             pod/swebench-run-24422-7677    Back-off pulling image "us-central1-docker.pkg.dev/bsalmon-gke-dev/test-repo/sweperf:pylint-dev__pylint-7277"
4m45s       Warning   Failed              pod/swebench-run-24422-7677    Error: ImagePullBackOff
1s          Normal    BackOff             pod/swebench-run-24423-14223   Back-off pulling image "us-central1-docker.pkg.dev/bsalmon-gke-dev/test-repo/sweperf:django__django-13315"
4m46s       Warning   Failed              pod/swebench-run-24423-14223   Error: ImagePullBackOff
3m51s       Normal    BackOff             pod/swebench-run-24424-23795   Back-off pulling image "us-central1-docker.pkg.dev/bsalmon-gke-dev/test-repo/sweperf:django__django-12193"
4m28s       Warning   Failed              pod/swebench-run-24424-23795   Error: ImagePullBackOff
3m44s       Normal    BackOff             pod/swebench-run-24425-25429   Back-off pulling image "us-central1-docker.pkg.dev/bsalmon-gke-dev/test-repo/sweperf:django__django-13807"
4m41s       Warning   Failed              pod/swebench-run-24425-25429   Error: ImagePullBackOff
3m43s       Warning   FailedScheduling    pod/swebench-run-24426-28028   0/1 nodes are available: 1 Too many pods. no new claims to deallocate, preemption: 0/1 nodes are available: 1 No preemption victims found for incoming pod.
6s          Normal    NotTriggerScaleUp   pod/swebench-run-24426-28028   Pod didn't trigger scale-up:
3m43s       Warning   FailedScheduling    pod/swebench-run-24427-29433   0/1 nodes are available: 1 Too many pods. no new claims to deallocate, preemption: 0/1 nodes are available: 1 No preemption victims found for incoming pod.
6s          Normal    NotTriggerScaleUp   pod/swebench-run-24427-29433   Pod didn't trigger scale-up:
3m43s       Warning   FailedScheduling    pod/swebench-run-24428-17830   0/1 nodes are available: 1 Too many pods. no new claims to deallocate, preemption: 0/1 nodes are available: 1 No preemption victims found for incoming pod.
6s          Normal    NotTriggerScaleUp   pod/swebench-run-24428-17830   Pod didn't trigger scale-up:
3m43s       Warning   FailedScheduling    pod/swebench-run-24429-28033   0/1 nodes are available: 1 Too many pods. no new claims to deallocate, preemption: 0/1 nodes are available: 1 No preemption victims found for incoming pod.
6s          Normal    NotTriggerScaleUp   pod/swebench-run-24429-28033   Pod didn't trigger scale-up:
3m43s       Warning   FailedScheduling    pod/swebench-run-24430-18871   0/1 nodes are available: 1 Too many pods. no new claims to deallocate, preemption: 0/1 nodes are available: 1 No preemption victims found for incoming pod.
6s          Normal    NotTriggerScaleUp   pod/swebench-run-24430-18871   Pod didn't trigger scale-up:
3m43s       Warning   FailedScheduling    pod/swebench-run-24431-15394   0/1 nodes are available: 1 Too many pods. no new claims to deallocate, preemption: 0/1 nodes are available: 1 No preemption victims found for incoming pod.
6s          Normal    NotTriggerScaleUp   pod/swebench-run-24431-15394   Pod didn't trigger scale-up:
3m43s       Warning   FailedScheduling    pod/swebench-run-24432-1629    0/1 nodes are available: 1 Too many pods. no new claims to deallocate, preemption: 0/1 nodes are available: 1 No preemption victims found for incoming pod.
6s          Normal    NotTriggerScaleUp   pod/swebench-run-24432-1629    Pod didn't trigger scale-up:
3m43s       Warning   FailedScheduling    pod/swebench-run-24433-12501   0/1 nodes are available: 1 Too many pods. no new claims to deallocate, preemption: 0/1 nodes are available: 1 No preemption victims found for incoming pod.
6s          Normal    NotTriggerScaleUp   pod/swebench-run-24433-12501   Pod didn't trigger scale-up:
3m44s       Warning   FailedScheduling    pod/swebench-run-24434-22407   0/1 nodes are available: 1 Too many pods. no new claims to deallocate, preemption: 0/1 nodes are available: 1 No preemption victims found for incoming pod.
6s          Normal    NotTriggerScaleUp   pod/swebench-run-24434-22407   Pod didn't trigger scale-up:
3m43s       Warning   FailedScheduling    pod/swebench-run-24435-20533   0/1 nodes are available: 1 Too many pods. no new claims to deallocate, preemption: 0/1 nodes are available: 1 No preemption victims found for incoming pod.
6s          Normal    NotTriggerScaleUp   pod/swebench-run-24435-20533   Pod didn't trigger scale-up:
3m43s       Warning   FailedScheduling    pod/swebench-run-24436-18862   0/1 nodes are available: 1 Too many pods. no new claims to deallocate, preemption: 0/1 nodes are available: 1 No preemption victims found for incoming pod.
6s          Normal    NotTriggerScaleUp   pod/swebench-run-24436-18862   Pod didn't trigger scale-up:
3m43s       Warning   FailedScheduling    pod/swebench-run-24437-3029    0/1 nodes are available: 1 Too many pods. no new claims to deallocate, preemption: 0/1 nodes are available: 1 No preemption victims found for incoming pod.
5m1s        Normal    NotTriggerScaleUp   pod/swebench-run-24437-3029    Pod didn't trigger scale-up:
3m43s       Warning   FailedScheduling    pod/swebench-run-24438-15737   0/1 nodes are available: 1 Too many pods. no new claims to deallocate, preemption: 0/1 nodes are available: 1 No preemption victims found for incoming pod.
5m1s        Normal    NotTriggerScaleUp   pod/swebench-run-24438-15737   Pod didn't trigger scale-up:
3m43s       Warning   FailedScheduling    pod/swebench-run-24439-16701   0/1 nodes are available: 1 Too many pods. no new claims to deallocate, preemption: 0/1 nodes are available: 1 No preemption victims found for incoming pod.
5m1s        Normal    NotTriggerScaleUp   pod/swebench-run-24439-16701   Pod didn't trigger scale-up:
3m43s       Warning   FailedScheduling    pod/swebench-run-24440-13359   0/1 nodes are available: 1 Too many pods. no new claims to deallocate, preemption: 0/1 nodes are available: 1 No preemption victims found for incoming pod.
5m1s        Normal    NotTriggerScaleUp   pod/swebench-run-24440-13359   Pod didn't trigger scale-up:
3m43s       Warning   FailedScheduling    pod/swebench-run-24441-6323    0/1 nodes are available: 1 Too many pods. no new claims to deallocate, preemption: 0/1 nodes are available: 1 No preemption victims found for incoming pod.
5m1s        Normal    NotTriggerScaleUp   pod/swebench-run-24441-6323    Pod didn't trigger scale-up:
3m43s       Warning   FailedScheduling    pod/swebench-run-24442-27976   0/1 nodes are available: 1 Too many pods. no new claims to deallocate, preemption: 0/1 nodes are available: 1 No preemption victims found for incoming pod.
5m1s        Normal    NotTriggerScaleUp   pod/swebench-run-24442-27976   Pod didn't trigger scale-up:
3m43s       Warning   FailedScheduling    pod/swebench-run-24443-16939   0/1 nodes are available: 1 Too many pods. no new claims to deallocate, preemption: 0/1 nodes are available: 1 No preemption victims found for incoming pod.
5m1s        Normal    NotTriggerScaleUp   pod/swebench-run-24443-16939   Pod didn't trigger scale-up:
3m43s       Warning   FailedScheduling    pod/swebench-run-24444-12103   0/1 nodes are available: 1 Too many pods. no new claims to deallocate, preemption: 0/1 nodes are available: 1 No preemption victims found for incoming pod.
5m1s        Normal    NotTriggerScaleUp   pod/swebench-run-24444-12103   Pod didn't trigger scale-up:
3m43s       Warning   FailedScheduling    pod/swebench-run-24445-12376   0/1 nodes are available: 1 Too many pods. no new claims to deallocate, preemption: 0/1 nodes are available: 1 No preemption victims found for incoming pod.
5m1s        Normal    NotTriggerScaleUp   pod/swebench-run-24445-12376   Pod didn't trigger scale-up:
3m43s       Warning   FailedScheduling    pod/swebench-run-24446-17177   0/1 nodes are available: 1 Too many pods. no new claims to deallocate, preemption: 0/1 nodes are available: 1 No preemption victims found for incoming pod.
5m1s        Normal    NotTriggerScaleUp   pod/swebench-run-24446-17177   Pod didn't trigger scale-up:
3m43s       Warning   FailedScheduling    pod/swebench-run-24447-11591   0/1 nodes are available: 1 Too many pods. no new claims to deallocate, preemption: 0/1 nodes are available: 1 No preemption victims found for incoming pod.
5m1s        Normal    NotTriggerScaleUp   pod/swebench-run-24447-11591   Pod didn't trigger scale-up:
3m43s       Warning   FailedScheduling    pod/swebench-run-24448-22703   0/1 nodes are available: 1 Too many pods. no new claims to deallocate, preemption: 0/1 nodes are available: 1 No preemption victims found for incoming pod.
5m1s        Normal    NotTriggerScaleUp   pod/swebench-run-24448-22703   Pod didn't trigger scale-up:
3m43s       Warning   FailedScheduling    pod/swebench-run-24449-7984    0/1 nodes are available: 1 Too many pods. no new claims to deallocate, preemption: 0/1 nodes are available: 1 No preemption victims found for incoming pod.
5m1s        Normal    NotTriggerScaleUp   pod/swebench-run-24449-7984    Pod didn't trigger scale-up:
3m43s       Warning   FailedScheduling    pod/swebench-run-24450-2609    0/1 nodes are available: 1 Too many pods. no new claims to deallocate, preemption: 0/1 nodes are available: 1 No preemption victims found for incoming pod.
5m1s        Normal    NotTriggerScaleUp   pod/swebench-run-24450-2609    Pod didn't trigger scale-up:
3m43s       Warning   FailedScheduling    pod/swebench-run-24451-9673    0/1 nodes are available: 1 Too many pods. no new claims to deallocate, preemption: 0/1 nodes are available: 1 No preemption victims found for incoming pod.
5m1s        Normal    NotTriggerScaleUp   pod/swebench-run-24451-9673    Pod didn't trigger scale-up:
3m43s       Warning   FailedScheduling    pod/swebench-run-24452-27632   0/1 nodes are available: 1 Too many pods. no new claims to deallocate, preemption: 0/1 nodes are available: 1 No preemption victims found for incoming pod.
5m1s        Normal    NotTriggerScaleUp   pod/swebench-run-24452-27632   Pod didn't trigger scale-up:
3m43s       Warning   FailedScheduling    pod/swebench-run-24453-19916   0/1 nodes are available: 1 Too many pods. no new claims to deallocate, preemption: 0/1 nodes are available: 1 No preemption victims found for incoming pod.
5m1s        Normal    NotTriggerScaleUp   pod/swebench-run-24453-19916   Pod didn't trigger scale-up:
3m43s       Warning   FailedScheduling    pod/swebench-run-24454-25743   0/1 nodes are available: 1 Too many pods. no new claims to deallocate, preemption: 0/1 nodes are available: 1 No preemption victims found for incoming pod.
5m1s        Normal    NotTriggerScaleUp   pod/swebench-run-24454-25743   Pod didn't trigger scale-up:
3m43s       Warning   FailedScheduling    pod/swebench-run-24455-23424   0/1 nodes are available: 1 Too many pods. no new claims to deallocate, preemption: 0/1 nodes are available: 1 No preemption victims found for incoming pod.
5m1s        Normal    NotTriggerScaleUp   pod/swebench-run-24455-23424   Pod didn't trigger scale-up:
11s         Normal    BackOff             pod/swebench-run-24456-15416   Back-off pulling image "us-central1-docker.pkg.dev/bsalmon-gke-dev/test-repo/sweperf:django__django-14725"
11s         Warning   Failed              pod/swebench-run-24456-15416   Error: ImagePullBackOff
17s         Normal    BackOff             pod/swebench-run-24457-12909   Back-off pulling image "us-central1-docker.pkg.dev/bsalmon-gke-dev/test-repo/sweperf:scikit-learn__scikit-learn-14087"
17s         Warning   Failed              pod/swebench-run-24457-12909   Error: ImagePullBackOff
9s          Normal    BackOff             pod/swebench-run-24458-31659   Back-off pulling image "us-central1-docker.pkg.dev/bsalmon-gke-dev/test-repo/sweperf:django__django-15022"
5m5s        Warning   Failed              pod/swebench-run-24458-31659   Error: ImagePullBackOff
4s          Normal    BackOff             pod/swebench-run-24459-29513   Back-off pulling image "us-central1-docker.pkg.dev/bsalmon-gke-dev/test-repo/sweperf:django__django-13794"
4s          Warning   Failed              pod/swebench-run-24459-29513   Error: ImagePullBackOff
4s          Normal    BackOff             pod/swebench-run-24460-26292   Back-off pulling image "us-central1-docker.pkg.dev/bsalmon-gke-dev/test-repo/sweperf:psf__requests-6028"
4s          Warning   Failed              pod/swebench-run-24460-26292   Error: ImagePullBackOff
7s          Normal    BackOff             pod/swebench-run-24461-21558   Back-off pulling image "us-central1-docker.pkg.dev/bsalmon-gke-dev/test-repo/sweperf:pydata__xarray-4695"
5m1s        Warning   Failed              pod/swebench-run-24461-21558   Error: ImagePullBackOff
7s          Normal    BackOff             pod/swebench-run-24462-19461   Back-off pulling image "us-central1-docker.pkg.dev/bsalmon-gke-dev/test-repo/sweperf:django__django-11555"
4m51s       Warning   Failed              pod/swebench-run-24462-19461   Error: ImagePullBackOff
4s          Normal    BackOff             pod/swebench-run-24463-16066   Back-off pulling image "us-central1-docker.pkg.dev/bsalmon-gke-dev/test-repo/sweperf:matplotlib__matplotlib-24570"
4m50s       Warning   Failed              pod/swebench-run-24463-16066   Error: ImagePullBackOff
8s          Normal    BackOff             pod/swebench-run-24464-5735    Back-off pulling image "us-central1-docker.pkg.dev/bsalmon-gke-dev/test-repo/sweperf:django__django-14089"
4m47s       Warning   Failed              pod/swebench-run-24464-5735    Error: ImagePullBackOff
3s          Normal    BackOff             pod/swebench-run-24465-17290   Back-off pulling image "us-central1-docker.pkg.dev/bsalmon-gke-dev/test-repo/sweperf:django__django-15315"
4m54s       Warning   Failed              pod/swebench-run-24465-17290   Error: ImagePullBackOff
2s          Normal    BackOff             pod/swebench-run-24466-9929    Back-off pulling image "us-central1-docker.pkg.dev/bsalmon-gke-dev/test-repo/sweperf:sphinx-doc__sphinx-9658"
4m46s       Warning   Failed              pod/swebench-run-24466-9929    Error: ImagePullBackOff
1s          Normal    BackOff             pod/swebench-run-24467-8555    Back-off pulling image "us-central1-docker.pkg.dev/bsalmon-gke-dev/test-repo/sweperf:astropy__astropy-8707"
4m37s       Warning   Failed              pod/swebench-run-24467-8555    Error: ImagePullBackOff
3m58s       Normal    BackOff             pod/swebench-run-24468-14388   Back-off pulling image "us-central1-docker.pkg.dev/bsalmon-gke-dev/test-repo/sweperf:django__django-13363"
4m52s       Warning   Failed              pod/swebench-run-24468-14388   Error: ImagePullBackOff
4m8s        Normal    BackOff             pod/swebench-run-24469-6110    Back-off pulling image "us-central1-docker.pkg.dev/bsalmon-gke-dev/test-repo/sweperf:sphinx-doc__sphinx-8265"
4m43s       Warning   Failed              pod/swebench-run-24469-6110    Error: ImagePullBackOff
3s          Normal    BackOff             pod/swebench-run-24470-29190   Back-off pulling image "us-central1-docker.pkg.dev/bsalmon-gke-dev/test-repo/sweperf:django__django-12039"
4m44s       Warning   Failed              pod/swebench-run-24470-29190   Error: ImagePullBackOff
2s          Normal    BackOff             pod/swebench-run-24471-8809    Back-off pulling image "us-central1-docker.pkg.dev/bsalmon-gke-dev/test-repo/sweperf:django__django-11728"
4m26s       Warning   Failed              pod/swebench-run-24471-8809    Error: ImagePullBackOff
1s          Normal    BackOff             pod/swebench-run-24472-3661    Back-off pulling image "us-central1-docker.pkg.dev/bsalmon-gke-dev/test-repo/sweperf:sympy__sympy-16597"
4m34s       Warning   Failed              pod/swebench-run-24472-3661    Error: ImagePullBackOff
3m55s       Normal    BackOff             pod/swebench-run-24473-24695   Back-off pulling image "us-central1-docker.pkg.dev/bsalmon-gke-dev/test-repo/sweperf:django__django-16116"
4m32s       Warning   Failed              pod/swebench-run-24473-24695   Error: ImagePullBackOff
3m43s       Warning   FailedScheduling    pod/swebench-run-24474-4573    0/1 nodes are available: 1 Too many pods. no new claims to deallocate, preemption: 0/1 nodes are available: 1 No preemption victims found for incoming pod.
6s          Normal    NotTriggerScaleUp   pod/swebench-run-24474-4573    Pod didn't trigger scale-up:
3m43s       Warning   FailedScheduling    pod/swebench-run-24475-5329    0/1 nodes are available: 1 Too many pods. no new claims to deallocate, preemption: 0/1 nodes are available: 1 No preemption victims found for incoming pod.
6s          Normal    NotTriggerScaleUp   pod/swebench-run-24475-5329    Pod didn't trigger scale-up:
3m43s       Warning   FailedScheduling    pod/swebench-run-24476-21141   0/1 nodes are available: 1 Too many pods. no new claims to deallocate, preemption: 0/1 nodes are available: 1 No preemption victims found for incoming pod.
6s          Normal    NotTriggerScaleUp   pod/swebench-run-24476-21141   Pod didn't trigger scale-up:
3m43s       Warning   FailedScheduling    pod/swebench-run-24477-381     0/1 nodes are available: 1 Too many pods. no new claims to deallocate, preemption: 0/1 nodes are available: 1 No preemption victims found for incoming pod.
6s          Normal    NotTriggerScaleUp   pod/swebench-run-24477-381     Pod didn't trigger scale-up:
3m43s       Warning   FailedScheduling    pod/swebench-run-24478-9540    0/1 nodes are available: 1 Too many pods. no new claims to deallocate, preemption: 0/1 nodes are available: 1 No preemption victims found for incoming pod.
6s          Normal    NotTriggerScaleUp   pod/swebench-run-24478-9540    Pod didn't trigger scale-up:
3m43s       Warning   FailedScheduling    pod/swebench-run-24479-13270   0/1 nodes are available: 1 Too many pods. no new claims to deallocate, preemption: 0/1 nodes are available: 1 No preemption victims found for incoming pod.
6s          Normal    NotTriggerScaleUp   pod/swebench-run-24479-13270   Pod didn't trigger scale-up:
3m43s       Warning   FailedScheduling    pod/swebench-run-24480-32672   0/1 nodes are available: 1 Too many pods. no new claims to deallocate, preemption: 0/1 nodes are available: 1 No preemption victims found for incoming pod.
6s          Normal    NotTriggerScaleUp   pod/swebench-run-24480-32672   Pod didn't trigger scale-up:
3m41s       Normal    BackOff             pod/swebench-run-24481-9468    Back-off pulling image "us-central1-docker.pkg.dev/bsalmon-gke-dev/test-repo/sweperf:sympy__sympy-22714"
4m19s       Warning   Failed              pod/swebench-run-24481-9468    Error: ImagePullBackOff
3m43s       Warning   FailedScheduling    pod/swebench-run-24482-24161   0/1 nodes are available: 1 Too many pods. no new claims to deallocate, preemption: 0/1 nodes are available: 1 No preemption victims found for incoming pod.
6s          Normal    NotTriggerScaleUp   pod/swebench-run-24482-24161   Pod didn't trigger scale-up:
3m43s       Warning   FailedScheduling    pod/swebench-run-24483-32388   0/1 nodes are available: 1 Too many pods. no new claims to deallocate, preemption: 0/1 nodes are available: 1 No preemption victims found for incoming pod.
6s          Normal    NotTriggerScaleUp   pod/swebench-run-24483-32388   Pod didn't trigger scale-up:
3m43s       Warning   FailedScheduling    pod/swebench-run-24484-12326   0/1 nodes are available: 1 Too many pods. no new claims to deallocate, preemption: 0/1 nodes are available: 1 No preemption victims found for incoming pod.
6s          Normal    NotTriggerScaleUp   pod/swebench-run-24484-12326   Pod didn't trigger scale-up:
3m43s       Warning   FailedScheduling    pod/swebench-run-24485-16440   0/1 nodes are available: 1 Too many pods. no new claims to deallocate, preemption: 0/1 nodes are available: 1 No preemption victims found for incoming pod.
6s          Normal    NotTriggerScaleUp   pod/swebench-run-24485-16440   Pod didn't trigger scale-up:
3m43s       Warning   FailedScheduling    pod/swebench-run-24486-18560   0/1 nodes are available: 1 Too many pods. no new claims to deallocate, preemption: 0/1 nodes are available: 1 No preemption victims found for incoming pod.
6s          Normal    NotTriggerScaleUp   pod/swebench-run-24486-18560   Pod didn't trigger scale-up:
3m43s       Warning   FailedScheduling    pod/swebench-run-24487-802     0/1 nodes are available: 1 Too many pods. no new claims to deallocate, preemption: 0/1 nodes are available: 1 No preemption victims found for incoming pod.
5m1s        Normal    NotTriggerScaleUp   pod/swebench-run-24487-802     Pod didn't trigger scale-up:
3m43s       Warning   FailedScheduling    pod/swebench-run-24488-26839   0/1 nodes are available: 1 Too many pods. no new claims to deallocate, preemption: 0/1 nodes are available: 1 No preemption victims found for incoming pod.
5m1s        Normal    NotTriggerScaleUp   pod/swebench-run-24488-26839   Pod didn't trigger scale-up:
3m43s       Warning   FailedScheduling    pod/swebench-run-24489-6093    0/1 nodes are available: 1 Too many pods. no new claims to deallocate, preemption: 0/1 nodes are available: 1 No preemption victims found for incoming pod.
5m1s        Normal    NotTriggerScaleUp   pod/swebench-run-24489-6093    Pod didn't trigger scale-up:
3m43s       Warning   FailedScheduling    pod/swebench-run-24490-5789    0/1 nodes are available: 1 Too many pods. no new claims to deallocate, preemption: 0/1 nodes are available: 1 No preemption victims found for incoming pod.
5m1s        Normal    NotTriggerScaleUp   pod/swebench-run-24490-5789    Pod didn't trigger scale-up:
3m43s       Warning   FailedScheduling    pod/swebench-run-24491-25181   0/1 nodes are available: 1 Too many pods. no new claims to deallocate, preemption: 0/1 nodes are available: 1 No preemption victims found for incoming pod.
5m1s        Normal    NotTriggerScaleUp   pod/swebench-run-24491-25181   Pod didn't trigger scale-up:
3m43s       Warning   FailedScheduling    pod/swebench-run-24492-22300   0/1 nodes are available: 1 Too many pods. no new claims to deallocate, preemption: 0/1 nodes are available: 1 No preemption victims found for incoming pod.
5m1s        Normal    NotTriggerScaleUp   pod/swebench-run-24492-22300   Pod didn't trigger scale-up:
3m43s       Warning   FailedScheduling    pod/swebench-run-24493-7469    0/1 nodes are available: 1 Too many pods. no new claims to deallocate, preemption: 0/1 nodes are available: 1 No preemption victims found for incoming pod.
5m1s        Normal    NotTriggerScaleUp   pod/swebench-run-24493-7469    Pod didn't trigger scale-up:
3m43s       Warning   FailedScheduling    pod/swebench-run-24494-25461   0/1 nodes are available: 1 Too many pods. no new claims to deallocate, preemption: 0/1 nodes are available: 1 No preemption victims found for incoming pod.
5m1s        Normal    NotTriggerScaleUp   pod/swebench-run-24494-25461   Pod didn't trigger scale-up:
3m43s       Warning   FailedScheduling    pod/swebench-run-24495-32015   0/1 nodes are available: 1 Too many pods. no new claims to deallocate, preemption: 0/1 nodes are available: 1 No preemption victims found for incoming pod.
5m1s        Normal    NotTriggerScaleUp   pod/swebench-run-24495-32015   Pod didn't trigger scale-up:
3m43s       Warning   FailedScheduling    pod/swebench-run-24496-17796   0/1 nodes are available: 1 Too many pods. no new claims to deallocate, preemption: 0/1 nodes are available: 1 No preemption victims found for incoming pod.
5m1s        Normal    NotTriggerScaleUp   pod/swebench-run-24496-17796   Pod didn't trigger scale-up:
3m43s       Warning   FailedScheduling    pod/swebench-run-24497-24839   0/1 nodes are available: 1 Too many pods. no new claims to deallocate, preemption: 0/1 nodes are available: 1 No preemption victims found for incoming pod.
5m1s        Normal    NotTriggerScaleUp   pod/swebench-run-24497-24839   Pod didn't trigger scale-up:
3m43s       Warning   FailedScheduling    pod/swebench-run-24498-3604    0/1 nodes are available: 1 Too many pods. no new claims to deallocate, preemption: 0/1 nodes are available: 1 No preemption victims found for incoming pod.
5m1s        Normal    NotTriggerScaleUp   pod/swebench-run-24498-3604    Pod didn't trigger scale-up:
3m43s       Warning   FailedScheduling    pod/swebench-run-24499-18553   0/1 nodes are available: 1 Too many pods. no new claims to deallocate, preemption: 0/1 nodes are available: 1 No preemption victims found for incoming pod.
5m1s        Normal    NotTriggerScaleUp   pod/swebench-run-24499-18553   Pod didn't trigger scale-up:
3m43s       Warning   FailedScheduling    pod/swebench-run-24500-28233   0/1 nodes are available: 1 Too many pods. no new claims to deallocate, preemption: 0/1 nodes are available: 1 No preemption victims found for incoming pod.
4m51s       Normal    NotTriggerScaleUp   pod/swebench-run-24500-28233   Pod didn't trigger scale-up:
3m43s       Warning   FailedScheduling    pod/swebench-run-24501-707     0/1 nodes are available: 1 Too many pods. no new claims to deallocate, preemption: 0/1 nodes are available: 1 No preemption victims found for incoming pod.
5m1s        Normal    NotTriggerScaleUp   pod/swebench-run-24501-707     Pod didn't trigger scale-up:
3m43s       Warning   FailedScheduling    pod/swebench-run-24502-26451   0/1 nodes are available: 1 Too many pods. no new claims to deallocate, preemption: 0/1 nodes are available: 1 No preemption victims found for incoming pod.
5m1s        Normal    NotTriggerScaleUp   pod/swebench-run-24502-26451   Pod didn't trigger scale-up:
3m43s       Warning   FailedScheduling    pod/swebench-run-24503-9119    0/1 nodes are available: 1 Too many pods. no new claims to deallocate, preemption: 0/1 nodes are available: 1 No preemption victims found for incoming pod.
5m1s        Normal    NotTriggerScaleUp   pod/swebench-run-24503-9119    Pod didn't trigger scale-up:
3m43s       Warning   FailedScheduling    pod/swebench-run-24504-9491    0/1 nodes are available: 1 Too many pods. no new claims to deallocate, preemption: 0/1 nodes are available: 1 No preemption victims found for incoming pod.
5m1s        Normal    NotTriggerScaleUp   pod/swebench-run-24504-9491    Pod didn't trigger scale-up:
3m43s       Warning   FailedScheduling    pod/swebench-run-24505-8099    0/1 nodes are available: 1 Too many pods. no new claims to deallocate, preemption: 0/1 nodes are available: 1 No preemption victims found for incoming pod.
5m1s        Normal    NotTriggerScaleUp   pod/swebench-run-24505-8099    Pod didn't trigger scale-up:
17s         Normal    BackOff             pod/swebench-run-24506-10843   Back-off pulling image "us-central1-docker.pkg.dev/bsalmon-gke-dev/test-repo/sweperf:django__django-11551"
4s          Warning   Failed              pod/swebench-run-24506-10843   Error: ImagePullBackOff
9s          Normal    BackOff             pod/swebench-run-24507-15138   Back-off pulling image "us-central1-docker.pkg.dev/bsalmon-gke-dev/test-repo/sweperf:django__django-17084"
9s          Warning   Failed              pod/swebench-run-24507-15138   Error: ImagePullBackOff
13s         Normal    BackOff             pod/swebench-run-24508-25568   Back-off pulling image "us-central1-docker.pkg.dev/bsalmon-gke-dev/test-repo/sweperf:sphinx-doc__sphinx-7757"
2s          Warning   Failed              pod/swebench-run-24508-25568   Error: ImagePullBackOff
10s         Normal    BackOff             pod/swebench-run-24509-18787   Back-off pulling image "us-central1-docker.pkg.dev/bsalmon-gke-dev/test-repo/sweperf:pallets__flask-5014"
4m55s       Warning   Failed              pod/swebench-run-24509-18787   Error: ImagePullBackOff
9s          Normal    BackOff             pod/swebench-run-24510-622     Back-off pulling image "us-central1-docker.pkg.dev/bsalmon-gke-dev/test-repo/sweperf:pydata__xarray-3993"
5m1s        Warning   Failed              pod/swebench-run-24510-622     Error: ImagePullBackOff
8s          Normal    BackOff             pod/swebench-run-24511-29911   Back-off pulling image "us-central1-docker.pkg.dev/bsalmon-gke-dev/test-repo/sweperf:django__django-13569"
4m49s       Warning   Failed              pod/swebench-run-24511-29911   Error: ImagePullBackOff
2s          Normal    BackOff             pod/swebench-run-24512-20208   Back-off pulling image "us-central1-docker.pkg.dev/bsalmon-gke-dev/test-repo/sweperf:scikit-learn__scikit-learn-25747"
4m52s       Warning   Failed              pod/swebench-run-24512-20208   Error: ImagePullBackOff
5s          Normal    BackOff             pod/swebench-run-24513-10585   Back-off pulling image "us-central1-docker.pkg.dev/bsalmon-gke-dev/test-repo/sweperf:sympy__sympy-15599"
4m49s       Warning   Failed              pod/swebench-run-24513-10585   Error: ImagePullBackOff
4m6s        Normal    BackOff             pod/swebench-run-24514-919     Back-off pulling image "us-central1-docker.pkg.dev/bsalmon-gke-dev/test-repo/sweperf:sympy__sympy-15976"
4m43s       Warning   Failed              pod/swebench-run-24514-919     Error: ImagePullBackOff
4s          Normal    BackOff             pod/swebench-run-24515-6728    Back-off pulling image "us-central1-docker.pkg.dev/bsalmon-gke-dev/test-repo/sweperf:django__django-15525"
4m54s       Warning   Failed              pod/swebench-run-24515-6728    Error: ImagePullBackOff
0s          Normal    BackOff             pod/swebench-run-24516-9742    Back-off pulling image "us-central1-docker.pkg.dev/bsalmon-gke-dev/test-repo/sweperf:sphinx-doc__sphinx-7748"
4m45s       Warning   Failed              pod/swebench-run-24516-9742    Error: ImagePullBackOff
2s          Normal    BackOff             pod/swebench-run-24517-4506    Back-off pulling image "us-central1-docker.pkg.dev/bsalmon-gke-dev/test-repo/sweperf:matplotlib__matplotlib-24570"
4m49s       Warning   Failed              pod/swebench-run-24517-4506    Error: ImagePullBackOff
3m45s       Normal    BackOff             pod/swebench-run-24518-18331   Back-off pulling image "us-central1-docker.pkg.dev/bsalmon-gke-dev/test-repo/sweperf:django__django-13810"
4m38s       Warning   Failed              pod/swebench-run-24518-18331   Error: ImagePullBackOff
3m53s       Normal    BackOff             pod/swebench-run-24519-31914   Back-off pulling image "us-central1-docker.pkg.dev/bsalmon-gke-dev/test-repo/sweperf:django__django-13279"
4m32s       Warning   Failed              pod/swebench-run-24519-31914   Error: ImagePullBackOff
1s          Normal    BackOff             pod/swebench-run-24520-16021   Back-off pulling image "us-central1-docker.pkg.dev/bsalmon-gke-dev/test-repo/sweperf:matplotlib__matplotlib-25122"
4m33s       Warning   Failed              pod/swebench-run-24520-16021   Error: ImagePullBackOff
3m56s       Normal    BackOff             pod/swebench-run-24521-23827   Back-off pulling image "us-central1-docker.pkg.dev/bsalmon-gke-dev/test-repo/sweperf:sympy__sympy-13551"
4m30s       Warning   Failed              pod/swebench-run-24521-23827   Error: ImagePullBackOff
3m45s       Normal    BackOff             pod/swebench-run-24522-16702   Back-off pulling image "us-central1-docker.pkg.dev/bsalmon-gke-dev/test-repo/sweperf:sympy__sympy-21612"
4m24s       Warning   Failed              pod/swebench-run-24522-16702   Error: ImagePullBackOff
3m43s       Warning   FailedScheduling    pod/swebench-run-24523-32245   0/1 nodes are available: 1 Too many pods. no new claims to deallocate, preemption: 0/1 nodes are available: 1 No preemption victims found for incoming pod.
6s          Normal    NotTriggerScaleUp   pod/swebench-run-24523-32245   Pod didn't trigger scale-up:
6s          Normal    NotTriggerScaleUp   pod/swebench-run-24524-25434   Pod didn't trigger scale-up:
3m43s       Warning   FailedScheduling    pod/swebench-run-24524-25434   0/1 nodes are available: 1 Too many pods. no new claims to deallocate, preemption: 0/1 nodes are available: 1 No preemption victims found for incoming pod.
3m43s       Warning   FailedScheduling    pod/swebench-run-24525-26479   0/1 nodes are available: 1 Too many pods. no new claims to deallocate, preemption: 0/1 nodes are available: 1 No preemption victims found for incoming pod.
6s          Normal    NotTriggerScaleUp   pod/swebench-run-24525-26479   Pod didn't trigger scale-up:
3m43s       Warning   FailedScheduling    pod/swebench-run-24526-10483   0/1 nodes are available: 1 Too many pods. no new claims to deallocate, preemption: 0/1 nodes are available: 1 No preemption victims found for incoming pod.
6s          Normal    NotTriggerScaleUp   pod/swebench-run-24526-10483   Pod didn't trigger scale-up:
3m43s       Warning   FailedScheduling    pod/swebench-run-24527-14973   0/1 nodes are available: 1 Too many pods. no new claims to deallocate, preemption: 0/1 nodes are available: 1 No preemption victims found for incoming pod.
6s          Normal    NotTriggerScaleUp   pod/swebench-run-24527-14973   Pod didn't trigger scale-up:
3m43s       Warning   FailedScheduling    pod/swebench-run-24528-2908    0/1 nodes are available: 1 Too many pods. no new claims to deallocate, preemption: 0/1 nodes are available: 1 No preemption victims found for incoming pod.
6s          Normal    NotTriggerScaleUp   pod/swebench-run-24528-2908    Pod didn't trigger scale-up:
3m43s       Warning   FailedScheduling    pod/swebench-run-24529-11539   0/1 nodes are available: 1 Too many pods. no new claims to deallocate, preemption: 0/1 nodes are available: 1 No preemption victims found for incoming pod.
6s          Normal    NotTriggerScaleUp   pod/swebench-run-24529-11539   Pod didn't trigger scale-up:
3m44s       Warning   FailedScheduling    pod/swebench-run-24530-28358   0/1 nodes are available: 1 Too many pods. no new claims to deallocate, preemption: 0/1 nodes are available: 1 No preemption victims found for incoming pod.
6s          Normal    NotTriggerScaleUp   pod/swebench-run-24530-28358   Pod didn't trigger scale-up:
3m43s       Warning   FailedScheduling    pod/swebench-run-24531-21630   0/1 nodes are available: 1 Too many pods. no new claims to deallocate, preemption: 0/1 nodes are available: 1 No preemption victims found for incoming pod.
6s          Normal    NotTriggerScaleUp   pod/swebench-run-24531-21630   Pod didn't trigger scale-up:
3m43s       Warning   FailedScheduling    pod/swebench-run-24532-12850   0/1 nodes are available: 1 Too many pods. no new claims to deallocate, preemption: 0/1 nodes are available: 1 No preemption victims found for incoming pod.
5m1s        Normal    NotTriggerScaleUp   pod/swebench-run-24532-12850   Pod didn't trigger scale-up:
3m43s       Warning   FailedScheduling    pod/swebench-run-24533-19264   0/1 nodes are available: 1 Too many pods. no new claims to deallocate, preemption: 0/1 nodes are available: 1 No preemption victims found for incoming pod.
5m1s        Normal    NotTriggerScaleUp   pod/swebench-run-24533-19264   Pod didn't trigger scale-up:
3m43s       Warning   FailedScheduling    pod/swebench-run-24534-30004   0/1 nodes are available: 1 Too many pods. no new claims to deallocate, preemption: 0/1 nodes are available: 1 No preemption victims found for incoming pod.
6s          Normal    NotTriggerScaleUp   pod/swebench-run-24534-30004   Pod didn't trigger scale-up:
3m43s       Warning   FailedScheduling    pod/swebench-run-24535-19501   0/1 nodes are available: 1 Too many pods. no new claims to deallocate, preemption: 0/1 nodes are available: 1 No preemption victims found for incoming pod.
5m1s        Normal    NotTriggerScaleUp   pod/swebench-run-24535-19501   Pod didn't trigger scale-up:
3m43s       Warning   FailedScheduling    pod/swebench-run-24536-29602   0/1 nodes are available: 1 Too many pods. no new claims to deallocate, preemption: 0/1 nodes are available: 1 No preemption victims found for incoming pod.
5m1s        Normal    NotTriggerScaleUp   pod/swebench-run-24536-29602   Pod didn't trigger scale-up:
3m43s       Warning   FailedScheduling    pod/swebench-run-24537-4797    0/1 nodes are available: 1 Too many pods. no new claims to deallocate, preemption: 0/1 nodes are available: 1 No preemption victims found for incoming pod.
5m1s        Normal    NotTriggerScaleUp   pod/swebench-run-24537-4797    Pod didn't trigger scale-up:
3m43s       Warning   FailedScheduling    pod/swebench-run-24538-22055   0/1 nodes are available: 1 Too many pods. no new claims to deallocate, preemption: 0/1 nodes are available: 1 No preemption victims found for incoming pod.
5m1s        Normal    NotTriggerScaleUp   pod/swebench-run-24538-22055   Pod didn't trigger scale-up:
3m43s       Warning   FailedScheduling    pod/swebench-run-24539-26493   0/1 nodes are available: 1 Too many pods. no new claims to deallocate, preemption: 0/1 nodes are available: 1 No preemption victims found for incoming pod.
5m1s        Normal    NotTriggerScaleUp   pod/swebench-run-24539-26493   Pod didn't trigger scale-up:
3m43s       Warning   FailedScheduling    pod/swebench-run-24540-13585   0/1 nodes are available: 1 Too many pods. no new claims to deallocate, preemption: 0/1 nodes are available: 1 No preemption victims found for incoming pod.
5m1s        Normal    NotTriggerScaleUp   pod/swebench-run-24540-13585   Pod didn't trigger scale-up:
3m43s       Warning   FailedScheduling    pod/swebench-run-24541-6788    0/1 nodes are available: 1 Too many pods. no new claims to deallocate, preemption: 0/1 nodes are available: 1 No preemption victims found for incoming pod.
5m1s        Normal    NotTriggerScaleUp   pod/swebench-run-24541-6788    Pod didn't trigger scale-up:
3m43s       Warning   FailedScheduling    pod/swebench-run-24542-4023    0/1 nodes are available: 1 Too many pods. no new claims to deallocate, preemption: 0/1 nodes are available: 1 No preemption victims found for incoming pod.
5m1s        Normal    NotTriggerScaleUp   pod/swebench-run-24542-4023    Pod didn't trigger scale-up:
3m43s       Warning   FailedScheduling    pod/swebench-run-24543-25540   0/1 nodes are available: 1 Too many pods. no new claims to deallocate, preemption: 0/1 nodes are available: 1 No preemption victims found for incoming pod.
5m1s        Normal    NotTriggerScaleUp   pod/swebench-run-24543-25540   Pod didn't trigger scale-up:
3m43s       Warning   FailedScheduling    pod/swebench-run-24544-28172   0/1 nodes are available: 1 Too many pods. no new claims to deallocate, preemption: 0/1 nodes are available: 1 No preemption victims found for incoming pod.
5m1s        Normal    NotTriggerScaleUp   pod/swebench-run-24544-28172   Pod didn't trigger scale-up:
3m43s       Warning   FailedScheduling    pod/swebench-run-24545-18790   0/1 nodes are available: 1 Too many pods. no new claims to deallocate, preemption: 0/1 nodes are available: 1 No preemption victims found for incoming pod.
5m1s        Normal    NotTriggerScaleUp   pod/swebench-run-24545-18790   Pod didn't trigger scale-up:
3m43s       Warning   FailedScheduling    pod/swebench-run-24546-30943   0/1 nodes are available: 1 Too many pods. no new claims to deallocate, preemption: 0/1 nodes are available: 1 No preemption victims found for incoming pod.
5m1s        Normal    NotTriggerScaleUp   pod/swebench-run-24546-30943   Pod didn't trigger scale-up:
3m43s       Warning   FailedScheduling    pod/swebench-run-24547-513     0/1 nodes are available: 1 Too many pods. no new claims to deallocate, preemption: 0/1 nodes are available: 1 No preemption victims found for incoming pod.
5m1s        Normal    NotTriggerScaleUp   pod/swebench-run-24547-513     Pod didn't trigger scale-up:
3m43s       Warning   FailedScheduling    pod/swebench-run-24548-15240   0/1 nodes are available: 1 Too many pods. no new claims to deallocate, preemption: 0/1 nodes are available: 1 No preemption victims found for incoming pod.
5m1s        Normal    NotTriggerScaleUp   pod/swebench-run-24548-15240   Pod didn't trigger scale-up:
3m43s       Warning   FailedScheduling    pod/swebench-run-24549-31680   0/1 nodes are available: 1 Too many pods. no new claims to deallocate, preemption: 0/1 nodes are available: 1 No preemption victims found for incoming pod.
5m1s        Normal    NotTriggerScaleUp   pod/swebench-run-24549-31680   Pod didn't trigger scale-up:
3m43s       Warning   FailedScheduling    pod/swebench-run-24550-8191    0/1 nodes are available: 1 Too many pods. no new claims to deallocate, preemption: 0/1 nodes are available: 1 No preemption victims found for incoming pod.
5m1s        Normal    NotTriggerScaleUp   pod/swebench-run-24550-8191    Pod didn't trigger scale-up:
3m43s       Warning   FailedScheduling    pod/swebench-run-24551-17135   0/1 nodes are available: 1 Too many pods. no new claims to deallocate, preemption: 0/1 nodes are available: 1 No preemption victims found for incoming pod.
5m1s        Normal    NotTriggerScaleUp   pod/swebench-run-24551-17135   Pod didn't trigger scale-up:
3m43s       Warning   FailedScheduling    pod/swebench-run-24552-17140   0/1 nodes are available: 1 Too many pods. no new claims to deallocate, preemption: 0/1 nodes are available: 1 No preemption victims found for incoming pod.
5m1s        Normal    NotTriggerScaleUp   pod/swebench-run-24552-17140   Pod didn't trigger scale-up:
3m43s       Warning   FailedScheduling    pod/swebench-run-24553-15414   0/1 nodes are available: 1 Too many pods. no new claims to deallocate, preemption: 0/1 nodes are available: 1 No preemption victims found for incoming pod.
5m1s        Normal    NotTriggerScaleUp   pod/swebench-run-24553-15414   Pod didn't trigger scale-up:
3m43s       Warning   FailedScheduling    pod/swebench-run-24554-1516    0/1 nodes are available: 1 Too many pods. no new claims to deallocate, preemption: 0/1 nodes are available: 1 No preemption victims found for incoming pod.
5m1s        Normal    NotTriggerScaleUp   pod/swebench-run-24554-1516    Pod didn't trigger scale-up:
3m43s       Warning   FailedScheduling    pod/swebench-run-24555-12254   0/1 nodes are available: 1 Too many pods. no new claims to deallocate, preemption: 0/1 nodes are available: 1 No preemption victims found for incoming pod.
5m1s        Normal    NotTriggerScaleUp   pod/swebench-run-24555-12254   Pod didn't trigger scale-up:
17s         Normal    BackOff             pod/swebench-run-24556-19187   Back-off pulling image "us-central1-docker.pkg.dev/bsalmon-gke-dev/test-repo/sweperf:django__django-14404"
3s          Warning   Failed              pod/swebench-run-24556-19187   Error: ImagePullBackOff
4m1s        Normal    Pulling             pod/swebench-run-24557-8931    Pulling image "us-central1-docker.pkg.dev/bsalmon-gke-dev/test-repo/sweperf:django__django-14539"
12s         Normal    BackOff             pod/swebench-run-24557-8931    Back-off pulling image "us-central1-docker.pkg.dev/bsalmon-gke-dev/test-repo/sweperf:django__django-14539"
4m54s       Warning   Failed              pod/swebench-run-24557-8931    Error: ImagePullBackOff
7s          Normal    BackOff             pod/swebench-run-24558-1700    Back-off pulling image "us-central1-docker.pkg.dev/bsalmon-gke-dev/test-repo/sweperf:django__django-15268"
5m3s        Warning   Failed              pod/swebench-run-24558-1700    Error: ImagePullBackOff
4s          Normal    BackOff             pod/swebench-run-24559-18327   Back-off pulling image "us-central1-docker.pkg.dev/bsalmon-gke-dev/test-repo/sweperf:sympy__sympy-16886"
4m49s       Warning   Failed              pod/swebench-run-24559-18327   Error: ImagePullBackOff
0s          Normal    BackOff             pod/swebench-run-24560-27990   Back-off pulling image "us-central1-docker.pkg.dev/bsalmon-gke-dev/test-repo/sweperf:scikit-learn__scikit-learn-13135"
0s          Warning   Failed              pod/swebench-run-24560-27990   Error: ImagePullBackOff
7s          Normal    BackOff             pod/swebench-run-24561-640     Back-off pulling image "us-central1-docker.pkg.dev/bsalmon-gke-dev/test-repo/sweperf:sympy__sympy-17318"
4m52s       Warning   Failed              pod/swebench-run-24561-640     Error: ImagePullBackOff
8s          Normal    BackOff             pod/swebench-run-24562-14731   Back-off pulling image "us-central1-docker.pkg.dev/bsalmon-gke-dev/test-repo/sweperf:sphinx-doc__sphinx-9673"
4m57s       Warning   Failed              pod/swebench-run-24562-14731   Error: ImagePullBackOff
3m56s       Normal    BackOff             pod/swebench-run-24563-8452    Back-off pulling image "us-central1-docker.pkg.dev/bsalmon-gke-dev/test-repo/sweperf:django__django-13028"
4m44s       Warning   Failed              pod/swebench-run-24563-8452    Error: ImagePullBackOff
1s          Normal    BackOff             pod/swebench-run-24564-13182   Back-off pulling image "us-central1-docker.pkg.dev/bsalmon-gke-dev/test-repo/sweperf:pydata__xarray-4695"
4m50s       Warning   Failed              pod/swebench-run-24564-13182   Error: ImagePullBackOff
4m10s       Normal    BackOff             pod/swebench-run-24565-12754   Back-off pulling image "us-central1-docker.pkg.dev/bsalmon-gke-dev/test-repo/sweperf:sympy__sympy-18189"
4m48s       Warning   Failed              pod/swebench-run-24565-12754   Error: ImagePullBackOff
2s          Normal    BackOff             pod/swebench-run-24566-5956    Back-off pulling image "us-central1-docker.pkg.dev/bsalmon-gke-dev/test-repo/sweperf:matplotlib__matplotlib-23314"
4m44s       Warning   Failed              pod/swebench-run-24566-5956    Error: ImagePullBackOff
0s          Normal    BackOff             pod/swebench-run-24567-21909   Back-off pulling image "us-central1-docker.pkg.dev/bsalmon-gke-dev/test-repo/sweperf:django__django-11333"
4m47s       Warning   Failed              pod/swebench-run-24567-21909   Error: ImagePullBackOff
3m58s       Normal    BackOff             pod/swebench-run-24568-12076   Back-off pulling image "us-central1-docker.pkg.dev/bsalmon-gke-dev/test-repo/sweperf:pydata__xarray-3095"
4m40s       Warning   Failed              pod/swebench-run-24568-12076   Error: ImagePullBackOff
3m56s       Normal    BackOff             pod/swebench-run-24569-10069   Back-off pulling image "us-central1-docker.pkg.dev/bsalmon-gke-dev/test-repo/sweperf:django__django-12713"
4m36s       Warning   Failed              pod/swebench-run-24569-10069   Error: ImagePullBackOff
3m43s       Warning   FailedScheduling    pod/swebench-run-24570-7551    0/1 nodes are available: 1 Too many pods. no new claims to deallocate, preemption: 0/1 nodes are available: 1 No preemption victims found for incoming pod.
6s          Normal    NotTriggerScaleUp   pod/swebench-run-24570-7551    Pod didn't trigger scale-up:
3m43s       Warning   FailedScheduling    pod/swebench-run-24571-3085    0/1 nodes are available: 1 Too many pods. no new claims to deallocate, preemption: 0/1 nodes are available: 1 No preemption victims found for incoming pod.
6s          Normal    NotTriggerScaleUp   pod/swebench-run-24571-3085    Pod didn't trigger scale-up:
3m43s       Warning   FailedScheduling    pod/swebench-run-24572-31750   0/1 nodes are available: 1 Too many pods. no new claims to deallocate, preemption: 0/1 nodes are available: 1 No preemption victims found for incoming pod.
6s          Normal    NotTriggerScaleUp   pod/swebench-run-24572-31750   Pod didn't trigger scale-up:
6s          Normal    NotTriggerScaleUp   pod/swebench-run-24573-4123    Pod didn't trigger scale-up:
3m43s       Warning   FailedScheduling    pod/swebench-run-24573-4123    0/1 nodes are available: 1 Too many pods. no new claims to deallocate, preemption: 0/1 nodes are available: 1 No preemption victims found for incoming pod.
3m43s       Warning   FailedScheduling    pod/swebench-run-24574-5675    0/1 nodes are available: 1 Too many pods. no new claims to deallocate, preemption: 0/1 nodes are available: 1 No preemption victims found for incoming pod.
6s          Normal    NotTriggerScaleUp   pod/swebench-run-24574-5675    Pod didn't trigger scale-up:
6s          Normal    NotTriggerScaleUp   pod/swebench-run-24575-5137    Pod didn't trigger scale-up:
3m43s       Warning   FailedScheduling    pod/swebench-run-24575-5137    0/1 nodes are available: 1 Too many pods. no new claims to deallocate, preemption: 0/1 nodes are available: 1 No preemption victims found for incoming pod.
3m43s       Warning   FailedScheduling    pod/swebench-run-24576-9905    0/1 nodes are available: 1 Too many pods. no new claims to deallocate, preemption: 0/1 nodes are available: 1 No preemption victims found for incoming pod.
6s          Normal    NotTriggerScaleUp   pod/swebench-run-24576-9905    Pod didn't trigger scale-up:
6s          Normal    NotTriggerScaleUp   pod/swebench-run-24577-18813   Pod didn't trigger scale-up:
3m43s       Warning   FailedScheduling    pod/swebench-run-24577-18813   0/1 nodes are available: 1 Too many pods. no new claims to deallocate, preemption: 0/1 nodes are available: 1 No preemption victims found for incoming pod.
3m44s       Warning   FailedScheduling    pod/swebench-run-24578-18665   0/1 nodes are available: 1 Too many pods. no new claims to deallocate, preemption: 0/1 nodes are available: 1 No preemption victims found for incoming pod.
6s          Normal    NotTriggerScaleUp   pod/swebench-run-24578-18665   Pod didn't trigger scale-up:
3m43s       Warning   FailedScheduling    pod/swebench-run-24579-21123   0/1 nodes are available: 1 Too many pods. no new claims to deallocate, preemption: 0/1 nodes are available: 1 No preemption victims found for incoming pod.
6s          Normal    NotTriggerScaleUp   pod/swebench-run-24579-21123   Pod didn't trigger scale-up:
3m43s       Warning   FailedScheduling    pod/swebench-run-24580-18640   0/1 nodes are available: 1 Too many pods. no new claims to deallocate, preemption: 0/1 nodes are available: 1 No preemption victims found for incoming pod.
5m1s        Normal    NotTriggerScaleUp   pod/swebench-run-24580-18640   Pod didn't trigger scale-up:
3m43s       Warning   FailedScheduling    pod/swebench-run-24581-26404   0/1 nodes are available: 1 Too many pods. no new claims to deallocate, preemption: 0/1 nodes are available: 1 No preemption victims found for incoming pod.
5m1s        Normal    NotTriggerScaleUp   pod/swebench-run-24581-26404   Pod didn't trigger scale-up:
3m43s       Warning   FailedScheduling    pod/swebench-run-24582-1501    0/1 nodes are available: 1 Too many pods. no new claims to deallocate, preemption: 0/1 nodes are available: 1 No preemption victims found for incoming pod.
5m1s        Normal    NotTriggerScaleUp   pod/swebench-run-24582-1501    Pod didn't trigger scale-up:
3m43s       Warning   FailedScheduling    pod/swebench-run-24583-11392   0/1 nodes are available: 1 Too many pods. no new claims to deallocate, preemption: 0/1 nodes are available: 1 No preemption victims found for incoming pod.
5m1s        Normal    NotTriggerScaleUp   pod/swebench-run-24583-11392   Pod didn't trigger scale-up:
3m43s       Warning   FailedScheduling    pod/swebench-run-24584-14661   0/1 nodes are available: 1 Too many pods. no new claims to deallocate, preemption: 0/1 nodes are available: 1 No preemption victims found for incoming pod.
5m1s        Normal    NotTriggerScaleUp   pod/swebench-run-24584-14661   Pod didn't trigger scale-up:
3m43s       Warning   FailedScheduling    pod/swebench-run-24585-10787   0/1 nodes are available: 1 Too many pods. no new claims to deallocate, preemption: 0/1 nodes are available: 1 No preemption victims found for incoming pod.
5m1s        Normal    NotTriggerScaleUp   pod/swebench-run-24585-10787   Pod didn't trigger scale-up:
3m43s       Warning   FailedScheduling    pod/swebench-run-24586-11510   0/1 nodes are available: 1 Too many pods. no new claims to deallocate, preemption: 0/1 nodes are available: 1 No preemption victims found for incoming pod.
5m1s        Normal    NotTriggerScaleUp   pod/swebench-run-24586-11510   Pod didn't trigger scale-up:
3m43s       Warning   FailedScheduling    pod/swebench-run-24587-8096    0/1 nodes are available: 1 Too many pods. no new claims to deallocate, preemption: 0/1 nodes are available: 1 No preemption victims found for incoming pod.
5m1s        Normal    NotTriggerScaleUp   pod/swebench-run-24587-8096    Pod didn't trigger scale-up:
3m43s       Warning   FailedScheduling    pod/swebench-run-24588-8307    0/1 nodes are available: 1 Too many pods. no new claims to deallocate, preemption: 0/1 nodes are available: 1 No preemption victims found for incoming pod.
5m1s        Normal    NotTriggerScaleUp   pod/swebench-run-24588-8307    Pod didn't trigger scale-up:
3m43s       Warning   FailedScheduling    pod/swebench-run-24589-31477   0/1 nodes are available: 1 Too many pods. no new claims to deallocate, preemption: 0/1 nodes are available: 1 No preemption victims found for incoming pod.
5m1s        Normal    NotTriggerScaleUp   pod/swebench-run-24589-31477   Pod didn't trigger scale-up:
3m43s       Warning   FailedScheduling    pod/swebench-run-24590-27331   0/1 nodes are available: 1 Too many pods. no new claims to deallocate, preemption: 0/1 nodes are available: 1 No preemption victims found for incoming pod.
5m1s        Normal    NotTriggerScaleUp   pod/swebench-run-24590-27331   Pod didn't trigger scale-up:
3m43s       Warning   FailedScheduling    pod/swebench-run-24591-1332    0/1 nodes are available: 1 Too many pods. no new claims to deallocate, preemption: 0/1 nodes are available: 1 No preemption victims found for incoming pod.
5m1s        Normal    NotTriggerScaleUp   pod/swebench-run-24591-1332    Pod didn't trigger scale-up:
3m43s       Warning   FailedScheduling    pod/swebench-run-24592-13670   0/1 nodes are available: 1 Too many pods. no new claims to deallocate, preemption: 0/1 nodes are available: 1 No preemption victims found for incoming pod.
5m1s        Normal    NotTriggerScaleUp   pod/swebench-run-24592-13670   Pod didn't trigger scale-up:
3m43s       Warning   FailedScheduling    pod/swebench-run-24593-16925   0/1 nodes are available: 1 Too many pods. no new claims to deallocate, preemption: 0/1 nodes are available: 1 No preemption victims found for incoming pod.
5m1s        Normal    NotTriggerScaleUp   pod/swebench-run-24593-16925   Pod didn't trigger scale-up:
3m43s       Warning   FailedScheduling    pod/swebench-run-24594-25752   0/1 nodes are available: 1 Too many pods. no new claims to deallocate, preemption: 0/1 nodes are available: 1 No preemption victims found for incoming pod.
5m1s        Normal    NotTriggerScaleUp   pod/swebench-run-24594-25752   Pod didn't trigger scale-up:
3m43s       Warning   FailedScheduling    pod/swebench-run-24595-27378   0/1 nodes are available: 1 Too many pods. no new claims to deallocate, preemption: 0/1 nodes are available: 1 No preemption victims found for incoming pod.
5m1s        Normal    NotTriggerScaleUp   pod/swebench-run-24595-27378   Pod didn't trigger scale-up:
3m43s       Warning   FailedScheduling    pod/swebench-run-24596-31339   0/1 nodes are available: 1 Too many pods. no new claims to deallocate, preemption: 0/1 nodes are available: 1 No preemption victims found for incoming pod.
5m1s        Normal    NotTriggerScaleUp   pod/swebench-run-24596-31339   Pod didn't trigger scale-up:
3m43s       Warning   FailedScheduling    pod/swebench-run-24597-2880    0/1 nodes are available: 1 Too many pods. no new claims to deallocate, preemption: 0/1 nodes are available: 1 No preemption victims found for incoming pod.
4m51s       Normal    NotTriggerScaleUp   pod/swebench-run-24597-2880    Pod didn't trigger scale-up:
3m43s       Warning   FailedScheduling    pod/swebench-run-24598-30996   0/1 nodes are available: 1 Too many pods. no new claims to deallocate, preemption: 0/1 nodes are available: 1 No preemption victims found for incoming pod.
5m1s        Normal    NotTriggerScaleUp   pod/swebench-run-24598-30996   Pod didn't trigger scale-up:
3m43s       Warning   FailedScheduling    pod/swebench-run-24599-25681   0/1 nodes are available: 1 Too many pods. no new claims to deallocate, preemption: 0/1 nodes are available: 1 No preemption victims found for incoming pod.
5m1s        Normal    NotTriggerScaleUp   pod/swebench-run-24599-25681   Pod didn't trigger scale-up:
3m43s       Warning   FailedScheduling    pod/swebench-run-24600-8889    0/1 nodes are available: 1 Too many pods. no new claims to deallocate, preemption: 0/1 nodes are available: 1 No preemption victims found for incoming pod.
5m1s        Normal    NotTriggerScaleUp   pod/swebench-run-24600-8889    Pod didn't trigger scale-up:
3m43s       Warning   FailedScheduling    pod/swebench-run-24601-10593   0/1 nodes are available: 1 Too many pods. no new claims to deallocate, preemption: 0/1 nodes are available: 1 No preemption victims found for incoming pod.
5m1s        Normal    NotTriggerScaleUp   pod/swebench-run-24601-10593   Pod didn't trigger scale-up:
3m43s       Warning   FailedScheduling    pod/swebench-run-24602-14374   0/1 nodes are available: 1 Too many pods. no new claims to deallocate, preemption: 0/1 nodes are available: 1 No preemption victims found for incoming pod.
5m1s        Normal    NotTriggerScaleUp   pod/swebench-run-24602-14374   Pod didn't trigger scale-up:
3m43s       Warning   FailedScheduling    pod/swebench-run-24603-25437   0/1 nodes are available: 1 Too many pods. no new claims to deallocate, preemption: 0/1 nodes are available: 1 No preemption victims found for incoming pod.
5m1s        Normal    NotTriggerScaleUp   pod/swebench-run-24603-25437   Pod didn't trigger scale-up:
3m43s       Warning   FailedScheduling    pod/swebench-run-24604-16761   0/1 nodes are available: 1 Too many pods. no new claims to deallocate, preemption: 0/1 nodes are available: 1 No preemption victims found for incoming pod.
5m1s        Normal    NotTriggerScaleUp   pod/swebench-run-24604-16761   Pod didn't trigger scale-up:
3m43s       Warning   FailedScheduling    pod/swebench-run-24605-10047   0/1 nodes are available: 1 Too many pods. no new claims to deallocate, preemption: 0/1 nodes are available: 1 No preemption victims found for incoming pod.
4m51s       Normal    NotTriggerScaleUp   pod/swebench-run-24605-10047   Pod didn't trigger scale-up:
1s          Normal    BackOff             pod/swebench-run-24606-1268    Back-off pulling image "us-central1-docker.pkg.dev/bsalmon-gke-dev/test-repo/sweperf:sympy__sympy-19040"
1s          Warning   Failed              pod/swebench-run-24606-1268    Error: ImagePullBackOff
11s         Normal    BackOff             pod/swebench-run-24607-8352    Back-off pulling image "us-central1-docker.pkg.dev/bsalmon-gke-dev/test-repo/sweperf:django__django-13128"
4m58s       Warning   Failed              pod/swebench-run-24607-8352    Error: ImagePullBackOff
8s          Normal    BackOff             pod/swebench-run-24608-12430   Back-off pulling image "us-central1-docker.pkg.dev/bsalmon-gke-dev/test-repo/sweperf:django__django-13028"
4m57s       Warning   Failed              pod/swebench-run-24608-12430   Error: ImagePullBackOff
4m13s       Normal    BackOff             pod/swebench-run-24609-1635    Back-off pulling image "us-central1-docker.pkg.dev/bsalmon-gke-dev/test-repo/sweperf:django__django-12419"
4m53s       Warning   Failed              pod/swebench-run-24609-1635    Error: ImagePullBackOff
8s          Normal    BackOff             pod/swebench-run-24610-3098    Back-off pulling image "us-central1-docker.pkg.dev/bsalmon-gke-dev/test-repo/sweperf:django__django-11734"
4m55s       Warning   Failed              pod/swebench-run-24610-3098    Error: ImagePullBackOff
4m1s        Normal    BackOff             pod/swebench-run-24611-734     Back-off pulling image "us-central1-docker.pkg.dev/bsalmon-gke-dev/test-repo/sweperf:django__django-13449"
4m52s       Warning   Failed              pod/swebench-run-24611-734     Error: ImagePullBackOff
3m49s       Normal    BackOff             pod/swebench-run-24612-31730   Back-off pulling image "us-central1-docker.pkg.dev/bsalmon-gke-dev/test-repo/sweperf:django__django-15732"
4m43s       Warning   Failed              pod/swebench-run-24612-31730   Error: ImagePullBackOff
2s          Normal    BackOff             pod/swebench-run-24613-21260   Back-off pulling image "us-central1-docker.pkg.dev/bsalmon-gke-dev/test-repo/sweperf:sphinx-doc__sphinx-9281"
4m46s       Warning   Failed              pod/swebench-run-24613-21260   Error: ImagePullBackOff
3m55s       Normal    BackOff             pod/swebench-run-24614-13137   Back-off pulling image "us-central1-docker.pkg.dev/bsalmon-gke-dev/test-repo/sweperf:django__django-13794"
4m35s       Warning   Failed              pod/swebench-run-24614-13137   Error: ImagePullBackOff
3m58s       Normal    BackOff             pod/swebench-run-24615-10322   Back-off pulling image "us-central1-docker.pkg.dev/bsalmon-gke-dev/test-repo/sweperf:django__django-15022"
4m31s       Warning   Failed              pod/swebench-run-24615-10322   Error: ImagePullBackOff
3m48s       Normal    BackOff             pod/swebench-run-24616-17345   Back-off pulling image "us-central1-docker.pkg.dev/bsalmon-gke-dev/test-repo/sweperf:sympy__sympy-24443"
4m38s       Warning   Failed              pod/swebench-run-24616-17345   Error: ImagePullBackOff
4m          Normal    BackOff             pod/swebench-run-24617-16460   Back-off pulling image "us-central1-docker.pkg.dev/bsalmon-gke-dev/test-repo/sweperf:scikit-learn__scikit-learn-12973"
4m38s       Warning   Failed              pod/swebench-run-24617-16460   Error: ImagePullBackOff
3m43s       Warning   FailedScheduling    pod/swebench-run-24618-23385   0/1 nodes are available: 1 Too many pods. no new claims to deallocate, preemption: 0/1 nodes are available: 1 No preemption victims found for incoming pod.
6s          Normal    NotTriggerScaleUp   pod/swebench-run-24618-23385   Pod didn't trigger scale-up:
3m43s       Warning   FailedScheduling    pod/swebench-run-24619-23610   0/1 nodes are available: 1 Too many pods. no new claims to deallocate, preemption: 0/1 nodes are available: 1 No preemption victims found for incoming pod.
6s          Normal    NotTriggerScaleUp   pod/swebench-run-24619-23610   Pod didn't trigger scale-up:
3m43s       Warning   FailedScheduling    pod/swebench-run-24620-3921    0/1 nodes are available: 1 Too many pods. no new claims to deallocate, preemption: 0/1 nodes are available: 1 No preemption victims found for incoming pod.
6s          Normal    NotTriggerScaleUp   pod/swebench-run-24620-3921    Pod didn't trigger scale-up:
3m43s       Warning   FailedScheduling    pod/swebench-run-24621-28987   0/1 nodes are available: 1 Too many pods. no new claims to deallocate, preemption: 0/1 nodes are available: 1 No preemption victims found for incoming pod.
6s          Normal    NotTriggerScaleUp   pod/swebench-run-24621-28987   Pod didn't trigger scale-up:
3m43s       Warning   FailedScheduling    pod/swebench-run-24622-15409   0/1 nodes are available: 1 Too many pods. no new claims to deallocate, preemption: 0/1 nodes are available: 1 No preemption victims found for incoming pod.
6s          Normal    NotTriggerScaleUp   pod/swebench-run-24622-15409   Pod didn't trigger scale-up:
3m43s       Warning   FailedScheduling    pod/swebench-run-24623-8721    0/1 nodes are available: 1 Too many pods. no new claims to deallocate, preemption: 0/1 nodes are available: 1 No preemption victims found for incoming pod.
6s          Normal    NotTriggerScaleUp   pod/swebench-run-24623-8721    Pod didn't trigger scale-up:
3m43s       Warning   FailedScheduling    pod/swebench-run-24624-8500    0/1 nodes are available: 1 Too many pods. no new claims to deallocate, preemption: 0/1 nodes are available: 1 No preemption victims found for incoming pod.
6s          Normal    NotTriggerScaleUp   pod/swebench-run-24624-8500    Pod didn't trigger scale-up:
3m43s       Warning   FailedScheduling    pod/swebench-run-24625-11834   0/1 nodes are available: 1 Too many pods. no new claims to deallocate, preemption: 0/1 nodes are available: 1 No preemption victims found for incoming pod.
6s          Normal    NotTriggerScaleUp   pod/swebench-run-24625-11834   Pod didn't trigger scale-up:
3m44s       Warning   FailedScheduling    pod/swebench-run-24626-18412   0/1 nodes are available: 1 Too many pods. no new claims to deallocate, preemption: 0/1 nodes are available: 1 No preemption victims found for incoming pod.
6s          Normal    NotTriggerScaleUp   pod/swebench-run-24626-18412   Pod didn't trigger scale-up:
3m43s       Warning   FailedScheduling    pod/swebench-run-24627-30000   0/1 nodes are available: 1 Too many pods. no new claims to deallocate, preemption: 0/1 nodes are available: 1 No preemption victims found for incoming pod.
6s          Normal    NotTriggerScaleUp   pod/swebench-run-24627-30000   Pod didn't trigger scale-up:
3m43s       Warning   FailedScheduling    pod/swebench-run-24628-3764    0/1 nodes are available: 1 Too many pods. no new claims to deallocate, preemption: 0/1 nodes are available: 1 No preemption victims found for incoming pod.
5m1s        Normal    NotTriggerScaleUp   pod/swebench-run-24628-3764    Pod didn't trigger scale-up:
3m43s       Warning   FailedScheduling    pod/swebench-run-24629-4334    0/1 nodes are available: 1 Too many pods. no new claims to deallocate, preemption: 0/1 nodes are available: 1 No preemption victims found for incoming pod.
6s          Normal    NotTriggerScaleUp   pod/swebench-run-24629-4334    Pod didn't trigger scale-up:
3m43s       Warning   FailedScheduling    pod/swebench-run-24630-14655   0/1 nodes are available: 1 Too many pods. no new claims to deallocate, preemption: 0/1 nodes are available: 1 No preemption victims found for incoming pod.
5m1s        Normal    NotTriggerScaleUp   pod/swebench-run-24630-14655   Pod didn't trigger scale-up:
3m43s       Warning   FailedScheduling    pod/swebench-run-24631-2754    0/1 nodes are available: 1 Too many pods. no new claims to deallocate, preemption: 0/1 nodes are available: 1 No preemption victims found for incoming pod.
5m1s        Normal    NotTriggerScaleUp   pod/swebench-run-24631-2754    Pod didn't trigger scale-up:
3m43s       Warning   FailedScheduling    pod/swebench-run-24632-4887    0/1 nodes are available: 1 Too many pods. no new claims to deallocate, preemption: 0/1 nodes are available: 1 No preemption victims found for incoming pod.
5m1s        Normal    NotTriggerScaleUp   pod/swebench-run-24632-4887    Pod didn't trigger scale-up:
3m43s       Warning   FailedScheduling    pod/swebench-run-24633-20561   0/1 nodes are available: 1 Too many pods. no new claims to deallocate, preemption: 0/1 nodes are available: 1 No preemption victims found for incoming pod.
5m1s        Normal    NotTriggerScaleUp   pod/swebench-run-24633-20561   Pod didn't trigger scale-up:
3m43s       Warning   FailedScheduling    pod/swebench-run-24634-17028   0/1 nodes are available: 1 Too many pods. no new claims to deallocate, preemption: 0/1 nodes are available: 1 No preemption victims found for incoming pod.
5m1s        Normal    NotTriggerScaleUp   pod/swebench-run-24634-17028   Pod didn't trigger scale-up:
3m43s       Warning   FailedScheduling    pod/swebench-run-24635-29091   0/1 nodes are available: 1 Too many pods. no new claims to deallocate, preemption: 0/1 nodes are available: 1 No preemption victims found for incoming pod.
5m1s        Normal    NotTriggerScaleUp   pod/swebench-run-24635-29091   Pod didn't trigger scale-up:
3m43s       Warning   FailedScheduling    pod/swebench-run-24636-9800    0/1 nodes are available: 1 Too many pods. no new claims to deallocate, preemption: 0/1 nodes are available: 1 No preemption victims found for incoming pod.
5m1s        Normal    NotTriggerScaleUp   pod/swebench-run-24636-9800    Pod didn't trigger scale-up:
3m43s       Warning   FailedScheduling    pod/swebench-run-24637-16956   0/1 nodes are available: 1 Too many pods. no new claims to deallocate, preemption: 0/1 nodes are available: 1 No preemption victims found for incoming pod.
5m1s        Normal    NotTriggerScaleUp   pod/swebench-run-24637-16956   Pod didn't trigger scale-up:
3m43s       Warning   FailedScheduling    pod/swebench-run-24638-17340   0/1 nodes are available: 1 Too many pods. no new claims to deallocate, preemption: 0/1 nodes are available: 1 No preemption victims found for incoming pod.
5m1s        Normal    NotTriggerScaleUp   pod/swebench-run-24638-17340   Pod didn't trigger scale-up:
3m43s       Warning   FailedScheduling    pod/swebench-run-24639-22341   0/1 nodes are available: 1 Too many pods. no new claims to deallocate, preemption: 0/1 nodes are available: 1 No preemption victims found for incoming pod.
5m1s        Normal    NotTriggerScaleUp   pod/swebench-run-24639-22341   Pod didn't trigger scale-up:
3m43s       Warning   FailedScheduling    pod/swebench-run-24640-6104    0/1 nodes are available: 1 Too many pods. no new claims to deallocate, preemption: 0/1 nodes are available: 1 No preemption victims found for incoming pod.
5m1s        Normal    NotTriggerScaleUp   pod/swebench-run-24640-6104    Pod didn't trigger scale-up:
3m43s       Warning   FailedScheduling    pod/swebench-run-24641-30224   0/1 nodes are available: 1 Too many pods. no new claims to deallocate, preemption: 0/1 nodes are available: 1 No preemption victims found for incoming pod.
5m1s        Normal    NotTriggerScaleUp   pod/swebench-run-24641-30224   Pod didn't trigger scale-up:
3m43s       Warning   FailedScheduling    pod/swebench-run-24642-26944   0/1 nodes are available: 1 Too many pods. no new claims to deallocate, preemption: 0/1 nodes are available: 1 No preemption victims found for incoming pod.
5m1s        Normal    NotTriggerScaleUp   pod/swebench-run-24642-26944   Pod didn't trigger scale-up:
3m43s       Warning   FailedScheduling    pod/swebench-run-24643-17130   0/1 nodes are available: 1 Too many pods. no new claims to deallocate, preemption: 0/1 nodes are available: 1 No preemption victims found for incoming pod.
5m1s        Normal    NotTriggerScaleUp   pod/swebench-run-24643-17130   Pod didn't trigger scale-up:
3m43s       Warning   FailedScheduling    pod/swebench-run-24644-14564   0/1 nodes are available: 1 Too many pods. no new claims to deallocate, preemption: 0/1 nodes are available: 1 No preemption victims found for incoming pod.
5m1s        Normal    NotTriggerScaleUp   pod/swebench-run-24644-14564   Pod didn't trigger scale-up:
3m43s       Warning   FailedScheduling    pod/swebench-run-24645-520     0/1 nodes are available: 1 Too many pods. no new claims to deallocate, preemption: 0/1 nodes are available: 1 No preemption victims found for incoming pod.
5m1s        Normal    NotTriggerScaleUp   pod/swebench-run-24645-520     Pod didn't trigger scale-up:
3m43s       Warning   FailedScheduling    pod/swebench-run-24646-32608   0/1 nodes are available: 1 Too many pods. no new claims to deallocate, preemption: 0/1 nodes are available: 1 No preemption victims found for incoming pod.
5m1s        Normal    NotTriggerScaleUp   pod/swebench-run-24646-32608   Pod didn't trigger scale-up:
3m43s       Warning   FailedScheduling    pod/swebench-run-24647-10838   0/1 nodes are available: 1 Too many pods. no new claims to deallocate, preemption: 0/1 nodes are available: 1 No preemption victims found for incoming pod.
5m1s        Normal    NotTriggerScaleUp   pod/swebench-run-24647-10838   Pod didn't trigger scale-up:
3m43s       Warning   FailedScheduling    pod/swebench-run-24648-22089   0/1 nodes are available: 1 Too many pods. no new claims to deallocate, preemption: 0/1 nodes are available: 1 No preemption victims found for incoming pod.
4m51s       Normal    NotTriggerScaleUp   pod/swebench-run-24648-22089   Pod didn't trigger scale-up:
3m43s       Warning   FailedScheduling    pod/swebench-run-24649-30096   0/1 nodes are available: 1 Too many pods. no new claims to deallocate, preemption: 0/1 nodes are available: 1 No preemption victims found for incoming pod.
5m1s        Normal    NotTriggerScaleUp   pod/swebench-run-24649-30096   Pod didn't trigger scale-up:
3m43s       Warning   FailedScheduling    pod/swebench-run-24650-30348   0/1 nodes are available: 1 Too many pods. no new claims to deallocate, preemption: 0/1 nodes are available: 1 No preemption victims found for incoming pod.
4m51s       Normal    NotTriggerScaleUp   pod/swebench-run-24650-30348   Pod didn't trigger scale-up:
3m43s       Warning   FailedScheduling    pod/swebench-run-24651-14261   0/1 nodes are available: 1 Too many pods. no new claims to deallocate, preemption: 0/1 nodes are available: 1 No preemption victims found for incoming pod.
4m51s       Normal    NotTriggerScaleUp   pod/swebench-run-24651-14261   Pod didn't trigger scale-up:
3m43s       Warning   FailedScheduling    pod/swebench-run-24652-32424   0/1 nodes are available: 1 Too many pods. no new claims to deallocate, preemption: 0/1 nodes are available: 1 No preemption victims found for incoming pod.
5m1s        Normal    NotTriggerScaleUp   pod/swebench-run-24652-32424   Pod didn't trigger scale-up:
3m43s       Warning   FailedScheduling    pod/swebench-run-24653-18110   0/1 nodes are available: 1 Too many pods. no new claims to deallocate, preemption: 0/1 nodes are available: 1 No preemption victims found for incoming pod.
4m51s       Normal    NotTriggerScaleUp   pod/swebench-run-24653-18110   Pod didn't trigger scale-up:
3m43s       Warning   FailedScheduling    pod/swebench-run-24654-15193   0/1 nodes are available: 1 Too many pods. no new claims to deallocate, preemption: 0/1 nodes are available: 1 No preemption victims found for incoming pod.
4m51s       Normal    NotTriggerScaleUp   pod/swebench-run-24654-15193   Pod didn't trigger scale-up:
3m43s       Warning   FailedScheduling    pod/swebench-run-24655-30530   0/1 nodes are available: 1 Too many pods. no new claims to deallocate, preemption: 0/1 nodes are available: 1 No preemption victims found for incoming pod.
5m1s        Normal    NotTriggerScaleUp   pod/swebench-run-24655-30530   Pod didn't trigger scale-up:
3s          Normal    BackOff             pod/swebench-run-24656-26031   Back-off pulling image "us-central1-docker.pkg.dev/bsalmon-gke-dev/test-repo/sweperf:django__django-11211"
4m51s       Warning   Failed              pod/swebench-run-24656-26031   Error: ImagePullBackOff
3s          Normal    BackOff             pod/swebench-run-24657-25874   Back-off pulling image "us-central1-docker.pkg.dev/bsalmon-gke-dev/test-repo/sweperf:django__django-13112"
4m56s       Warning   Failed              pod/swebench-run-24657-25874   Error: ImagePullBackOff
4m13s       Normal    BackOff             pod/swebench-run-24658-3365    Back-off pulling image "us-central1-docker.pkg.dev/bsalmon-gke-dev/test-repo/sweperf:django__django-14500"
4m53s       Warning   Failed              pod/swebench-run-24658-3365    Error: ImagePullBackOff
4s          Normal    BackOff             pod/swebench-run-24659-29030   Back-off pulling image "us-central1-docker.pkg.dev/bsalmon-gke-dev/test-repo/sweperf:django__django-11477"
4m55s       Warning   Failed              pod/swebench-run-24659-29030   Error: ImagePullBackOff
2s          Normal    BackOff             pod/swebench-run-24660-14309   Back-off pulling image "us-central1-docker.pkg.dev/bsalmon-gke-dev/test-repo/sweperf:django__django-16612"
4m47s       Warning   Failed              pod/swebench-run-24660-14309   Error: ImagePullBackOff
1s          Normal    BackOff             pod/swebench-run-24661-3260    Back-off pulling image "us-central1-docker.pkg.dev/bsalmon-gke-dev/test-repo/sweperf:sympy__sympy-19637"
4m42s       Warning   Failed              pod/swebench-run-24661-3260    Error: ImagePullBackOff
0s          Normal    BackOff             pod/swebench-run-24662-20806   Back-off pulling image "us-central1-docker.pkg.dev/bsalmon-gke-dev/test-repo/sweperf:sphinx-doc__sphinx-9230"
4m42s       Warning   Failed              pod/swebench-run-24662-20806   Error: ImagePullBackOff
4m2s        Normal    BackOff             pod/swebench-run-24663-11071   Back-off pulling image "us-central1-docker.pkg.dev/bsalmon-gke-dev/test-repo/sweperf:scikit-learn__scikit-learn-25232"
4m43s       Warning   Failed              pod/swebench-run-24663-11071   Error: ImagePullBackOff
3m58s       Normal    BackOff             pod/swebench-run-24664-18161   Back-off pulling image "us-central1-docker.pkg.dev/bsalmon-gke-dev/test-repo/sweperf:django__django-15851"
4m34s       Warning   Failed              pod/swebench-run-24664-18161   Error: ImagePullBackOff
3m52s       Normal    BackOff             pod/swebench-run-24665-24254   Back-off pulling image "us-central1-docker.pkg.dev/bsalmon-gke-dev/test-repo/sweperf:matplotlib__matplotlib-22865"
4m32s       Warning   Failed              pod/swebench-run-24665-24254   Error: ImagePullBackOff
3m56s       Normal    BackOff             pod/swebench-run-24666-24856   Back-off pulling image "us-central1-docker.pkg.dev/bsalmon-gke-dev/test-repo/sweperf:django__django-14493"
4m34s       Warning   Failed              pod/swebench-run-24666-24856   Error: ImagePullBackOff
3m55s       Normal    BackOff             pod/swebench-run-24667-20533   Back-off pulling image "us-central1-docker.pkg.dev/bsalmon-gke-dev/test-repo/sweperf:matplotlib__matplotlib-21568"
4m33s       Warning   Failed              pod/swebench-run-24667-20533   Error: ImagePullBackOff
3m43s       Warning   FailedScheduling    pod/swebench-run-24668-5988    0/1 nodes are available: 1 Too many pods. no new claims to deallocate, preemption: 0/1 nodes are available: 1 No preemption victims found for incoming pod.
6s          Normal    NotTriggerScaleUp   pod/swebench-run-24668-5988    Pod didn't trigger scale-up:
3m43s       Warning   FailedScheduling    pod/swebench-run-24669-24573   0/1 nodes are available: 1 Too many pods. no new claims to deallocate, preemption: 0/1 nodes are available: 1 No preemption victims found for incoming pod.
6s          Normal    NotTriggerScaleUp   pod/swebench-run-24669-24573   Pod didn't trigger scale-up:
3m43s       Warning   FailedScheduling    pod/swebench-run-24670-7159    0/1 nodes are available: 1 Too many pods. no new claims to deallocate, preemption: 0/1 nodes are available: 1 No preemption victims found for incoming pod.
6s          Normal    NotTriggerScaleUp   pod/swebench-run-24670-7159    Pod didn't trigger scale-up:
3m43s       Warning   FailedScheduling    pod/swebench-run-24671-15330   0/1 nodes are available: 1 Too many pods. no new claims to deallocate, preemption: 0/1 nodes are available: 1 No preemption victims found for incoming pod.
6s          Normal    NotTriggerScaleUp   pod/swebench-run-24671-15330   Pod didn't trigger scale-up:
3m43s       Warning   FailedScheduling    pod/swebench-run-24672-28393   0/1 nodes are available: 1 Too many pods. no new claims to deallocate, preemption: 0/1 nodes are available: 1 No preemption victims found for incoming pod.
6s          Normal    NotTriggerScaleUp   pod/swebench-run-24672-28393   Pod didn't trigger scale-up:
3m43s       Warning   FailedScheduling    pod/swebench-run-24673-23361   0/1 nodes are available: 1 Too many pods. no new claims to deallocate, preemption: 0/1 nodes are available: 1 No preemption victims found for incoming pod.
6s          Normal    NotTriggerScaleUp   pod/swebench-run-24673-23361   Pod didn't trigger scale-up:
3m43s       Warning   FailedScheduling    pod/swebench-run-24674-22510   0/1 nodes are available: 1 Too many pods. no new claims to deallocate, preemption: 0/1 nodes are available: 1 No preemption victims found for incoming pod.
6s          Normal    NotTriggerScaleUp   pod/swebench-run-24674-22510   Pod didn't trigger scale-up:
3m25s       Normal    BackOff             pod/swebench-run-24675-27009   Back-off pulling image "us-central1-docker.pkg.dev/bsalmon-gke-dev/test-repo/sweperf:astropy__astropy-7336"
3m36s       Warning   Failed              pod/swebench-run-24675-27009   Error: ImagePullBackOff
3m43s       Warning   FailedScheduling    pod/swebench-run-24676-22318   0/1 nodes are available: 1 Too many pods. no new claims to deallocate, preemption: 0/1 nodes are available: 1 No preemption victims found for incoming pod.
6s          Normal    NotTriggerScaleUp   pod/swebench-run-24676-22318   Pod didn't trigger scale-up:
3m43s       Warning   FailedScheduling    pod/swebench-run-24677-8594    0/1 nodes are available: 1 Too many pods. no new claims to deallocate, preemption: 0/1 nodes are available: 1 No preemption victims found for incoming pod.
6s          Normal    NotTriggerScaleUp   pod/swebench-run-24677-8594    Pod didn't trigger scale-up:
3m43s       Warning   FailedScheduling    pod/swebench-run-24678-8518    0/1 nodes are available: 1 Too many pods. no new claims to deallocate, preemption: 0/1 nodes are available: 1 No preemption victims found for incoming pod.
5m1s        Normal    NotTriggerScaleUp   pod/swebench-run-24678-8518    Pod didn't trigger scale-up:
3m43s       Warning   FailedScheduling    pod/swebench-run-24679-3190    0/1 nodes are available: 1 Too many pods. no new claims to deallocate, preemption: 0/1 nodes are available: 1 No preemption victims found for incoming pod.
6s          Normal    NotTriggerScaleUp   pod/swebench-run-24679-3190    Pod didn't trigger scale-up:
3m43s       Warning   FailedScheduling    pod/swebench-run-24680-29776   0/1 nodes are available: 1 Too many pods. no new claims to deallocate, preemption: 0/1 nodes are available: 1 No preemption victims found for incoming pod.
5m1s        Normal    NotTriggerScaleUp   pod/swebench-run-24680-29776   Pod didn't trigger scale-up:
3m43s       Warning   FailedScheduling    pod/swebench-run-24681-31817   0/1 nodes are available: 1 Too many pods. no new claims to deallocate, preemption: 0/1 nodes are available: 1 No preemption victims found for incoming pod.
5m1s        Normal    NotTriggerScaleUp   pod/swebench-run-24681-31817   Pod didn't trigger scale-up:
3m43s       Warning   FailedScheduling    pod/swebench-run-24682-30841   0/1 nodes are available: 1 Too many pods. no new claims to deallocate, preemption: 0/1 nodes are available: 1 No preemption victims found for incoming pod.
5m1s        Normal    NotTriggerScaleUp   pod/swebench-run-24682-30841   Pod didn't trigger scale-up:
3m43s       Warning   FailedScheduling    pod/swebench-run-24683-25779   0/1 nodes are available: 1 Too many pods. no new claims to deallocate, preemption: 0/1 nodes are available: 1 No preemption victims found for incoming pod.
5m1s        Normal    NotTriggerScaleUp   pod/swebench-run-24683-25779   Pod didn't trigger scale-up:
3m43s       Warning   FailedScheduling    pod/swebench-run-24684-2494    0/1 nodes are available: 1 Too many pods. no new claims to deallocate, preemption: 0/1 nodes are available: 1 No preemption victims found for incoming pod.
5m1s        Normal    NotTriggerScaleUp   pod/swebench-run-24684-2494    Pod didn't trigger scale-up:
3m43s       Warning   FailedScheduling    pod/swebench-run-24685-1276    0/1 nodes are available: 1 Too many pods. no new claims to deallocate, preemption: 0/1 nodes are available: 1 No preemption victims found for incoming pod.
5m1s        Normal    NotTriggerScaleUp   pod/swebench-run-24685-1276    Pod didn't trigger scale-up:
3m43s       Warning   FailedScheduling    pod/swebench-run-24686-23791   0/1 nodes are available: 1 Too many pods. no new claims to deallocate, preemption: 0/1 nodes are available: 1 No preemption victims found for incoming pod.
5m1s        Normal    NotTriggerScaleUp   pod/swebench-run-24686-23791   Pod didn't trigger scale-up:
3m43s       Warning   FailedScheduling    pod/swebench-run-24687-24271   0/1 nodes are available: 1 Too many pods. no new claims to deallocate, preemption: 0/1 nodes are available: 1 No preemption victims found for incoming pod.
5m1s        Normal    NotTriggerScaleUp   pod/swebench-run-24687-24271   Pod didn't trigger scale-up:
3m43s       Warning   FailedScheduling    pod/swebench-run-24688-7782    0/1 nodes are available: 1 Too many pods. no new claims to deallocate, preemption: 0/1 nodes are available: 1 No preemption victims found for incoming pod.
5m1s        Normal    NotTriggerScaleUp   pod/swebench-run-24688-7782    Pod didn't trigger scale-up:
3m43s       Warning   FailedScheduling    pod/swebench-run-24689-13127   0/1 nodes are available: 1 Too many pods. no new claims to deallocate, preemption: 0/1 nodes are available: 1 No preemption victims found for incoming pod.
5m1s        Normal    NotTriggerScaleUp   pod/swebench-run-24689-13127   Pod didn't trigger scale-up:
3m43s       Warning   FailedScheduling    pod/swebench-run-24690-26462   0/1 nodes are available: 1 Too many pods. no new claims to deallocate, preemption: 0/1 nodes are available: 1 No preemption victims found for incoming pod.
5m1s        Normal    NotTriggerScaleUp   pod/swebench-run-24690-26462   Pod didn't trigger scale-up:
3m43s       Warning   FailedScheduling    pod/swebench-run-24691-11322   0/1 nodes are available: 1 Too many pods. no new claims to deallocate, preemption: 0/1 nodes are available: 1 No preemption victims found for incoming pod.
5m1s        Normal    NotTriggerScaleUp   pod/swebench-run-24691-11322   Pod didn't trigger scale-up:
3m43s       Warning   FailedScheduling    pod/swebench-run-24692-7758    0/1 nodes are available: 1 Too many pods. no new claims to deallocate, preemption: 0/1 nodes are available: 1 No preemption victims found for incoming pod.
5m1s        Normal    NotTriggerScaleUp   pod/swebench-run-24692-7758    Pod didn't trigger scale-up:
3m43s       Warning   FailedScheduling    pod/swebench-run-24693-11504   0/1 nodes are available: 1 Too many pods. no new claims to deallocate, preemption: 0/1 nodes are available: 1 No preemption victims found for incoming pod.
5m1s        Normal    NotTriggerScaleUp   pod/swebench-run-24693-11504   Pod didn't trigger scale-up:
3m43s       Warning   FailedScheduling    pod/swebench-run-24694-4094    0/1 nodes are available: 1 Too many pods. no new claims to deallocate, preemption: 0/1 nodes are available: 1 No preemption victims found for incoming pod.
5m1s        Normal    NotTriggerScaleUp   pod/swebench-run-24694-4094    Pod didn't trigger scale-up:
3m43s       Warning   FailedScheduling    pod/swebench-run-24695-15478   0/1 nodes are available: 1 Too many pods. no new claims to deallocate, preemption: 0/1 nodes are available: 1 No preemption victims found for incoming pod.
5m1s        Normal    NotTriggerScaleUp   pod/swebench-run-24695-15478   Pod didn't trigger scale-up:
3m43s       Warning   FailedScheduling    pod/swebench-run-24696-24931   0/1 nodes are available: 1 Too many pods. no new claims to deallocate, preemption: 0/1 nodes are available: 1 No preemption victims found for incoming pod.
5m1s        Normal    NotTriggerScaleUp   pod/swebench-run-24696-24931   Pod didn't trigger scale-up:
3m43s       Warning   FailedScheduling    pod/swebench-run-24697-16702   0/1 nodes are available: 1 Too many pods. no new claims to deallocate, preemption: 0/1 nodes are available: 1 No preemption victims found for incoming pod.
4m51s       Normal    NotTriggerScaleUp   pod/swebench-run-24697-16702   Pod didn't trigger scale-up:
3m43s       Warning   FailedScheduling    pod/swebench-run-24698-4330    0/1 nodes are available: 1 Too many pods. no new claims to deallocate, preemption: 0/1 nodes are available: 1 No preemption victims found for incoming pod.
5m1s        Normal    NotTriggerScaleUp   pod/swebench-run-24698-4330    Pod didn't trigger scale-up:
3m43s       Warning   FailedScheduling    pod/swebench-run-24699-4762    0/1 nodes are available: 1 Too many pods. no new claims to deallocate, preemption: 0/1 nodes are available: 1 No preemption victims found for incoming pod.
5m1s        Normal    NotTriggerScaleUp   pod/swebench-run-24699-4762    Pod didn't trigger scale-up:
3m43s       Warning   FailedScheduling    pod/swebench-run-24700-15897   0/1 nodes are available: 1 Too many pods. no new claims to deallocate, preemption: 0/1 nodes are available: 1 No preemption victims found for incoming pod.
4m51s       Normal    NotTriggerScaleUp   pod/swebench-run-24700-15897   Pod didn't trigger scale-up:
3m43s       Warning   FailedScheduling    pod/swebench-run-24701-1117    0/1 nodes are available: 1 Too many pods. no new claims to deallocate, preemption: 0/1 nodes are available: 1 No preemption victims found for incoming pod.
4m51s       Normal    NotTriggerScaleUp   pod/swebench-run-24701-1117    Pod didn't trigger scale-up:
3m43s       Warning   FailedScheduling    pod/swebench-run-24702-19545   0/1 nodes are available: 1 Too many pods. no new claims to deallocate, preemption: 0/1 nodes are available: 1 No preemption victims found for incoming pod.
4m51s       Normal    NotTriggerScaleUp   pod/swebench-run-24702-19545   Pod didn't trigger scale-up:
3m43s       Warning   FailedScheduling    pod/swebench-run-24703-8618    0/1 nodes are available: 1 Too many pods. no new claims to deallocate, preemption: 0/1 nodes are available: 1 No preemption victims found for incoming pod.
4m51s       Normal    NotTriggerScaleUp   pod/swebench-run-24703-8618    Pod didn't trigger scale-up:
3m43s       Warning   FailedScheduling    pod/swebench-run-24704-5124    0/1 nodes are available: 1 Too many pods. no new claims to deallocate, preemption: 0/1 nodes are available: 1 No preemption victims found for incoming pod.
4m51s       Normal    NotTriggerScaleUp   pod/swebench-run-24704-5124    Pod didn't trigger scale-up:
3m43s       Warning   FailedScheduling    pod/swebench-run-24705-6199    0/1 nodes are available: 1 Too many pods. no new claims to deallocate, preemption: 0/1 nodes are available: 1 No preemption victims found for incoming pod.
4m51s       Normal    NotTriggerScaleUp   pod/swebench-run-24705-6199    Pod didn't trigger scale-up:
3m43s       Warning   FailedScheduling    pod/swebench-run-24706-20818   0/1 nodes are available: 1 Too many pods. no new claims to deallocate, preemption: 0/1 nodes are available: 1 No preemption victims found for incoming pod.
4m51s       Normal    NotTriggerScaleUp   pod/swebench-run-24706-20818   Pod didn't trigger scale-up:
3m43s       Warning   FailedScheduling    pod/swebench-run-24707-26694   0/1 nodes are available: 1 Too many pods. no new claims to deallocate, preemption: 0/1 nodes are available: 1 No preemption victims found for incoming pod.
4m41s       Normal    NotTriggerScaleUp   pod/swebench-run-24707-26694   Pod didn't trigger scale-up:
3m43s       Warning   FailedScheduling    pod/swebench-run-24708-4803    0/1 nodes are available: 1 Too many pods. no new claims to deallocate, preemption: 0/1 nodes are available: 1 No preemption victims found for incoming pod.
4m41s       Normal    NotTriggerScaleUp   pod/swebench-run-24708-4803    Pod didn't trigger scale-up:
3m43s       Warning   FailedScheduling    pod/swebench-run-24709-13191   0/1 nodes are available: 1 Too many pods. no new claims to deallocate, preemption: 0/1 nodes are available: 1 No preemption victims found for incoming pod.
4m41s       Normal    NotTriggerScaleUp   pod/swebench-run-24709-13191   Pod didn't trigger scale-up:
3m43s       Warning   FailedScheduling    pod/swebench-run-24710-25471   0/1 nodes are available: 1 Too many pods. no new claims to deallocate, preemption: 0/1 nodes are available: 1 No preemption victims found for incoming pod.
4m41s       Normal    NotTriggerScaleUp   pod/swebench-run-24710-25471   Pod didn't trigger scale-up:
3m43s       Warning   FailedScheduling    pod/swebench-run-24711-21852   0/1 nodes are available: 1 Too many pods. no new claims to deallocate, preemption: 0/1 nodes are available: 1 No preemption victims found for incoming pod.
4m41s       Normal    NotTriggerScaleUp   pod/swebench-run-24711-21852   Pod didn't trigger scale-up:
3m43s       Warning   FailedScheduling    pod/swebench-run-24712-8482    0/1 nodes are available: 1 Too many pods. no new claims to deallocate, preemption: 0/1 nodes are available: 1 No preemption victims found for incoming pod.
4m41s       Normal    NotTriggerScaleUp   pod/swebench-run-24712-8482    Pod didn't trigger scale-up:
3m43s       Warning   FailedScheduling    pod/swebench-run-24713-27125   0/1 nodes are available: 1 Too many pods. no new claims to deallocate, preemption: 0/1 nodes are available: 1 No preemption victims found for incoming pod.
4m41s       Normal    NotTriggerScaleUp   pod/swebench-run-24713-27125   Pod didn't trigger scale-up:
3m43s       Warning   FailedScheduling    pod/swebench-run-24714-3060    0/1 nodes are available: 1 Too many pods. no new claims to deallocate, preemption: 0/1 nodes are available: 1 No preemption victims found for incoming pod.
4m41s       Normal    NotTriggerScaleUp   pod/swebench-run-24714-3060    Pod didn't trigger scale-up:
3m43s       Warning   FailedScheduling    pod/swebench-run-24715-14822   0/1 nodes are available: 1 Too many pods. no new claims to deallocate, preemption: 0/1 nodes are available: 1 No preemption victims found for incoming pod.
4m41s       Normal    NotTriggerScaleUp   pod/swebench-run-24715-14822   Pod didn't trigger scale-up:
3m43s       Warning   FailedScheduling    pod/swebench-run-24716-8100    0/1 nodes are available: 1 Too many pods. no new claims to deallocate, preemption: 0/1 nodes are available: 1 No preemption victims found for incoming pod.
4m41s       Normal    NotTriggerScaleUp   pod/swebench-run-24716-8100    Pod didn't trigger scale-up:
3m43s       Warning   FailedScheduling    pod/swebench-run-24717-16560   0/1 nodes are available: 1 Too many pods. no new claims to deallocate, preemption: 0/1 nodes are available: 1 No preemption victims found for incoming pod.
4m41s       Normal    NotTriggerScaleUp   pod/swebench-run-24717-16560   Pod didn't trigger scale-up:
3m43s       Warning   FailedScheduling    pod/swebench-run-24718-18756   0/1 nodes are available: 1 Too many pods. no new claims to deallocate, preemption: 0/1 nodes are available: 1 No preemption victims found for incoming pod.
4m41s       Normal    NotTriggerScaleUp   pod/swebench-run-24718-18756   Pod didn't trigger scale-up:
3m43s       Warning   FailedScheduling    pod/swebench-run-24719-11454   0/1 nodes are available: 1 Too many pods. no new claims to deallocate, preemption: 0/1 nodes are available: 1 No preemption victims found for incoming pod.
4m41s       Normal    NotTriggerScaleUp   pod/swebench-run-24719-11454   Pod didn't trigger scale-up:
3m43s       Warning   FailedScheduling    pod/swebench-run-24720-24661   0/1 nodes are available: 1 Too many pods. no new claims to deallocate, preemption: 0/1 nodes are available: 1 No preemption victims found for incoming pod.
4m31s       Normal    NotTriggerScaleUp   pod/swebench-run-24720-24661   Pod didn't trigger scale-up:
3m43s       Warning   FailedScheduling    pod/swebench-run-24721-8964    0/1 nodes are available: 1 Too many pods. no new claims to deallocate, preemption: 0/1 nodes are available: 1 No preemption victims found for incoming pod.
4m31s       Normal    NotTriggerScaleUp   pod/swebench-run-24721-8964    Pod didn't trigger scale-up:
4m31s       Normal    NotTriggerScaleUp   pod/swebench-run-24722-3339    Pod didn't trigger scale-up:
3m43s       Warning   FailedScheduling    pod/swebench-run-24722-3339    0/1 nodes are available: 1 Too many pods. no new claims to deallocate, preemption: 0/1 nodes are available: 1 No preemption victims found for incoming pod.
3m43s       Warning   FailedScheduling    pod/swebench-run-24723-21800   0/1 nodes are available: 1 Too many pods. no new claims to deallocate, preemption: 0/1 nodes are available: 1 No preemption victims found for incoming pod.
4m31s       Normal    NotTriggerScaleUp   pod/swebench-run-24723-21800   Pod didn't trigger scale-up:
3m43s       Warning   FailedScheduling    pod/swebench-run-24724-11392   0/1 nodes are available: 1 Too many pods. no new claims to deallocate, preemption: 0/1 nodes are available: 1 No preemption victims found for incoming pod.
4m31s       Normal    NotTriggerScaleUp   pod/swebench-run-24724-11392   Pod didn't trigger scale-up:
4m31s       Normal    NotTriggerScaleUp   pod/swebench-run-24725-24348   Pod didn't trigger scale-up:
3m43s       Warning   FailedScheduling    pod/swebench-run-24725-24348   0/1 nodes are available: 1 Too many pods. no new claims to deallocate, preemption: 0/1 nodes are available: 1 No preemption victims found for incoming pod.
3m43s       Warning   FailedScheduling    pod/swebench-run-24726-1321    0/1 nodes are available: 1 Too many pods. no new claims to deallocate, preemption: 0/1 nodes are available: 1 No preemption victims found for incoming pod.
4m21s       Normal    NotTriggerScaleUp   pod/swebench-run-24726-1321    Pod didn't trigger scale-up:
3m43s       Warning   FailedScheduling    pod/swebench-run-24727-4974    0/1 nodes are available: 1 Too many pods. no new claims to deallocate, preemption: 0/1 nodes are available: 1 No preemption victims found for incoming pod.
4m11s       Normal    NotTriggerScaleUp   pod/swebench-run-24727-4974    Pod didn't trigger scale-up:
4m31s       Normal    NotTriggerScaleUp   pod/swebench-run-24728-768     Pod didn't trigger scale-up:
3m43s       Warning   FailedScheduling    pod/swebench-run-24728-768     0/1 nodes are available: 1 Too many pods. no new claims to deallocate, preemption: 0/1 nodes are available: 1 No preemption victims found for incoming pod.
4m31s       Normal    NotTriggerScaleUp   pod/swebench-run-24729-206     Pod didn't trigger scale-up:
3m43s       Warning   FailedScheduling    pod/swebench-run-24729-206     0/1 nodes are available: 1 Too many pods. no new claims to deallocate, preemption: 0/1 nodes are available: 1 No preemption victims found for incoming pod.
3m43s       Warning   FailedScheduling    pod/swebench-run-24730-10815   0/1 nodes are available: 1 Too many pods. no new claims to deallocate, preemption: 0/1 nodes are available: 1 No preemption victims found for incoming pod.
4m21s       Normal    NotTriggerScaleUp   pod/swebench-run-24730-10815   Pod didn't trigger scale-up:
4m31s       Normal    NotTriggerScaleUp   pod/swebench-run-24731-3385    Pod didn't trigger scale-up:
3m43s       Warning   FailedScheduling    pod/swebench-run-24731-3385    0/1 nodes are available: 1 Too many pods. no new claims to deallocate, preemption: 0/1 nodes are available: 1 No preemption victims found for incoming pod.
3m43s       Warning   FailedScheduling    pod/swebench-run-24732-1399    0/1 nodes are available: 1 Too many pods. no new claims to deallocate, preemption: 0/1 nodes are available: 1 No preemption victims found for incoming pod.
4m11s       Normal    NotTriggerScaleUp   pod/swebench-run-24732-1399    Pod didn't trigger scale-up:
3m43s       Warning   FailedScheduling    pod/swebench-run-24733-11743   0/1 nodes are available: 1 Too many pods. no new claims to deallocate, preemption: 0/1 nodes are available: 1 No preemption victims found for incoming pod.
4m11s       Normal    NotTriggerScaleUp   pod/swebench-run-24733-11743   Pod didn't trigger scale-up:
3m43s       Warning   FailedScheduling    pod/swebench-run-24734-12391   0/1 nodes are available: 1 Too many pods. no new claims to deallocate, preemption: 0/1 nodes are available: 1 No preemption victims found for incoming pod.
4m11s       Normal    NotTriggerScaleUp   pod/swebench-run-24734-12391   Pod didn't trigger scale-up:
3m43s       Warning   FailedScheduling    pod/swebench-run-24735-841     0/1 nodes are available: 1 Too many pods. no new claims to deallocate, preemption: 0/1 nodes are available: 1 No preemption victims found for incoming pod.
4m11s       Normal    NotTriggerScaleUp   pod/swebench-run-24735-841     Pod didn't trigger scale-up:
3m43s       Warning   FailedScheduling    pod/swebench-run-24736-8965    0/1 nodes are available: 1 Too many pods. no new claims to deallocate, preemption: 0/1 nodes are available: 1 No preemption victims found for incoming pod.
4m11s       Normal    NotTriggerScaleUp   pod/swebench-run-24736-8965    Pod didn't trigger scale-up:
3m43s       Warning   FailedScheduling    pod/swebench-run-24737-20167   0/1 nodes are available: 1 Too many pods. no new claims to deallocate, preemption: 0/1 nodes are available: 1 No preemption victims found for incoming pod.
4m21s       Normal    NotTriggerScaleUp   pod/swebench-run-24737-20167   Pod didn't trigger scale-up:
4m21s       Normal    NotTriggerScaleUp   pod/swebench-run-24738-29741   Pod didn't trigger scale-up:
3m43s       Warning   FailedScheduling    pod/swebench-run-24738-29741   0/1 nodes are available: 1 Too many pods. no new claims to deallocate, preemption: 0/1 nodes are available: 1 No preemption victims found for incoming pod.
4m11s       Normal    NotTriggerScaleUp   pod/swebench-run-24739-17336   Pod didn't trigger scale-up:
3m43s       Warning   FailedScheduling    pod/swebench-run-24739-17336   0/1 nodes are available: 1 Too many pods. no new claims to deallocate, preemption: 0/1 nodes are available: 1 No preemption victims found for incoming pod.
4m21s       Normal    NotTriggerScaleUp   pod/swebench-run-24740-4421    Pod didn't trigger scale-up:
3m43s       Warning   FailedScheduling    pod/swebench-run-24740-4421    0/1 nodes are available: 1 Too many pods. no new claims to deallocate, preemption: 0/1 nodes are available: 1 No preemption victims found for incoming pod.
4m21s       Normal    NotTriggerScaleUp   pod/swebench-run-24741-871     Pod didn't trigger scale-up:
3m43s       Warning   FailedScheduling    pod/swebench-run-24741-871     0/1 nodes are available: 1 Too many pods. no new claims to deallocate, preemption: 0/1 nodes are available: 1 No preemption victims found for incoming pod.
3m43s       Warning   FailedScheduling    pod/swebench-run-24742-1001    0/1 nodes are available: 1 Too many pods. no new claims to deallocate, preemption: 0/1 nodes are available: 1 No preemption victims found for incoming pod.
4m11s       Normal    NotTriggerScaleUp   pod/swebench-run-24742-1001    Pod didn't trigger scale-up:
3m43s       Warning   FailedScheduling    pod/swebench-run-24743-5504    0/1 nodes are available: 1 Too many pods. no new claims to deallocate, preemption: 0/1 nodes are available: 1 No preemption victims found for incoming pod.
4m11s       Normal    NotTriggerScaleUp   pod/swebench-run-24743-5504    Pod didn't trigger scale-up:
4m11s       Normal    NotTriggerScaleUp   pod/swebench-run-24744-19139   Pod didn't trigger scale-up:
3m43s       Warning   FailedScheduling    pod/swebench-run-24744-19139   0/1 nodes are available: 1 Too many pods. no new claims to deallocate, preemption: 0/1 nodes are available: 1 No preemption victims found for incoming pod.
3m43s       Warning   FailedScheduling    pod/swebench-run-24745-19509   0/1 nodes are available: 1 Too many pods. no new claims to deallocate, preemption: 0/1 nodes are available: 1 No preemption victims found for incoming pod.
4m11s       Normal    NotTriggerScaleUp   pod/swebench-run-24745-19509   Pod didn't trigger scale-up:
4m11s       Normal    NotTriggerScaleUp   pod/swebench-run-24746-5185    Pod didn't trigger scale-up:
3m43s       Warning   FailedScheduling    pod/swebench-run-24746-5185    0/1 nodes are available: 1 Too many pods. no new claims to deallocate, preemption: 0/1 nodes are available: 1 No preemption victims found for incoming pod.
4m11s       Normal    NotTriggerScaleUp   pod/swebench-run-24747-15884   Pod didn't trigger scale-up:
3m43s       Warning   FailedScheduling    pod/swebench-run-24747-15884   0/1 nodes are available: 1 Too many pods. no new claims to deallocate, preemption: 0/1 nodes are available: 1 No preemption victims found for incoming pod.
4m11s       Normal    NotTriggerScaleUp   pod/swebench-run-24748-30136   Pod didn't trigger scale-up:
3m43s       Warning   FailedScheduling    pod/swebench-run-24748-30136   0/1 nodes are available: 1 Too many pods. no new claims to deallocate, preemption: 0/1 nodes are available: 1 No preemption victims found for incoming pod.
4m11s       Normal    NotTriggerScaleUp   pod/swebench-run-24749-20412   Pod didn't trigger scale-up:
3m43s       Warning   FailedScheduling    pod/swebench-run-24749-20412   0/1 nodes are available: 1 Too many pods. no new claims to deallocate, preemption: 0/1 nodes are available: 1 No preemption victims found for incoming pod.
3m43s       Warning   FailedScheduling    pod/swebench-run-24750-6344    0/1 nodes are available: 1 Too many pods. no new claims to deallocate, preemption: 0/1 nodes are available: 1 No preemption victims found for incoming pod.
4m11s       Normal    NotTriggerScaleUp   pod/swebench-run-24750-6344    Pod didn't trigger scale-up:
3m43s       Warning   FailedScheduling    pod/swebench-run-24751-28164   0/1 nodes are available: 1 Too many pods. no new claims to deallocate, preemption: 0/1 nodes are available: 1 No preemption victims found for incoming pod.
4m11s       Normal    NotTriggerScaleUp   pod/swebench-run-24751-28164   Pod didn't trigger scale-up:
3m43s       Warning   FailedScheduling    pod/swebench-run-24752-26644   0/1 nodes are available: 1 Too many pods. no new claims to deallocate, preemption: 0/1 nodes are available: 1 No preemption victims found for incoming pod.
4m          Normal    NotTriggerScaleUp   pod/swebench-run-24752-26644   Pod didn't trigger scale-up:
3m43s       Warning   FailedScheduling    pod/swebench-run-24753-10174   0/1 nodes are available: 1 Too many pods. no new claims to deallocate, preemption: 0/1 nodes are available: 1 No preemption victims found for incoming pod.
4m          Normal    NotTriggerScaleUp   pod/swebench-run-24753-10174   Pod didn't trigger scale-up:
4m11s       Normal    NotTriggerScaleUp   pod/swebench-run-24754-1025    Pod didn't trigger scale-up:
3m43s       Warning   FailedScheduling    pod/swebench-run-24754-1025    0/1 nodes are available: 1 Too many pods. no new claims to deallocate, preemption: 0/1 nodes are available: 1 No preemption victims found for incoming pod.
4m11s       Normal    NotTriggerScaleUp   pod/swebench-run-24755-26214   Pod didn't trigger scale-up:
3m43s       Warning   FailedScheduling    pod/swebench-run-24755-26214   0/1 nodes are available: 1 Too many pods. no new claims to deallocate, preemption: 0/1 nodes are available: 1 No preemption victims found for incoming pod.
3m43s       Warning   FailedScheduling    pod/swebench-run-24756-2980    0/1 nodes are available: 1 Too many pods. no new claims to deallocate, preemption: 0/1 nodes are available: 1 No preemption victims found for incoming pod.
4m41s       Normal    NotTriggerScaleUp   pod/swebench-run-24756-2980    Pod didn't trigger scale-up:
3m43s       Warning   FailedScheduling    pod/swebench-run-24757-6645    0/1 nodes are available: 1 Too many pods. no new claims to deallocate, preemption: 0/1 nodes are available: 1 No preemption victims found for incoming pod.
4m41s       Normal    NotTriggerScaleUp   pod/swebench-run-24757-6645    Pod didn't trigger scale-up:
3m43s       Warning   FailedScheduling    pod/swebench-run-24758-22827   0/1 nodes are available: 1 Too many pods. no new claims to deallocate, preemption: 0/1 nodes are available: 1 No preemption victims found for incoming pod.
4m41s       Normal    NotTriggerScaleUp   pod/swebench-run-24758-22827   Pod didn't trigger scale-up:
3m43s       Warning   FailedScheduling    pod/swebench-run-24759-29798   0/1 nodes are available: 1 Too many pods. no new claims to deallocate, preemption: 0/1 nodes are available: 1 No preemption victims found for incoming pod.
4m41s       Normal    NotTriggerScaleUp   pod/swebench-run-24759-29798   Pod didn't trigger scale-up:
3m43s       Warning   FailedScheduling    pod/swebench-run-24760-9095    0/1 nodes are available: 1 Too many pods. no new claims to deallocate, preemption: 0/1 nodes are available: 1 No preemption victims found for incoming pod.
4m41s       Normal    NotTriggerScaleUp   pod/swebench-run-24760-9095    Pod didn't trigger scale-up:
3m43s       Warning   FailedScheduling    pod/swebench-run-24761-16457   0/1 nodes are available: 1 Too many pods. no new claims to deallocate, preemption: 0/1 nodes are available: 1 No preemption victims found for incoming pod.
4m41s       Normal    NotTriggerScaleUp   pod/swebench-run-24761-16457   Pod didn't trigger scale-up:
3m43s       Warning   FailedScheduling    pod/swebench-run-24762-21473   0/1 nodes are available: 1 Too many pods. no new claims to deallocate, preemption: 0/1 nodes are available: 1 No preemption victims found for incoming pod.
4m41s       Normal    NotTriggerScaleUp   pod/swebench-run-24762-21473   Pod didn't trigger scale-up:
3m43s       Warning   FailedScheduling    pod/swebench-run-24763-6715    0/1 nodes are available: 1 Too many pods. no new claims to deallocate, preemption: 0/1 nodes are available: 1 No preemption victims found for incoming pod.
4m41s       Normal    NotTriggerScaleUp   pod/swebench-run-24763-6715    Pod didn't trigger scale-up:
3m43s       Warning   FailedScheduling    pod/swebench-run-24764-19519   0/1 nodes are available: 1 Too many pods. no new claims to deallocate, preemption: 0/1 nodes are available: 1 No preemption victims found for incoming pod.
4m41s       Normal    NotTriggerScaleUp   pod/swebench-run-24764-19519   Pod didn't trigger scale-up:
3m43s       Warning   FailedScheduling    pod/swebench-run-24765-21854   0/1 nodes are available: 1 Too many pods. no new claims to deallocate, preemption: 0/1 nodes are available: 1 No preemption victims found for incoming pod.
4m41s       Normal    NotTriggerScaleUp   pod/swebench-run-24765-21854   Pod didn't trigger scale-up:
3m43s       Warning   FailedScheduling    pod/swebench-run-24766-999     0/1 nodes are available: 1 Too many pods. no new claims to deallocate, preemption: 0/1 nodes are available: 1 No preemption victims found for incoming pod.
4m41s       Normal    NotTriggerScaleUp   pod/swebench-run-24766-999     Pod didn't trigger scale-up:
3m43s       Warning   FailedScheduling    pod/swebench-run-24767-5041    0/1 nodes are available: 1 Too many pods. no new claims to deallocate, preemption: 0/1 nodes are available: 1 No preemption victims found for incoming pod.
4m31s       Normal    NotTriggerScaleUp   pod/swebench-run-24767-5041    Pod didn't trigger scale-up:
3m43s       Warning   FailedScheduling    pod/swebench-run-24768-29406   0/1 nodes are available: 1 Too many pods. no new claims to deallocate, preemption: 0/1 nodes are available: 1 No preemption victims found for incoming pod.
4m31s       Normal    NotTriggerScaleUp   pod/swebench-run-24768-29406   Pod didn't trigger scale-up:
3m43s       Warning   FailedScheduling    pod/swebench-run-24769-26306   0/1 nodes are available: 1 Too many pods. no new claims to deallocate, preemption: 0/1 nodes are available: 1 No preemption victims found for incoming pod.
4m31s       Normal    NotTriggerScaleUp   pod/swebench-run-24769-26306   Pod didn't trigger scale-up:
3m43s       Warning   FailedScheduling    pod/swebench-run-24770-10462   0/1 nodes are available: 1 Too many pods. no new claims to deallocate, preemption: 0/1 nodes are available: 1 No preemption victims found for incoming pod.
4m31s       Normal    NotTriggerScaleUp   pod/swebench-run-24770-10462   Pod didn't trigger scale-up:
3m43s       Warning   FailedScheduling    pod/swebench-run-24771-11411   0/1 nodes are available: 1 Too many pods. no new claims to deallocate, preemption: 0/1 nodes are available: 1 No preemption victims found for incoming pod.
4m31s       Normal    NotTriggerScaleUp   pod/swebench-run-24771-11411   Pod didn't trigger scale-up:
4m31s       Normal    NotTriggerScaleUp   pod/swebench-run-24772-23596   Pod didn't trigger scale-up:
3m43s       Warning   FailedScheduling    pod/swebench-run-24772-23596   0/1 nodes are available: 1 Too many pods. no new claims to deallocate, preemption: 0/1 nodes are available: 1 No preemption victims found for incoming pod.
3m43s       Warning   FailedScheduling    pod/swebench-run-24773-22454   0/1 nodes are available: 1 Too many pods. no new claims to deallocate, preemption: 0/1 nodes are available: 1 No preemption victims found for incoming pod.
4m31s       Normal    NotTriggerScaleUp   pod/swebench-run-24773-22454   Pod didn't trigger scale-up:
3m43s       Warning   FailedScheduling    pod/swebench-run-24774-31111   0/1 nodes are available: 1 Too many pods. no new claims to deallocate, preemption: 0/1 nodes are available: 1 No preemption victims found for incoming pod.
4m11s       Normal    NotTriggerScaleUp   pod/swebench-run-24774-31111   Pod didn't trigger scale-up:
4m31s       Normal    NotTriggerScaleUp   pod/swebench-run-24775-31230   Pod didn't trigger scale-up:
3m43s       Warning   FailedScheduling    pod/swebench-run-24775-31230   0/1 nodes are available: 1 Too many pods. no new claims to deallocate, preemption: 0/1 nodes are available: 1 No preemption victims found for incoming pod.
3m43s       Warning   FailedScheduling    pod/swebench-run-24776-14007   0/1 nodes are available: 1 Too many pods. no new claims to deallocate, preemption: 0/1 nodes are available: 1 No preemption victims found for incoming pod.
4m31s       Normal    NotTriggerScaleUp   pod/swebench-run-24776-14007   Pod didn't trigger scale-up:
4m31s       Normal    NotTriggerScaleUp   pod/swebench-run-24777-12172   Pod didn't trigger scale-up:
3m43s       Warning   FailedScheduling    pod/swebench-run-24777-12172   0/1 nodes are available: 1 Too many pods. no new claims to deallocate, preemption: 0/1 nodes are available: 1 No preemption victims found for incoming pod.
3m43s       Warning   FailedScheduling    pod/swebench-run-24778-29047   0/1 nodes are available: 1 Too many pods. no new claims to deallocate, preemption: 0/1 nodes are available: 1 No preemption victims found for incoming pod.
4m21s       Normal    NotTriggerScaleUp   pod/swebench-run-24778-29047   Pod didn't trigger scale-up:
3m43s       Warning   FailedScheduling    pod/swebench-run-24779-30105   0/1 nodes are available: 1 Too many pods. no new claims to deallocate, preemption: 0/1 nodes are available: 1 No preemption victims found for incoming pod.
4m11s       Normal    NotTriggerScaleUp   pod/swebench-run-24779-30105   Pod didn't trigger scale-up:
4m21s       Normal    NotTriggerScaleUp   pod/swebench-run-24780-23475   Pod didn't trigger scale-up:
3m43s       Warning   FailedScheduling    pod/swebench-run-24780-23475   0/1 nodes are available: 1 Too many pods. no new claims to deallocate, preemption: 0/1 nodes are available: 1 No preemption victims found for incoming pod.
3m43s       Warning   FailedScheduling    pod/swebench-run-24781-22294   0/1 nodes are available: 1 Too many pods. no new claims to deallocate, preemption: 0/1 nodes are available: 1 No preemption victims found for incoming pod.
4m11s       Normal    NotTriggerScaleUp   pod/swebench-run-24781-22294   Pod didn't trigger scale-up:
3m43s       Warning   FailedScheduling    pod/swebench-run-24782-22321   0/1 nodes are available: 1 Too many pods. no new claims to deallocate, preemption: 0/1 nodes are available: 1 No preemption victims found for incoming pod.
4m11s       Normal    NotTriggerScaleUp   pod/swebench-run-24782-22321   Pod didn't trigger scale-up:
3m43s       Warning   FailedScheduling    pod/swebench-run-24783-19580   0/1 nodes are available: 1 Too many pods. no new claims to deallocate, preemption: 0/1 nodes are available: 1 No preemption victims found for incoming pod.
4m11s       Normal    NotTriggerScaleUp   pod/swebench-run-24783-19580   Pod didn't trigger scale-up:
3m43s       Warning   FailedScheduling    pod/swebench-run-24784-8584    0/1 nodes are available: 1 Too many pods. no new claims to deallocate, preemption: 0/1 nodes are available: 1 No preemption victims found for incoming pod.
4m21s       Normal    NotTriggerScaleUp   pod/swebench-run-24784-8584    Pod didn't trigger scale-up:
4m21s       Normal    NotTriggerScaleUp   pod/swebench-run-24785-22792   Pod didn't trigger scale-up:
3m43s       Warning   FailedScheduling    pod/swebench-run-24785-22792   0/1 nodes are available: 1 Too many pods. no new claims to deallocate, preemption: 0/1 nodes are available: 1 No preemption victims found for incoming pod.
3m43s       Warning   FailedScheduling    pod/swebench-run-24786-2788    0/1 nodes are available: 1 Too many pods. no new claims to deallocate, preemption: 0/1 nodes are available: 1 No preemption victims found for incoming pod.
4m11s       Normal    NotTriggerScaleUp   pod/swebench-run-24786-2788    Pod didn't trigger scale-up:
3m43s       Warning   FailedScheduling    pod/swebench-run-24787-5533    0/1 nodes are available: 1 Too many pods. no new claims to deallocate, preemption: 0/1 nodes are available: 1 No preemption victims found for incoming pod.
4m11s       Normal    NotTriggerScaleUp   pod/swebench-run-24787-5533    Pod didn't trigger scale-up:
4m21s       Normal    NotTriggerScaleUp   pod/swebench-run-24788-26868   Pod didn't trigger scale-up:
3m43s       Warning   FailedScheduling    pod/swebench-run-24788-26868   0/1 nodes are available: 1 Too many pods. no new claims to deallocate, preemption: 0/1 nodes are available: 1 No preemption victims found for incoming pod.
3m43s       Warning   FailedScheduling    pod/swebench-run-24789-30359   0/1 nodes are available: 1 Too many pods. no new claims to deallocate, preemption: 0/1 nodes are available: 1 No preemption victims found for incoming pod.
4m11s       Normal    NotTriggerScaleUp   pod/swebench-run-24789-30359   Pod didn't trigger scale-up:
4m21s       Normal    NotTriggerScaleUp   pod/swebench-run-24790-11283   Pod didn't trigger scale-up:
3m43s       Warning   FailedScheduling    pod/swebench-run-24790-11283   0/1 nodes are available: 1 Too many pods. no new claims to deallocate, preemption: 0/1 nodes are available: 1 No preemption victims found for incoming pod.
3m43s       Warning   FailedScheduling    pod/swebench-run-24791-12770   0/1 nodes are available: 1 Too many pods. no new claims to deallocate, preemption: 0/1 nodes are available: 1 No preemption victims found for incoming pod.
4m11s       Normal    NotTriggerScaleUp   pod/swebench-run-24791-12770   Pod didn't trigger scale-up:
3m43s       Warning   FailedScheduling    pod/swebench-run-24792-27974   0/1 nodes are available: 1 Too many pods. no new claims to deallocate, preemption: 0/1 nodes are available: 1 No preemption victims found for incoming pod.
4m11s       Normal    NotTriggerScaleUp   pod/swebench-run-24792-27974   Pod didn't trigger scale-up:
4m11s       Normal    NotTriggerScaleUp   pod/swebench-run-24793-24326   Pod didn't trigger scale-up:
3m43s       Warning   FailedScheduling    pod/swebench-run-24793-24326   0/1 nodes are available: 1 Too many pods. no new claims to deallocate, preemption: 0/1 nodes are available: 1 No preemption victims found for incoming pod.
3m43s       Warning   FailedScheduling    pod/swebench-run-24794-21206   0/1 nodes are available: 1 Too many pods. no new claims to deallocate, preemption: 0/1 nodes are available: 1 No preemption victims found for incoming pod.
4m11s       Normal    NotTriggerScaleUp   pod/swebench-run-24794-21206   Pod didn't trigger scale-up:
4m11s       Normal    NotTriggerScaleUp   pod/swebench-run-24795-903     Pod didn't trigger scale-up:
3m43s       Warning   FailedScheduling    pod/swebench-run-24795-903     0/1 nodes are available: 1 Too many pods. no new claims to deallocate, preemption: 0/1 nodes are available: 1 No preemption victims found for incoming pod.
3m43s       Warning   FailedScheduling    pod/swebench-run-24796-26637   0/1 nodes are available: 1 Too many pods. no new claims to deallocate, preemption: 0/1 nodes are available: 1 No preemption victims found for incoming pod.
4m11s       Normal    NotTriggerScaleUp   pod/swebench-run-24796-26637   Pod didn't trigger scale-up:
4m11s       Normal    NotTriggerScaleUp   pod/swebench-run-24797-15590   Pod didn't trigger scale-up:
3m43s       Warning   FailedScheduling    pod/swebench-run-24797-15590   0/1 nodes are available: 1 Too many pods. no new claims to deallocate, preemption: 0/1 nodes are available: 1 No preemption victims found for incoming pod.
4m11s       Normal    NotTriggerScaleUp   pod/swebench-run-24798-12377   Pod didn't trigger scale-up:
3m43s       Warning   FailedScheduling    pod/swebench-run-24798-12377   0/1 nodes are available: 1 Too many pods. no new claims to deallocate, preemption: 0/1 nodes are available: 1 No preemption victims found for incoming pod.
3m43s       Warning   FailedScheduling    pod/swebench-run-24799-24118   0/1 nodes are available: 1 Too many pods. no new claims to deallocate, preemption: 0/1 nodes are available: 1 No preemption victims found for incoming pod.
4m11s       Normal    NotTriggerScaleUp   pod/swebench-run-24799-24118   Pod didn't trigger scale-up:
3m43s       Warning   FailedScheduling    pod/swebench-run-24800-616     0/1 nodes are available: 1 Too many pods. no new claims to deallocate, preemption: 0/1 nodes are available: 1 No preemption victims found for incoming pod.
4m          Normal    NotTriggerScaleUp   pod/swebench-run-24800-616     Pod didn't trigger scale-up:
3m43s       Warning   FailedScheduling    pod/swebench-run-24801-13044   0/1 nodes are available: 1 Too many pods. no new claims to deallocate, preemption: 0/1 nodes are available: 1 No preemption victims found for incoming pod.
4m          Normal    NotTriggerScaleUp   pod/swebench-run-24801-13044   Pod didn't trigger scale-up:
3m43s       Warning   FailedScheduling    pod/swebench-run-24802-11020   0/1 nodes are available: 1 Too many pods. no new claims to deallocate, preemption: 0/1 nodes are available: 1 No preemption victims found for incoming pod.
4m11s       Normal    NotTriggerScaleUp   pod/swebench-run-24802-11020   Pod didn't trigger scale-up:
4m11s       Normal    NotTriggerScaleUp   pod/swebench-run-24803-16451   Pod didn't trigger scale-up:
3m43s       Warning   FailedScheduling    pod/swebench-run-24803-16451   0/1 nodes are available: 1 Too many pods. no new claims to deallocate, preemption: 0/1 nodes are available: 1 No preemption victims found for incoming pod.
4m11s       Normal    NotTriggerScaleUp   pod/swebench-run-24804-3704    Pod didn't trigger scale-up:
3m43s       Warning   FailedScheduling    pod/swebench-run-24804-3704    0/1 nodes are available: 1 Too many pods. no new claims to deallocate, preemption: 0/1 nodes are available: 1 No preemption victims found for incoming pod.
3m43s       Warning   FailedScheduling    pod/swebench-run-24805-24156   0/1 nodes are available: 1 Too many pods. no new claims to deallocate, preemption: 0/1 nodes are available: 1 No preemption victims found for incoming pod.
4m          Normal    NotTriggerScaleUp   pod/swebench-run-24805-24156   Pod didn't trigger scale-up:
3m43s       Warning   FailedScheduling    pod/swebench-run-24806-11147   0/1 nodes are available: 1 Too many pods. no new claims to deallocate, preemption: 0/1 nodes are available: 1 No preemption victims found for incoming pod.
4m41s       Normal    NotTriggerScaleUp   pod/swebench-run-24806-11147   Pod didn't trigger scale-up:
3m43s       Warning   FailedScheduling    pod/swebench-run-24807-26977   0/1 nodes are available: 1 Too many pods. no new claims to deallocate, preemption: 0/1 nodes are available: 1 No preemption victims found for incoming pod.
4m41s       Normal    NotTriggerScaleUp   pod/swebench-run-24807-26977   Pod didn't trigger scale-up:
3m43s       Warning   FailedScheduling    pod/swebench-run-24808-14670   0/1 nodes are available: 1 Too many pods. no new claims to deallocate, preemption: 0/1 nodes are available: 1 No preemption victims found for incoming pod.
4m41s       Normal    NotTriggerScaleUp   pod/swebench-run-24808-14670   Pod didn't trigger scale-up:
3m43s       Warning   FailedScheduling    pod/swebench-run-24809-32409   0/1 nodes are available: 1 Too many pods. no new claims to deallocate, preemption: 0/1 nodes are available: 1 No preemption victims found for incoming pod.
4m41s       Normal    NotTriggerScaleUp   pod/swebench-run-24809-32409   Pod didn't trigger scale-up:
3m43s       Warning   FailedScheduling    pod/swebench-run-24810-3626    0/1 nodes are available: 1 Too many pods. no new claims to deallocate, preemption: 0/1 nodes are available: 1 No preemption victims found for incoming pod.
4m41s       Normal    NotTriggerScaleUp   pod/swebench-run-24810-3626    Pod didn't trigger scale-up:
3m43s       Warning   FailedScheduling    pod/swebench-run-24811-14719   0/1 nodes are available: 1 Too many pods. no new claims to deallocate, preemption: 0/1 nodes are available: 1 No preemption victims found for incoming pod.
4m41s       Normal    NotTriggerScaleUp   pod/swebench-run-24811-14719   Pod didn't trigger scale-up:
3m43s       Warning   FailedScheduling    pod/swebench-run-24812-7481    0/1 nodes are available: 1 Too many pods. no new claims to deallocate, preemption: 0/1 nodes are available: 1 No preemption victims found for incoming pod.
4m41s       Normal    NotTriggerScaleUp   pod/swebench-run-24812-7481    Pod didn't trigger scale-up:
3m43s       Warning   FailedScheduling    pod/swebench-run-24813-20644   0/1 nodes are available: 1 Too many pods. no new claims to deallocate, preemption: 0/1 nodes are available: 1 No preemption victims found for incoming pod.
4m41s       Normal    NotTriggerScaleUp   pod/swebench-run-24813-20644   Pod didn't trigger scale-up:
3m43s       Warning   FailedScheduling    pod/swebench-run-24814-25128   0/1 nodes are available: 1 Too many pods. no new claims to deallocate, preemption: 0/1 nodes are available: 1 No preemption victims found for incoming pod.
4m41s       Normal    NotTriggerScaleUp   pod/swebench-run-24814-25128   Pod didn't trigger scale-up:
3m43s       Warning   FailedScheduling    pod/swebench-run-24815-20466   0/1 nodes are available: 1 Too many pods. no new claims to deallocate, preemption: 0/1 nodes are available: 1 No preemption victims found for incoming pod.
4m41s       Normal    NotTriggerScaleUp   pod/swebench-run-24815-20466   Pod didn't trigger scale-up:
3m43s       Warning   FailedScheduling    pod/swebench-run-24816-12250   0/1 nodes are available: 1 Too many pods. no new claims to deallocate, preemption: 0/1 nodes are available: 1 No preemption victims found for incoming pod.
4m41s       Normal    NotTriggerScaleUp   pod/swebench-run-24816-12250   Pod didn't trigger scale-up:
3m43s       Warning   FailedScheduling    pod/swebench-run-24817-27508   0/1 nodes are available: 1 Too many pods. no new claims to deallocate, preemption: 0/1 nodes are available: 1 No preemption victims found for incoming pod.
4m31s       Normal    NotTriggerScaleUp   pod/swebench-run-24817-27508   Pod didn't trigger scale-up:
3m43s       Warning   FailedScheduling    pod/swebench-run-24818-4957    0/1 nodes are available: 1 Too many pods. no new claims to deallocate, preemption: 0/1 nodes are available: 1 No preemption victims found for incoming pod.
4m41s       Normal    NotTriggerScaleUp   pod/swebench-run-24818-4957    Pod didn't trigger scale-up:
3m43s       Warning   FailedScheduling    pod/swebench-run-24819-19849   0/1 nodes are available: 1 Too many pods. no new claims to deallocate, preemption: 0/1 nodes are available: 1 No preemption victims found for incoming pod.
4m31s       Normal    NotTriggerScaleUp   pod/swebench-run-24819-19849   Pod didn't trigger scale-up:
3m43s       Warning   FailedScheduling    pod/swebench-run-24820-17972   0/1 nodes are available: 1 Too many pods. no new claims to deallocate, preemption: 0/1 nodes are available: 1 No preemption victims found for incoming pod.
4m31s       Normal    NotTriggerScaleUp   pod/swebench-run-24820-17972   Pod didn't trigger scale-up:
4m31s       Normal    NotTriggerScaleUp   pod/swebench-run-24821-29818   Pod didn't trigger scale-up:
3m43s       Warning   FailedScheduling    pod/swebench-run-24821-29818   0/1 nodes are available: 1 Too many pods. no new claims to deallocate, preemption: 0/1 nodes are available: 1 No preemption victims found for incoming pod.
4m31s       Normal    NotTriggerScaleUp   pod/swebench-run-24822-25853   Pod didn't trigger scale-up:
3m43s       Warning   FailedScheduling    pod/swebench-run-24822-25853   0/1 nodes are available: 1 Too many pods. no new claims to deallocate, preemption: 0/1 nodes are available: 1 No preemption victims found for incoming pod.
3m43s       Warning   FailedScheduling    pod/swebench-run-24823-2522    0/1 nodes are available: 1 Too many pods. no new claims to deallocate, preemption: 0/1 nodes are available: 1 No preemption victims found for incoming pod.
4m31s       Normal    NotTriggerScaleUp   pod/swebench-run-24823-2522    Pod didn't trigger scale-up:
3m43s       Warning   FailedScheduling    pod/swebench-run-24824-14092   0/1 nodes are available: 1 Too many pods. no new claims to deallocate, preemption: 0/1 nodes are available: 1 No preemption victims found for incoming pod.
4m31s       Normal    NotTriggerScaleUp   pod/swebench-run-24824-14092   Pod didn't trigger scale-up:
4m31s       Normal    NotTriggerScaleUp   pod/swebench-run-24825-2003    Pod didn't trigger scale-up:
3m43s       Warning   FailedScheduling    pod/swebench-run-24825-2003    0/1 nodes are available: 1 Too many pods. no new claims to deallocate, preemption: 0/1 nodes are available: 1 No preemption victims found for incoming pod.
3m43s       Warning   FailedScheduling    pod/swebench-run-24826-15590   0/1 nodes are available: 1 Too many pods. no new claims to deallocate, preemption: 0/1 nodes are available: 1 No preemption victims found for incoming pod.
4m21s       Normal    NotTriggerScaleUp   pod/swebench-run-24826-15590   Pod didn't trigger scale-up:
3m43s       Warning   FailedScheduling    pod/swebench-run-24827-909     0/1 nodes are available: 1 Too many pods. no new claims to deallocate, preemption: 0/1 nodes are available: 1 No preemption victims found for incoming pod.
4m21s       Normal    NotTriggerScaleUp   pod/swebench-run-24827-909     Pod didn't trigger scale-up:
4m31s       Normal    NotTriggerScaleUp   pod/swebench-run-24828-256     Pod didn't trigger scale-up:
3m43s       Warning   FailedScheduling    pod/swebench-run-24828-256     0/1 nodes are available: 1 Too many pods. no new claims to deallocate, preemption: 0/1 nodes are available: 1 No preemption victims found for incoming pod.
3m43s       Warning   FailedScheduling    pod/swebench-run-24829-31960   0/1 nodes are available: 1 Too many pods. no new claims to deallocate, preemption: 0/1 nodes are available: 1 No preemption victims found for incoming pod.
4m11s       Normal    NotTriggerScaleUp   pod/swebench-run-24829-31960   Pod didn't trigger scale-up:
4m31s       Normal    NotTriggerScaleUp   pod/swebench-run-24830-9456    Pod didn't trigger scale-up:
3m43s       Warning   FailedScheduling    pod/swebench-run-24830-9456    0/1 nodes are available: 1 Too many pods. no new claims to deallocate, preemption: 0/1 nodes are available: 1 No preemption victims found for incoming pod.
4m21s       Normal    NotTriggerScaleUp   pod/swebench-run-24831-30158   Pod didn't trigger scale-up:
3m43s       Warning   FailedScheduling    pod/swebench-run-24831-30158   0/1 nodes are available: 1 Too many pods. no new claims to deallocate, preemption: 0/1 nodes are available: 1 No preemption victims found for incoming pod.
3m43s       Warning   FailedScheduling    pod/swebench-run-24832-8314    0/1 nodes are available: 1 Too many pods. no new claims to deallocate, preemption: 0/1 nodes are available: 1 No preemption victims found for incoming pod.
4m11s       Normal    NotTriggerScaleUp   pod/swebench-run-24832-8314    Pod didn't trigger scale-up:
4m21s       Normal    NotTriggerScaleUp   pod/swebench-run-24833-24840   Pod didn't trigger scale-up:
3m43s       Warning   FailedScheduling    pod/swebench-run-24833-24840   0/1 nodes are available: 1 Too many pods. no new claims to deallocate, preemption: 0/1 nodes are available: 1 No preemption victims found for incoming pod.
4m21s       Normal    NotTriggerScaleUp   pod/swebench-run-24834-20516   Pod didn't trigger scale-up:
3m43s       Warning   FailedScheduling    pod/swebench-run-24834-20516   0/1 nodes are available: 1 Too many pods. no new claims to deallocate, preemption: 0/1 nodes are available: 1 No preemption victims found for incoming pod.
3m43s       Warning   FailedScheduling    pod/swebench-run-24835-23942   0/1 nodes are available: 1 Too many pods. no new claims to deallocate, preemption: 0/1 nodes are available: 1 No preemption victims found for incoming pod.
4m21s       Normal    NotTriggerScaleUp   pod/swebench-run-24835-23942   Pod didn't trigger scale-up:
4m21s       Normal    NotTriggerScaleUp   pod/swebench-run-24836-21567   Pod didn't trigger scale-up:
3m43s       Warning   FailedScheduling    pod/swebench-run-24836-21567   0/1 nodes are available: 1 Too many pods. no new claims to deallocate, preemption: 0/1 nodes are available: 1 No preemption victims found for incoming pod.
3m43s       Warning   FailedScheduling    pod/swebench-run-24837-9706    0/1 nodes are available: 1 Too many pods. no new claims to deallocate, preemption: 0/1 nodes are available: 1 No preemption victims found for incoming pod.
4m          Normal    NotTriggerScaleUp   pod/swebench-run-24837-9706    Pod didn't trigger scale-up:
4m21s       Normal    NotTriggerScaleUp   pod/swebench-run-24838-22593   Pod didn't trigger scale-up:
3m43s       Warning   FailedScheduling    pod/swebench-run-24838-22593   0/1 nodes are available: 1 Too many pods. no new claims to deallocate, preemption: 0/1 nodes are available: 1 No preemption victims found for incoming pod.
4m11s       Normal    NotTriggerScaleUp   pod/swebench-run-24839-5001    Pod didn't trigger scale-up:
3m43s       Warning   FailedScheduling    pod/swebench-run-24839-5001    0/1 nodes are available: 1 Too many pods. no new claims to deallocate, preemption: 0/1 nodes are available: 1 No preemption victims found for incoming pod.
3m43s       Warning   FailedScheduling    pod/swebench-run-24840-16417   0/1 nodes are available: 1 Too many pods. no new claims to deallocate, preemption: 0/1 nodes are available: 1 No preemption victims found for incoming pod.
4m11s       Normal    NotTriggerScaleUp   pod/swebench-run-24840-16417   Pod didn't trigger scale-up:
4m11s       Normal    NotTriggerScaleUp   pod/swebench-run-24841-746     Pod didn't trigger scale-up:
3m43s       Warning   FailedScheduling    pod/swebench-run-24841-746     0/1 nodes are available: 1 Too many pods. no new claims to deallocate, preemption: 0/1 nodes are available: 1 No preemption victims found for incoming pod.
4m11s       Normal    NotTriggerScaleUp   pod/swebench-run-24842-19409   Pod didn't trigger scale-up:
3m43s       Warning   FailedScheduling    pod/swebench-run-24842-19409   0/1 nodes are available: 1 Too many pods. no new claims to deallocate, preemption: 0/1 nodes are available: 1 No preemption victims found for incoming pod.
4m11s       Normal    NotTriggerScaleUp   pod/swebench-run-24843-7200    Pod didn't trigger scale-up:
3m43s       Warning   FailedScheduling    pod/swebench-run-24843-7200    0/1 nodes are available: 1 Too many pods. no new claims to deallocate, preemption: 0/1 nodes are available: 1 No preemption victims found for incoming pod.
3m43s       Warning   FailedScheduling    pod/swebench-run-24844-22912   0/1 nodes are available: 1 Too many pods. no new claims to deallocate, preemption: 0/1 nodes are available: 1 No preemption victims found for incoming pod.
4m          Normal    NotTriggerScaleUp   pod/swebench-run-24844-22912   Pod didn't trigger scale-up:
3m43s       Warning   FailedScheduling    pod/swebench-run-24845-8640    0/1 nodes are available: 1 Too many pods. no new claims to deallocate, preemption: 0/1 nodes are available: 1 No preemption victims found for incoming pod.
4m11s       Normal    NotTriggerScaleUp   pod/swebench-run-24845-8640    Pod didn't trigger scale-up:
4m11s       Normal    NotTriggerScaleUp   pod/swebench-run-24846-9086    Pod didn't trigger scale-up:
3m43s       Warning   FailedScheduling    pod/swebench-run-24846-9086    0/1 nodes are available: 1 Too many pods. no new claims to deallocate, preemption: 0/1 nodes are available: 1 No preemption victims found for incoming pod.
4m11s       Normal    NotTriggerScaleUp   pod/swebench-run-24847-11348   Pod didn't trigger scale-up:
3m43s       Warning   FailedScheduling    pod/swebench-run-24847-11348   0/1 nodes are available: 1 Too many pods. no new claims to deallocate, preemption: 0/1 nodes are available: 1 No preemption victims found for incoming pod.
4m11s       Normal    NotTriggerScaleUp   pod/swebench-run-24848-17954   Pod didn't trigger scale-up:
3m43s       Warning   FailedScheduling    pod/swebench-run-24848-17954   0/1 nodes are available: 1 Too many pods. no new claims to deallocate, preemption: 0/1 nodes are available: 1 No preemption victims found for incoming pod.
4m11s       Normal    NotTriggerScaleUp   pod/swebench-run-24849-19818   Pod didn't trigger scale-up:
3m43s       Warning   FailedScheduling    pod/swebench-run-24849-19818   0/1 nodes are available: 1 Too many pods. no new claims to deallocate, preemption: 0/1 nodes are available: 1 No preemption victims found for incoming pod.
4m11s       Normal    NotTriggerScaleUp   pod/swebench-run-24850-24204   Pod didn't trigger scale-up:
3m43s       Warning   FailedScheduling    pod/swebench-run-24850-24204   0/1 nodes are available: 1 Too many pods. no new claims to deallocate, preemption: 0/1 nodes are available: 1 No preemption victims found for incoming pod.
4m11s       Normal    NotTriggerScaleUp   pod/swebench-run-24851-11120   Pod didn't trigger scale-up:
3m43s       Warning   FailedScheduling    pod/swebench-run-24851-11120   0/1 nodes are available: 1 Too many pods. no new claims to deallocate, preemption: 0/1 nodes are available: 1 No preemption victims found for incoming pod.
3m43s       Warning   FailedScheduling    pod/swebench-run-24852-31739   0/1 nodes are available: 1 Too many pods. no new claims to deallocate, preemption: 0/1 nodes are available: 1 No preemption victims found for incoming pod.
4m11s       Normal    NotTriggerScaleUp   pod/swebench-run-24852-31739   Pod didn't trigger scale-up:
3m43s       Warning   FailedScheduling    pod/swebench-run-24853-7800    0/1 nodes are available: 1 Too many pods. no new claims to deallocate, preemption: 0/1 nodes are available: 1 No preemption victims found for incoming pod.
4m          Normal    NotTriggerScaleUp   pod/swebench-run-24853-7800    Pod didn't trigger scale-up:
3m43s       Warning   FailedScheduling    pod/swebench-run-24854-8345    0/1 nodes are available: 1 Too many pods. no new claims to deallocate, preemption: 0/1 nodes are available: 1 No preemption victims found for incoming pod.
4m11s       Normal    NotTriggerScaleUp   pod/swebench-run-24854-8345    Pod didn't trigger scale-up:
3m43s       Warning   FailedScheduling    pod/swebench-run-24855-26720   0/1 nodes are available: 1 Too many pods. no new claims to deallocate, preemption: 0/1 nodes are available: 1 No preemption victims found for incoming pod.
4m          Normal    NotTriggerScaleUp   pod/swebench-run-24855-26720   Pod didn't trigger scale-up:
3m43s       Warning   FailedScheduling    pod/swebench-run-24856-32568   0/1 nodes are available: 1 Too many pods. no new claims to deallocate, preemption: 0/1 nodes are available: 1 No preemption victims found for incoming pod.
4m41s       Normal    NotTriggerScaleUp   pod/swebench-run-24856-32568   Pod didn't trigger scale-up:
3m43s       Warning   FailedScheduling    pod/swebench-run-24857-28124   0/1 nodes are available: 1 Too many pods. no new claims to deallocate, preemption: 0/1 nodes are available: 1 No preemption victims found for incoming pod.
4m41s       Normal    NotTriggerScaleUp   pod/swebench-run-24857-28124   Pod didn't trigger scale-up:
3m43s       Warning   FailedScheduling    pod/swebench-run-24858-6800    0/1 nodes are available: 1 Too many pods. no new claims to deallocate, preemption: 0/1 nodes are available: 1 No preemption victims found for incoming pod.
4m41s       Normal    NotTriggerScaleUp   pod/swebench-run-24858-6800    Pod didn't trigger scale-up:
3m43s       Warning   FailedScheduling    pod/swebench-run-24859-13039   0/1 nodes are available: 1 Too many pods. no new claims to deallocate, preemption: 0/1 nodes are available: 1 No preemption victims found for incoming pod.
4m41s       Normal    NotTriggerScaleUp   pod/swebench-run-24859-13039   Pod didn't trigger scale-up:
3m43s       Warning   FailedScheduling    pod/swebench-run-24860-11468   0/1 nodes are available: 1 Too many pods. no new claims to deallocate, preemption: 0/1 nodes are available: 1 No preemption victims found for incoming pod.
4m41s       Normal    NotTriggerScaleUp   pod/swebench-run-24860-11468   Pod didn't trigger scale-up:
3m43s       Warning   FailedScheduling    pod/swebench-run-24861-23897   0/1 nodes are available: 1 Too many pods. no new claims to deallocate, preemption: 0/1 nodes are available: 1 No preemption victims found for incoming pod.
4m41s       Normal    NotTriggerScaleUp   pod/swebench-run-24861-23897   Pod didn't trigger scale-up:
3m43s       Warning   FailedScheduling    pod/swebench-run-24862-4498    0/1 nodes are available: 1 Too many pods. no new claims to deallocate, preemption: 0/1 nodes are available: 1 No preemption victims found for incoming pod.
4m41s       Normal    NotTriggerScaleUp   pod/swebench-run-24862-4498    Pod didn't trigger scale-up:
3m43s       Warning   FailedScheduling    pod/swebench-run-24863-12734   0/1 nodes are available: 1 Too many pods. no new claims to deallocate, preemption: 0/1 nodes are available: 1 No preemption victims found for incoming pod.
4m41s       Normal    NotTriggerScaleUp   pod/swebench-run-24863-12734   Pod didn't trigger scale-up:
3m43s       Warning   FailedScheduling    pod/swebench-run-24864-25205   0/1 nodes are available: 1 Too many pods. no new claims to deallocate, preemption: 0/1 nodes are available: 1 No preemption victims found for incoming pod.
4m41s       Normal    NotTriggerScaleUp   pod/swebench-run-24864-25205   Pod didn't trigger scale-up:
3m43s       Warning   FailedScheduling    pod/swebench-run-24865-20006   0/1 nodes are available: 1 Too many pods. no new claims to deallocate, preemption: 0/1 nodes are available: 1 No preemption victims found for incoming pod.
4m41s       Normal    NotTriggerScaleUp   pod/swebench-run-24865-20006   Pod didn't trigger scale-up:
3m43s       Warning   FailedScheduling    pod/swebench-run-24866-18905   0/1 nodes are available: 1 Too many pods. no new claims to deallocate, preemption: 0/1 nodes are available: 1 No preemption victims found for incoming pod.
4m31s       Normal    NotTriggerScaleUp   pod/swebench-run-24866-18905   Pod didn't trigger scale-up:
3m43s       Warning   FailedScheduling    pod/swebench-run-24867-4488    0/1 nodes are available: 1 Too many pods. no new claims to deallocate, preemption: 0/1 nodes are available: 1 No preemption victims found for incoming pod.
4m31s       Normal    NotTriggerScaleUp   pod/swebench-run-24867-4488    Pod didn't trigger scale-up:
3m43s       Warning   FailedScheduling    pod/swebench-run-24868-17820   0/1 nodes are available: 1 Too many pods. no new claims to deallocate, preemption: 0/1 nodes are available: 1 No preemption victims found for incoming pod.
4m41s       Normal    NotTriggerScaleUp   pod/swebench-run-24868-17820   Pod didn't trigger scale-up:
3m43s       Warning   FailedScheduling    pod/swebench-run-24869-8011    0/1 nodes are available: 1 Too many pods. no new claims to deallocate, preemption: 0/1 nodes are available: 1 No preemption victims found for incoming pod.
4m31s       Normal    NotTriggerScaleUp   pod/swebench-run-24869-8011    Pod didn't trigger scale-up:
4m31s       Normal    NotTriggerScaleUp   pod/swebench-run-24870-24596   Pod didn't trigger scale-up:
3m43s       Warning   FailedScheduling    pod/swebench-run-24870-24596   0/1 nodes are available: 1 Too many pods. no new claims to deallocate, preemption: 0/1 nodes are available: 1 No preemption victims found for incoming pod.
4m31s       Normal    NotTriggerScaleUp   pod/swebench-run-24871-8060    Pod didn't trigger scale-up:
3m43s       Warning   FailedScheduling    pod/swebench-run-24871-8060    0/1 nodes are available: 1 Too many pods. no new claims to deallocate, preemption: 0/1 nodes are available: 1 No preemption victims found for incoming pod.
3m43s       Warning   FailedScheduling    pod/swebench-run-24872-20568   0/1 nodes are available: 1 Too many pods. no new claims to deallocate, preemption: 0/1 nodes are available: 1 No preemption victims found for incoming pod.
4m31s       Normal    NotTriggerScaleUp   pod/swebench-run-24872-20568   Pod didn't trigger scale-up:
4m31s       Normal    NotTriggerScaleUp   pod/swebench-run-24873-22302   Pod didn't trigger scale-up:
3m43s       Warning   FailedScheduling    pod/swebench-run-24873-22302   0/1 nodes are available: 1 Too many pods. no new claims to deallocate, preemption: 0/1 nodes are available: 1 No preemption victims found for incoming pod.
4m31s       Normal    NotTriggerScaleUp   pod/swebench-run-24874-29497   Pod didn't trigger scale-up:
3m43s       Warning   FailedScheduling    pod/swebench-run-24874-29497   0/1 nodes are available: 1 Too many pods. no new claims to deallocate, preemption: 0/1 nodes are available: 1 No preemption victims found for incoming pod.
3m43s       Warning   FailedScheduling    pod/swebench-run-24875-23      0/1 nodes are available: 1 Too many pods. no new claims to deallocate, preemption: 0/1 nodes are available: 1 No preemption victims found for incoming pod.
4m11s       Normal    NotTriggerScaleUp   pod/swebench-run-24875-23      Pod didn't trigger scale-up:
3m43s       Warning   FailedScheduling    pod/swebench-run-24876-2852    0/1 nodes are available: 1 Too many pods. no new claims to deallocate, preemption: 0/1 nodes are available: 1 No preemption victims found for incoming pod.
4m31s       Normal    NotTriggerScaleUp   pod/swebench-run-24876-2852    Pod didn't trigger scale-up:
3m43s       Warning   FailedScheduling    pod/swebench-run-24877-32213   0/1 nodes are available: 1 Too many pods. no new claims to deallocate, preemption: 0/1 nodes are available: 1 No preemption victims found for incoming pod.
4m21s       Normal    NotTriggerScaleUp   pod/swebench-run-24877-32213   Pod didn't trigger scale-up:
3m43s       Warning   FailedScheduling    pod/swebench-run-24878-13996   0/1 nodes are available: 1 Too many pods. no new claims to deallocate, preemption: 0/1 nodes are available: 1 No preemption victims found for incoming pod.
4m21s       Normal    NotTriggerScaleUp   pod/swebench-run-24878-13996   Pod didn't trigger scale-up:
3m43s       Warning   FailedScheduling    pod/swebench-run-24879-24709   0/1 nodes are available: 1 Too many pods. no new claims to deallocate, preemption: 0/1 nodes are available: 1 No preemption victims found for incoming pod.
4m11s       Normal    NotTriggerScaleUp   pod/swebench-run-24879-24709   Pod didn't trigger scale-up:
4m21s       Normal    NotTriggerScaleUp   pod/swebench-run-24880-18143   Pod didn't trigger scale-up:
3m43s       Warning   FailedScheduling    pod/swebench-run-24880-18143   0/1 nodes are available: 1 Too many pods. no new claims to deallocate, preemption: 0/1 nodes are available: 1 No preemption victims found for incoming pod.
4m21s       Normal    NotTriggerScaleUp   pod/swebench-run-24881-28763   Pod didn't trigger scale-up:
3m43s       Warning   FailedScheduling    pod/swebench-run-24881-28763   0/1 nodes are available: 1 Too many pods. no new claims to deallocate, preemption: 0/1 nodes are available: 1 No preemption victims found for incoming pod.
3m43s       Warning   FailedScheduling    pod/swebench-run-24882-28187   0/1 nodes are available: 1 Too many pods. no new claims to deallocate, preemption: 0/1 nodes are available: 1 No preemption victims found for incoming pod.
4m11s       Normal    NotTriggerScaleUp   pod/swebench-run-24882-28187   Pod didn't trigger scale-up:
3m43s       Warning   FailedScheduling    pod/swebench-run-24883-15103   0/1 nodes are available: 1 Too many pods. no new claims to deallocate, preemption: 0/1 nodes are available: 1 No preemption victims found for incoming pod.
4m11s       Normal    NotTriggerScaleUp   pod/swebench-run-24883-15103   Pod didn't trigger scale-up:
4m21s       Normal    NotTriggerScaleUp   pod/swebench-run-24884-10842   Pod didn't trigger scale-up:
3m43s       Warning   FailedScheduling    pod/swebench-run-24884-10842   0/1 nodes are available: 1 Too many pods. no new claims to deallocate, preemption: 0/1 nodes are available: 1 No preemption victims found for incoming pod.
4m11s       Normal    NotTriggerScaleUp   pod/swebench-run-24885-23151   Pod didn't trigger scale-up:
3m43s       Warning   FailedScheduling    pod/swebench-run-24885-23151   0/1 nodes are available: 1 Too many pods. no new claims to deallocate, preemption: 0/1 nodes are available: 1 No preemption victims found for incoming pod.
3m43s       Warning   FailedScheduling    pod/swebench-run-24886-6901    0/1 nodes are available: 1 Too many pods. no new claims to deallocate, preemption: 0/1 nodes are available: 1 No preemption victims found for incoming pod.
4m11s       Normal    NotTriggerScaleUp   pod/swebench-run-24886-6901    Pod didn't trigger scale-up:
3m43s       Warning   FailedScheduling    pod/swebench-run-24887-29578   0/1 nodes are available: 1 Too many pods. no new claims to deallocate, preemption: 0/1 nodes are available: 1 No preemption victims found for incoming pod.
4m11s       Normal    NotTriggerScaleUp   pod/swebench-run-24887-29578   Pod didn't trigger scale-up:
4m11s       Normal    NotTriggerScaleUp   pod/swebench-run-24888-953     Pod didn't trigger scale-up:
3m43s       Warning   FailedScheduling    pod/swebench-run-24888-953     0/1 nodes are available: 1 Too many pods. no new claims to deallocate, preemption: 0/1 nodes are available: 1 No preemption victims found for incoming pod.
4m21s       Normal    NotTriggerScaleUp   pod/swebench-run-24889-14073   Pod didn't trigger scale-up:
3m43s       Warning   FailedScheduling    pod/swebench-run-24889-14073   0/1 nodes are available: 1 Too many pods. no new claims to deallocate, preemption: 0/1 nodes are available: 1 No preemption victims found for incoming pod.
3m43s       Warning   FailedScheduling    pod/swebench-run-24890-603     0/1 nodes are available: 1 Too many pods. no new claims to deallocate, preemption: 0/1 nodes are available: 1 No preemption victims found for incoming pod.
4m          Normal    NotTriggerScaleUp   pod/swebench-run-24890-603     Pod didn't trigger scale-up:
3m43s       Warning   FailedScheduling    pod/swebench-run-24891-7296    0/1 nodes are available: 1 Too many pods. no new claims to deallocate, preemption: 0/1 nodes are available: 1 No preemption victims found for incoming pod.
4m11s       Normal    NotTriggerScaleUp   pod/swebench-run-24891-7296    Pod didn't trigger scale-up:
4m11s       Normal    NotTriggerScaleUp   pod/swebench-run-24892-10478   Pod didn't trigger scale-up:
3m43s       Warning   FailedScheduling    pod/swebench-run-24892-10478   0/1 nodes are available: 1 Too many pods. no new claims to deallocate, preemption: 0/1 nodes are available: 1 No preemption victims found for incoming pod.
3m43s       Warning   FailedScheduling    pod/swebench-run-24893-20669   0/1 nodes are available: 1 Too many pods. no new claims to deallocate, preemption: 0/1 nodes are available: 1 No preemption victims found for incoming pod.
4m11s       Normal    NotTriggerScaleUp   pod/swebench-run-24893-20669   Pod didn't trigger scale-up:
4m11s       Normal    NotTriggerScaleUp   pod/swebench-run-24894-11546   Pod didn't trigger scale-up:
3m43s       Warning   FailedScheduling    pod/swebench-run-24894-11546   0/1 nodes are available: 1 Too many pods. no new claims to deallocate, preemption: 0/1 nodes are available: 1 No preemption victims found for incoming pod.
4m11s       Normal    NotTriggerScaleUp   pod/swebench-run-24895-3000    Pod didn't trigger scale-up:
3m43s       Warning   FailedScheduling    pod/swebench-run-24895-3000    0/1 nodes are available: 1 Too many pods. no new claims to deallocate, preemption: 0/1 nodes are available: 1 No preemption victims found for incoming pod.
3m43s       Warning   FailedScheduling    pod/swebench-run-24896-26936   0/1 nodes are available: 1 Too many pods. no new claims to deallocate, preemption: 0/1 nodes are available: 1 No preemption victims found for incoming pod.
4m11s       Normal    NotTriggerScaleUp   pod/swebench-run-24896-26936   Pod didn't trigger scale-up:
4m11s       Normal    NotTriggerScaleUp   pod/swebench-run-24897-17314   Pod didn't trigger scale-up:
3m43s       Warning   FailedScheduling    pod/swebench-run-24897-17314   0/1 nodes are available: 1 Too many pods. no new claims to deallocate, preemption: 0/1 nodes are available: 1 No preemption victims found for incoming pod.
3m43s       Warning   FailedScheduling    pod/swebench-run-24898-13447   0/1 nodes are available: 1 Too many pods. no new claims to deallocate, preemption: 0/1 nodes are available: 1 No preemption victims found for incoming pod.
4m11s       Normal    NotTriggerScaleUp   pod/swebench-run-24898-13447   Pod didn't trigger scale-up:
4m11s       Normal    NotTriggerScaleUp   pod/swebench-run-24899-11307   Pod didn't trigger scale-up:
3m43s       Warning   FailedScheduling    pod/swebench-run-24899-11307   0/1 nodes are available: 1 Too many pods. no new claims to deallocate, preemption: 0/1 nodes are available: 1 No preemption victims found for incoming pod.
3m43s       Warning   FailedScheduling    pod/swebench-run-24900-13917   0/1 nodes are available: 1 Too many pods. no new claims to deallocate, preemption: 0/1 nodes are available: 1 No preemption victims found for incoming pod.
4m          Normal    NotTriggerScaleUp   pod/swebench-run-24900-13917   Pod didn't trigger scale-up:
3m43s       Warning   FailedScheduling    pod/swebench-run-24901-1846    0/1 nodes are available: 1 Too many pods. no new claims to deallocate, preemption: 0/1 nodes are available: 1 No preemption victims found for incoming pod.
4m11s       Normal    NotTriggerScaleUp   pod/swebench-run-24901-1846    Pod didn't trigger scale-up:
3m43s       Warning   FailedScheduling    pod/swebench-run-24902-2647    0/1 nodes are available: 1 Too many pods. no new claims to deallocate, preemption: 0/1 nodes are available: 1 No preemption victims found for incoming pod.
4m11s       Normal    NotTriggerScaleUp   pod/swebench-run-24902-2647    Pod didn't trigger scale-up:
3m43s       Warning   FailedScheduling    pod/swebench-run-24903-29537   0/1 nodes are available: 1 Too many pods. no new claims to deallocate, preemption: 0/1 nodes are available: 1 No preemption victims found for incoming pod.
4m          Normal    NotTriggerScaleUp   pod/swebench-run-24903-29537   Pod didn't trigger scale-up:
4m11s       Normal    NotTriggerScaleUp   pod/swebench-run-24904-5281    Pod didn't trigger scale-up:
3m43s       Warning   FailedScheduling    pod/swebench-run-24904-5281    0/1 nodes are available: 1 Too many pods. no new claims to deallocate, preemption: 0/1 nodes are available: 1 No preemption victims found for incoming pod.
4m11s       Normal    NotTriggerScaleUp   pod/swebench-run-24905-6195    Pod didn't trigger scale-up:
3m44s       Warning   FailedScheduling    pod/swebench-run-24905-6195    0/1 nodes are available: 1 Too many pods. no new claims to deallocate, preemption: 0/1 nodes are available: 1 No preemption victims found for incoming pod.
3m44s       Warning   FailedScheduling    pod/swebench-run-24906-22354   0/1 nodes are available: 1 Too many pods. no new claims to deallocate, preemption: 0/1 nodes are available: 1 No preemption victims found for incoming pod.
4m42s       Normal    NotTriggerScaleUp   pod/swebench-run-24906-22354   Pod didn't trigger scale-up:
3m44s       Warning   FailedScheduling    pod/swebench-run-24907-10514   0/1 nodes are available: 1 Too many pods. no new claims to deallocate, preemption: 0/1 nodes are available: 1 No preemption victims found for incoming pod.
4m42s       Normal    NotTriggerScaleUp   pod/swebench-run-24907-10514   Pod didn't trigger scale-up:
3m44s       Warning   FailedScheduling    pod/swebench-run-24908-15563   0/1 nodes are available: 1 Too many pods. no new claims to deallocate, preemption: 0/1 nodes are available: 1 No preemption victims found for incoming pod.
4m42s       Normal    NotTriggerScaleUp   pod/swebench-run-24908-15563   Pod didn't trigger scale-up:
3m44s       Warning   FailedScheduling    pod/swebench-run-24909-13785   0/1 nodes are available: 1 Too many pods. no new claims to deallocate, preemption: 0/1 nodes are available: 1 No preemption victims found for incoming pod.
4m42s       Normal    NotTriggerScaleUp   pod/swebench-run-24909-13785   Pod didn't trigger scale-up:
3m44s       Warning   FailedScheduling    pod/swebench-run-24910-32729   0/1 nodes are available: 1 Too many pods. no new claims to deallocate, preemption: 0/1 nodes are available: 1 No preemption victims found for incoming pod.
4m42s       Normal    NotTriggerScaleUp   pod/swebench-run-24910-32729   Pod didn't trigger scale-up:
3m44s       Warning   FailedScheduling    pod/swebench-run-24911-19149   0/1 nodes are available: 1 Too many pods. no new claims to deallocate, preemption: 0/1 nodes are available: 1 No preemption victims found for incoming pod.
4m42s       Normal    NotTriggerScaleUp   pod/swebench-run-24911-19149   Pod didn't trigger scale-up:
3m44s       Warning   FailedScheduling    pod/swebench-run-24912-18522   0/1 nodes are available: 1 Too many pods. no new claims to deallocate, preemption: 0/1 nodes are available: 1 No preemption victims found for incoming pod.
4m42s       Normal    NotTriggerScaleUp   pod/swebench-run-24912-18522   Pod didn't trigger scale-up:
3m44s       Warning   FailedScheduling    pod/swebench-run-24913-26517   0/1 nodes are available: 1 Too many pods. no new claims to deallocate, preemption: 0/1 nodes are available: 1 No preemption victims found for incoming pod.
4m42s       Normal    NotTriggerScaleUp   pod/swebench-run-24913-26517   Pod didn't trigger scale-up:
3m44s       Warning   FailedScheduling    pod/swebench-run-24914-5677    0/1 nodes are available: 1 Too many pods. no new claims to deallocate, preemption: 0/1 nodes are available: 1 No preemption victims found for incoming pod.
4m42s       Normal    NotTriggerScaleUp   pod/swebench-run-24914-5677    Pod didn't trigger scale-up:
3m44s       Warning   FailedScheduling    pod/swebench-run-24915-24547   0/1 nodes are available: 1 Too many pods. no new claims to deallocate, preemption: 0/1 nodes are available: 1 No preemption victims found for incoming pod.
4m32s       Normal    NotTriggerScaleUp   pod/swebench-run-24915-24547   Pod didn't trigger scale-up:
3m44s       Warning   FailedScheduling    pod/swebench-run-24916-32227   0/1 nodes are available: 1 Too many pods. no new claims to deallocate, preemption: 0/1 nodes are available: 1 No preemption victims found for incoming pod.
4m32s       Normal    NotTriggerScaleUp   pod/swebench-run-24916-32227   Pod didn't trigger scale-up:
3m44s       Warning   FailedScheduling    pod/swebench-run-24917-960     0/1 nodes are available: 1 Too many pods. no new claims to deallocate, preemption: 0/1 nodes are available: 1 No preemption victims found for incoming pod.
4m42s       Normal    NotTriggerScaleUp   pod/swebench-run-24917-960     Pod didn't trigger scale-up:
3m44s       Warning   FailedScheduling    pod/swebench-run-24918-23574   0/1 nodes are available: 1 Too many pods. no new claims to deallocate, preemption: 0/1 nodes are available: 1 No preemption victims found for incoming pod.
4m32s       Normal    NotTriggerScaleUp   pod/swebench-run-24918-23574   Pod didn't trigger scale-up:
4m32s       Normal    NotTriggerScaleUp   pod/swebench-run-24919-26313   Pod didn't trigger scale-up:
3m44s       Warning   FailedScheduling    pod/swebench-run-24919-26313   0/1 nodes are available: 1 Too many pods. no new claims to deallocate, preemption: 0/1 nodes are available: 1 No preemption victims found for incoming pod.
3m44s       Warning   FailedScheduling    pod/swebench-run-24920-19870   0/1 nodes are available: 1 Too many pods. no new claims to deallocate, preemption: 0/1 nodes are available: 1 No preemption victims found for incoming pod.
4m32s       Normal    NotTriggerScaleUp   pod/swebench-run-24920-19870   Pod didn't trigger scale-up:
3m44s       Warning   FailedScheduling    pod/swebench-run-24921-28892   0/1 nodes are available: 1 Too many pods. no new claims to deallocate, preemption: 0/1 nodes are available: 1 No preemption victims found for incoming pod.
4m32s       Normal    NotTriggerScaleUp   pod/swebench-run-24921-28892   Pod didn't trigger scale-up:
3m44s       Warning   FailedScheduling    pod/swebench-run-24922-27142   0/1 nodes are available: 1 Too many pods. no new claims to deallocate, preemption: 0/1 nodes are available: 1 No preemption victims found for incoming pod.
4m22s       Normal    NotTriggerScaleUp   pod/swebench-run-24922-27142   Pod didn't trigger scale-up:
3m44s       Warning   FailedScheduling    pod/swebench-run-24923-22599   0/1 nodes are available: 1 Too many pods. no new claims to deallocate, preemption: 0/1 nodes are available: 1 No preemption victims found for incoming pod.
4m22s       Normal    NotTriggerScaleUp   pod/swebench-run-24923-22599   Pod didn't trigger scale-up:
3m44s       Warning   FailedScheduling    pod/swebench-run-24924-27342   0/1 nodes are available: 1 Too many pods. no new claims to deallocate, preemption: 0/1 nodes are available: 1 No preemption victims found for incoming pod.
4m12s       Normal    NotTriggerScaleUp   pod/swebench-run-24924-27342   Pod didn't trigger scale-up:
3m44s       Warning   FailedScheduling    pod/swebench-run-24925-22119   0/1 nodes are available: 1 Too many pods. no new claims to deallocate, preemption: 0/1 nodes are available: 1 No preemption victims found for incoming pod.
4m12s       Normal    NotTriggerScaleUp   pod/swebench-run-24925-22119   Pod didn't trigger scale-up:
3m44s       Warning   FailedScheduling    pod/swebench-run-24926-8583    0/1 nodes are available: 1 Too many pods. no new claims to deallocate, preemption: 0/1 nodes are available: 1 No preemption victims found for incoming pod.
4m22s       Normal    NotTriggerScaleUp   pod/swebench-run-24926-8583    Pod didn't trigger scale-up:
4m22s       Normal    NotTriggerScaleUp   pod/swebench-run-24927-22026   Pod didn't trigger scale-up:
3m44s       Warning   FailedScheduling    pod/swebench-run-24927-22026   0/1 nodes are available: 1 Too many pods. no new claims to deallocate, preemption: 0/1 nodes are available: 1 No preemption victims found for incoming pod.
4m22s       Normal    NotTriggerScaleUp   pod/swebench-run-24928-2458    Pod didn't trigger scale-up:
3m44s       Warning   FailedScheduling    pod/swebench-run-24928-2458    0/1 nodes are available: 1 Too many pods. no new claims to deallocate, preemption: 0/1 nodes are available: 1 No preemption victims found for incoming pod.
3m44s       Warning   FailedScheduling    pod/swebench-run-24929-3932    0/1 nodes are available: 1 Too many pods. no new claims to deallocate, preemption: 0/1 nodes are available: 1 No preemption victims found for incoming pod.
4m22s       Normal    NotTriggerScaleUp   pod/swebench-run-24929-3932    Pod didn't trigger scale-up:
4m22s       Normal    NotTriggerScaleUp   pod/swebench-run-24930-15214   Pod didn't trigger scale-up:
3m44s       Warning   FailedScheduling    pod/swebench-run-24930-15214   0/1 nodes are available: 1 Too many pods. no new claims to deallocate, preemption: 0/1 nodes are available: 1 No preemption victims found for incoming pod.
4m32s       Normal    NotTriggerScaleUp   pod/swebench-run-24931-8862    Pod didn't trigger scale-up:
3m44s       Warning   FailedScheduling    pod/swebench-run-24931-8862    0/1 nodes are available: 1 Too many pods. no new claims to deallocate, preemption: 0/1 nodes are available: 1 No preemption victims found for incoming pod.
3m44s       Warning   FailedScheduling    pod/swebench-run-24932-14551   0/1 nodes are available: 1 Too many pods. no new claims to deallocate, preemption: 0/1 nodes are available: 1 No preemption victims found for incoming pod.
4m12s       Normal    NotTriggerScaleUp   pod/swebench-run-24932-14551   Pod didn't trigger scale-up:
3m44s       Warning   FailedScheduling    pod/swebench-run-24933-28991   0/1 nodes are available: 1 Too many pods. no new claims to deallocate, preemption: 0/1 nodes are available: 1 No preemption victims found for incoming pod.
4m12s       Normal    NotTriggerScaleUp   pod/swebench-run-24933-28991   Pod didn't trigger scale-up:
3m44s       Warning   FailedScheduling    pod/swebench-run-24934-27726   0/1 nodes are available: 1 Too many pods. no new claims to deallocate, preemption: 0/1 nodes are available: 1 No preemption victims found for incoming pod.
4m12s       Normal    NotTriggerScaleUp   pod/swebench-run-24934-27726   Pod didn't trigger scale-up:
3m44s       Warning   FailedScheduling    pod/swebench-run-24935-17996   0/1 nodes are available: 1 Too many pods. no new claims to deallocate, preemption: 0/1 nodes are available: 1 No preemption victims found for incoming pod.
4m12s       Normal    NotTriggerScaleUp   pod/swebench-run-24935-17996   Pod didn't trigger scale-up:
3m44s       Warning   FailedScheduling    pod/swebench-run-24936-28688   0/1 nodes are available: 1 Too many pods. no new claims to deallocate, preemption: 0/1 nodes are available: 1 No preemption victims found for incoming pod.
4m12s       Normal    NotTriggerScaleUp   pod/swebench-run-24936-28688   Pod didn't trigger scale-up:
3m44s       Warning   FailedScheduling    pod/swebench-run-24937-27040   0/1 nodes are available: 1 Too many pods. no new claims to deallocate, preemption: 0/1 nodes are available: 1 No preemption victims found for incoming pod.
4m12s       Normal    NotTriggerScaleUp   pod/swebench-run-24937-27040   Pod didn't trigger scale-up:
4m12s       Normal    NotTriggerScaleUp   pod/swebench-run-24938-8260    Pod didn't trigger scale-up:
3m44s       Warning   FailedScheduling    pod/swebench-run-24938-8260    0/1 nodes are available: 1 Too many pods. no new claims to deallocate, preemption: 0/1 nodes are available: 1 No preemption victims found for incoming pod.
4m12s       Normal    NotTriggerScaleUp   pod/swebench-run-24939-20293   Pod didn't trigger scale-up:
3m44s       Warning   FailedScheduling    pod/swebench-run-24939-20293   0/1 nodes are available: 1 Too many pods. no new claims to deallocate, preemption: 0/1 nodes are available: 1 No preemption victims found for incoming pod.
4m12s       Normal    NotTriggerScaleUp   pod/swebench-run-24940-1803    Pod didn't trigger scale-up:
3m44s       Warning   FailedScheduling    pod/swebench-run-24940-1803    0/1 nodes are available: 1 Too many pods. no new claims to deallocate, preemption: 0/1 nodes are available: 1 No preemption victims found for incoming pod.
4m12s       Normal    NotTriggerScaleUp   pod/swebench-run-24941-21492   Pod didn't trigger scale-up:
3m44s       Warning   FailedScheduling    pod/swebench-run-24941-21492   0/1 nodes are available: 1 Too many pods. no new claims to deallocate, preemption: 0/1 nodes are available: 1 No preemption victims found for incoming pod.
4m12s       Normal    NotTriggerScaleUp   pod/swebench-run-24942-30879   Pod didn't trigger scale-up:
3m44s       Warning   FailedScheduling    pod/swebench-run-24942-30879   0/1 nodes are available: 1 Too many pods. no new claims to deallocate, preemption: 0/1 nodes are available: 1 No preemption victims found for incoming pod.
3m44s       Warning   FailedScheduling    pod/swebench-run-24943-19305   0/1 nodes are available: 1 Too many pods. no new claims to deallocate, preemption: 0/1 nodes are available: 1 No preemption victims found for incoming pod.
4m12s       Normal    NotTriggerScaleUp   pod/swebench-run-24943-19305   Pod didn't trigger scale-up:
3m44s       Warning   FailedScheduling    pod/swebench-run-24944-25365   0/1 nodes are available: 1 Too many pods. no new claims to deallocate, preemption: 0/1 nodes are available: 1 No preemption victims found for incoming pod.
4m12s       Normal    NotTriggerScaleUp   pod/swebench-run-24944-25365   Pod didn't trigger scale-up:
3m44s       Warning   FailedScheduling    pod/swebench-run-24945-28364   0/1 nodes are available: 1 Too many pods. no new claims to deallocate, preemption: 0/1 nodes are available: 1 No preemption victims found for incoming pod.
4m1s        Normal    NotTriggerScaleUp   pod/swebench-run-24945-28364   Pod didn't trigger scale-up:
4m12s       Normal    NotTriggerScaleUp   pod/swebench-run-24946-28833   Pod didn't trigger scale-up:
3m44s       Warning   FailedScheduling    pod/swebench-run-24946-28833   0/1 nodes are available: 1 Too many pods. no new claims to deallocate, preemption: 0/1 nodes are available: 1 No preemption victims found for incoming pod.
4m12s       Normal    NotTriggerScaleUp   pod/swebench-run-24947-27163   Pod didn't trigger scale-up:
3m44s       Warning   FailedScheduling    pod/swebench-run-24947-27163   0/1 nodes are available: 1 Too many pods. no new claims to deallocate, preemption: 0/1 nodes are available: 1 No preemption victims found for incoming pod.
3m44s       Warning   FailedScheduling    pod/swebench-run-24948-16639   0/1 nodes are available: 1 Too many pods. no new claims to deallocate, preemption: 0/1 nodes are available: 1 No preemption victims found for incoming pod.
4m12s       Normal    NotTriggerScaleUp   pod/swebench-run-24948-16639   Pod didn't trigger scale-up:
3m44s       Warning   FailedScheduling    pod/swebench-run-24949-10637   0/1 nodes are available: 1 Too many pods. no new claims to deallocate, preemption: 0/1 nodes are available: 1 No preemption victims found for incoming pod.
4m12s       Normal    NotTriggerScaleUp   pod/swebench-run-24949-10637   Pod didn't trigger scale-up:
3m44s       Warning   FailedScheduling    pod/swebench-run-24950-30828   0/1 nodes are available: 1 Too many pods. no new claims to deallocate, preemption: 0/1 nodes are available: 1 No preemption victims found for incoming pod.
4m12s       Normal    NotTriggerScaleUp   pod/swebench-run-24950-30828   Pod didn't trigger scale-up:
4m12s       Normal    NotTriggerScaleUp   pod/swebench-run-24951-11232   Pod didn't trigger scale-up:
3m44s       Warning   FailedScheduling    pod/swebench-run-24951-11232   0/1 nodes are available: 1 Too many pods. no new claims to deallocate, preemption: 0/1 nodes are available: 1 No preemption victims found for incoming pod.
3m44s       Warning   FailedScheduling    pod/swebench-run-24952-11008   0/1 nodes are available: 1 Too many pods. no new claims to deallocate, preemption: 0/1 nodes are available: 1 No preemption victims found for incoming pod.
4m12s       Normal    NotTriggerScaleUp   pod/swebench-run-24952-11008   Pod didn't trigger scale-up:
4m12s       Normal    NotTriggerScaleUp   pod/swebench-run-24953-21635   Pod didn't trigger scale-up:
3m44s       Warning   FailedScheduling    pod/swebench-run-24953-21635   0/1 nodes are available: 1 Too many pods. no new claims to deallocate, preemption: 0/1 nodes are available: 1 No preemption victims found for incoming pod.
3m44s       Warning   FailedScheduling    pod/swebench-run-24954-22178   0/1 nodes are available: 1 Too many pods. no new claims to deallocate, preemption: 0/1 nodes are available: 1 No preemption victims found for incoming pod.
4m1s        Normal    NotTriggerScaleUp   pod/swebench-run-24954-22178   Pod didn't trigger scale-up:
3m44s       Warning   FailedScheduling    pod/swebench-run-24955-12675   0/1 nodes are available: 1 Too many pods. no new claims to deallocate, preemption: 0/1 nodes are available: 1 No preemption victims found for incoming pod.
4m12s       Normal    NotTriggerScaleUp   pod/swebench-run-24955-12675   Pod didn't trigger scale-up:
3m44s       Warning   FailedScheduling    pod/swebench-run-24956-29230   0/1 nodes are available: 1 Too many pods. no new claims to deallocate, preemption: 0/1 nodes are available: 1 No preemption victims found for incoming pod.
4m42s       Normal    NotTriggerScaleUp   pod/swebench-run-24956-29230   Pod didn't trigger scale-up:
3m44s       Warning   FailedScheduling    pod/swebench-run-24957-28261   0/1 nodes are available: 1 Too many pods. no new claims to deallocate, preemption: 0/1 nodes are available: 1 No preemption victims found for incoming pod.
4m42s       Normal    NotTriggerScaleUp   pod/swebench-run-24957-28261   Pod didn't trigger scale-up:
3m44s       Warning   FailedScheduling    pod/swebench-run-24958-816     0/1 nodes are available: 1 Too many pods. no new claims to deallocate, preemption: 0/1 nodes are available: 1 No preemption victims found for incoming pod.
4m42s       Normal    NotTriggerScaleUp   pod/swebench-run-24958-816     Pod didn't trigger scale-up:
3m44s       Warning   FailedScheduling    pod/swebench-run-24959-31547   0/1 nodes are available: 1 Too many pods. no new claims to deallocate, preemption: 0/1 nodes are available: 1 No preemption victims found for incoming pod.
4m42s       Normal    NotTriggerScaleUp   pod/swebench-run-24959-31547   Pod didn't trigger scale-up:
3m44s       Warning   FailedScheduling    pod/swebench-run-24960-16391   0/1 nodes are available: 1 Too many pods. no new claims to deallocate, preemption: 0/1 nodes are available: 1 No preemption victims found for incoming pod.
4m42s       Normal    NotTriggerScaleUp   pod/swebench-run-24960-16391   Pod didn't trigger scale-up:
3m44s       Warning   FailedScheduling    pod/swebench-run-24961-21522   0/1 nodes are available: 1 Too many pods. no new claims to deallocate, preemption: 0/1 nodes are available: 1 No preemption victims found for incoming pod.
4m42s       Normal    NotTriggerScaleUp   pod/swebench-run-24961-21522   Pod didn't trigger scale-up:
3m44s       Warning   FailedScheduling    pod/swebench-run-24962-7472    0/1 nodes are available: 1 Too many pods. no new claims to deallocate, preemption: 0/1 nodes are available: 1 No preemption victims found for incoming pod.
4m42s       Normal    NotTriggerScaleUp   pod/swebench-run-24962-7472    Pod didn't trigger scale-up:
3m44s       Warning   FailedScheduling    pod/swebench-run-24963-27498   0/1 nodes are available: 1 Too many pods. no new claims to deallocate, preemption: 0/1 nodes are available: 1 No preemption victims found for incoming pod.
4m42s       Normal    NotTriggerScaleUp   pod/swebench-run-24963-27498   Pod didn't trigger scale-up:
3m44s       Warning   FailedScheduling    pod/swebench-run-24964-18753   0/1 nodes are available: 1 Too many pods. no new claims to deallocate, preemption: 0/1 nodes are available: 1 No preemption victims found for incoming pod.
4m32s       Normal    NotTriggerScaleUp   pod/swebench-run-24964-18753   Pod didn't trigger scale-up:
3m44s       Warning   FailedScheduling    pod/swebench-run-24965-20386   0/1 nodes are available: 1 Too many pods. no new claims to deallocate, preemption: 0/1 nodes are available: 1 No preemption victims found for incoming pod.
4m42s       Normal    NotTriggerScaleUp   pod/swebench-run-24965-20386   Pod didn't trigger scale-up:
4m32s       Normal    NotTriggerScaleUp   pod/swebench-run-24966-3741    Pod didn't trigger scale-up:
3m44s       Warning   FailedScheduling    pod/swebench-run-24966-3741    0/1 nodes are available: 1 Too many pods. no new claims to deallocate, preemption: 0/1 nodes are available: 1 No preemption victims found for incoming pod.
3m44s       Warning   FailedScheduling    pod/swebench-run-24967-30552   0/1 nodes are available: 1 Too many pods. no new claims to deallocate, preemption: 0/1 nodes are available: 1 No preemption victims found for incoming pod.
4m32s       Normal    NotTriggerScaleUp   pod/swebench-run-24967-30552   Pod didn't trigger scale-up:
4m32s       Normal    NotTriggerScaleUp   pod/swebench-run-24968-20270   Pod didn't trigger scale-up:
3m44s       Warning   FailedScheduling    pod/swebench-run-24968-20270   0/1 nodes are available: 1 Too many pods. no new claims to deallocate, preemption: 0/1 nodes are available: 1 No preemption victims found for incoming pod.
3m44s       Warning   FailedScheduling    pod/swebench-run-24969-1305    0/1 nodes are available: 1 Too many pods. no new claims to deallocate, preemption: 0/1 nodes are available: 1 No preemption victims found for incoming pod.
4m32s       Normal    NotTriggerScaleUp   pod/swebench-run-24969-1305    Pod didn't trigger scale-up:
3m44s       Warning   FailedScheduling    pod/swebench-run-24970-14086   0/1 nodes are available: 1 Too many pods. no new claims to deallocate, preemption: 0/1 nodes are available: 1 No preemption victims found for incoming pod.
4m32s       Normal    NotTriggerScaleUp   pod/swebench-run-24970-14086   Pod didn't trigger scale-up:
4m32s       Normal    NotTriggerScaleUp   pod/swebench-run-24971-13894   Pod didn't trigger scale-up:
3m44s       Warning   FailedScheduling    pod/swebench-run-24971-13894   0/1 nodes are available: 1 Too many pods. no new claims to deallocate, preemption: 0/1 nodes are available: 1 No preemption victims found for incoming pod.
3m44s       Warning   FailedScheduling    pod/swebench-run-24972-30268   0/1 nodes are available: 1 Too many pods. no new claims to deallocate, preemption: 0/1 nodes are available: 1 No preemption victims found for incoming pod.
4m22s       Normal    NotTriggerScaleUp   pod/swebench-run-24972-30268   Pod didn't trigger scale-up:
3m44s       Warning   FailedScheduling    pod/swebench-run-24973-13770   0/1 nodes are available: 1 Too many pods. no new claims to deallocate, preemption: 0/1 nodes are available: 1 No preemption victims found for incoming pod.
4m22s       Normal    NotTriggerScaleUp   pod/swebench-run-24973-13770   Pod didn't trigger scale-up:
3m44s       Warning   FailedScheduling    pod/swebench-run-24974-20082   0/1 nodes are available: 1 Too many pods. no new claims to deallocate, preemption: 0/1 nodes are available: 1 No preemption victims found for incoming pod.
4m32s       Normal    NotTriggerScaleUp   pod/swebench-run-24974-20082   Pod didn't trigger scale-up:
3m44s       Warning   FailedScheduling    pod/swebench-run-24975-21790   0/1 nodes are available: 1 Too many pods. no new claims to deallocate, preemption: 0/1 nodes are available: 1 No preemption victims found for incoming pod.
4m12s       Normal    NotTriggerScaleUp   pod/swebench-run-24975-21790   Pod didn't trigger scale-up:
4m22s       Normal    NotTriggerScaleUp   pod/swebench-run-24976-10613   Pod didn't trigger scale-up:
3m44s       Warning   FailedScheduling    pod/swebench-run-24976-10613   0/1 nodes are available: 1 Too many pods. no new claims to deallocate, preemption: 0/1 nodes are available: 1 No preemption victims found for incoming pod.
3m44s       Warning   FailedScheduling    pod/swebench-run-24977-30971   0/1 nodes are available: 1 Too many pods. no new claims to deallocate, preemption: 0/1 nodes are available: 1 No preemption victims found for incoming pod.
4m22s       Normal    NotTriggerScaleUp   pod/swebench-run-24977-30971   Pod didn't trigger scale-up:
4m32s       Normal    NotTriggerScaleUp   pod/swebench-run-24978-4885    Pod didn't trigger scale-up:
3m44s       Warning   FailedScheduling    pod/swebench-run-24978-4885    0/1 nodes are available: 1 Too many pods. no new claims to deallocate, preemption: 0/1 nodes are available: 1 No preemption victims found for incoming pod.
4m22s       Normal    NotTriggerScaleUp   pod/swebench-run-24979-17029   Pod didn't trigger scale-up:
3m44s       Warning   FailedScheduling    pod/swebench-run-24979-17029   0/1 nodes are available: 1 Too many pods. no new claims to deallocate, preemption: 0/1 nodes are available: 1 No preemption victims found for incoming pod.
3m44s       Warning   FailedScheduling    pod/swebench-run-24980-13865   0/1 nodes are available: 1 Too many pods. no new claims to deallocate, preemption: 0/1 nodes are available: 1 No preemption victims found for incoming pod.
4m22s       Normal    NotTriggerScaleUp   pod/swebench-run-24980-13865   Pod didn't trigger scale-up:
4m22s       Normal    NotTriggerScaleUp   pod/swebench-run-24981-6465    Pod didn't trigger scale-up:
3m44s       Warning   FailedScheduling    pod/swebench-run-24981-6465    0/1 nodes are available: 1 Too many pods. no new claims to deallocate, preemption: 0/1 nodes are available: 1 No preemption victims found for incoming pod.
4m22s       Normal    NotTriggerScaleUp   pod/swebench-run-24982-6945    Pod didn't trigger scale-up:
3m44s       Warning   FailedScheduling    pod/swebench-run-24982-6945    0/1 nodes are available: 1 Too many pods. no new claims to deallocate, preemption: 0/1 nodes are available: 1 No preemption victims found for incoming pod.
3m44s       Warning   FailedScheduling    pod/swebench-run-24983-8171    0/1 nodes are available: 1 Too many pods. no new claims to deallocate, preemption: 0/1 nodes are available: 1 No preemption victims found for incoming pod.
4m12s       Normal    NotTriggerScaleUp   pod/swebench-run-24983-8171    Pod didn't trigger scale-up:
4m12s       Normal    NotTriggerScaleUp   pod/swebench-run-24984-22819   Pod didn't trigger scale-up:
3m44s       Warning   FailedScheduling    pod/swebench-run-24984-22819   0/1 nodes are available: 1 Too many pods. no new claims to deallocate, preemption: 0/1 nodes are available: 1 No preemption victims found for incoming pod.
3m44s       Warning   FailedScheduling    pod/swebench-run-24985-28320   0/1 nodes are available: 1 Too many pods. no new claims to deallocate, preemption: 0/1 nodes are available: 1 No preemption victims found for incoming pod.
4m12s       Normal    NotTriggerScaleUp   pod/swebench-run-24985-28320   Pod didn't trigger scale-up:
4m22s       Normal    NotTriggerScaleUp   pod/swebench-run-24986-24659   Pod didn't trigger scale-up:
3m44s       Warning   FailedScheduling    pod/swebench-run-24986-24659   0/1 nodes are available: 1 Too many pods. no new claims to deallocate, preemption: 0/1 nodes are available: 1 No preemption victims found for incoming pod.
4m12s       Normal    NotTriggerScaleUp   pod/swebench-run-24987-8127    Pod didn't trigger scale-up:
3m44s       Warning   FailedScheduling    pod/swebench-run-24987-8127    0/1 nodes are available: 1 Too many pods. no new claims to deallocate, preemption: 0/1 nodes are available: 1 No preemption victims found for incoming pod.
4m12s       Normal    NotTriggerScaleUp   pod/swebench-run-24988-3215    Pod didn't trigger scale-up:
3m44s       Warning   FailedScheduling    pod/swebench-run-24988-3215    0/1 nodes are available: 1 Too many pods. no new claims to deallocate, preemption: 0/1 nodes are available: 1 No preemption victims found for incoming pod.
3m44s       Warning   FailedScheduling    pod/swebench-run-24989-27349   0/1 nodes are available: 1 Too many pods. no new claims to deallocate, preemption: 0/1 nodes are available: 1 No preemption victims found for incoming pod.
4m12s       Normal    NotTriggerScaleUp   pod/swebench-run-24989-27349   Pod didn't trigger scale-up:
3m44s       Warning   FailedScheduling    pod/swebench-run-24990-5880    0/1 nodes are available: 1 Too many pods. no new claims to deallocate, preemption: 0/1 nodes are available: 1 No preemption victims found for incoming pod.
4m12s       Normal    NotTriggerScaleUp   pod/swebench-run-24990-5880    Pod didn't trigger scale-up:
3m44s       Warning   FailedScheduling    pod/swebench-run-24991-1386    0/1 nodes are available: 1 Too many pods. no new claims to deallocate, preemption: 0/1 nodes are available: 1 No preemption victims found for incoming pod.
4m12s       Normal    NotTriggerScaleUp   pod/swebench-run-24991-1386    Pod didn't trigger scale-up:
4m12s       Normal    NotTriggerScaleUp   pod/swebench-run-24992-15122   Pod didn't trigger scale-up:
3m44s       Warning   FailedScheduling    pod/swebench-run-24992-15122   0/1 nodes are available: 1 Too many pods. no new claims to deallocate, preemption: 0/1 nodes are available: 1 No preemption victims found for incoming pod.
4m12s       Normal    NotTriggerScaleUp   pod/swebench-run-24993-17722   Pod didn't trigger scale-up:
3m44s       Warning   FailedScheduling    pod/swebench-run-24993-17722   0/1 nodes are available: 1 Too many pods. no new claims to deallocate, preemption: 0/1 nodes are available: 1 No preemption victims found for incoming pod.
3m44s       Warning   FailedScheduling    pod/swebench-run-24994-8959    0/1 nodes are available: 1 Too many pods. no new claims to deallocate, preemption: 0/1 nodes are available: 1 No preemption victims found for incoming pod.
4m12s       Normal    NotTriggerScaleUp   pod/swebench-run-24994-8959    Pod didn't trigger scale-up:
4m12s       Normal    NotTriggerScaleUp   pod/swebench-run-24995-382     Pod didn't trigger scale-up:
3m44s       Warning   FailedScheduling    pod/swebench-run-24995-382     0/1 nodes are available: 1 Too many pods. no new claims to deallocate, preemption: 0/1 nodes are available: 1 No preemption victims found for incoming pod.
3m44s       Warning   FailedScheduling    pod/swebench-run-24996-30329   0/1 nodes are available: 1 Too many pods. no new claims to deallocate, preemption: 0/1 nodes are available: 1 No preemption victims found for incoming pod.
4m1s        Normal    NotTriggerScaleUp   pod/swebench-run-24996-30329   Pod didn't trigger scale-up:
3m44s       Warning   FailedScheduling    pod/swebench-run-24997-24335   0/1 nodes are available: 1 Too many pods. no new claims to deallocate, preemption: 0/1 nodes are available: 1 No preemption victims found for incoming pod.
4m12s       Normal    NotTriggerScaleUp   pod/swebench-run-24997-24335   Pod didn't trigger scale-up:
4m12s       Normal    NotTriggerScaleUp   pod/swebench-run-24998-10667   Pod didn't trigger scale-up:
3m44s       Warning   FailedScheduling    pod/swebench-run-24998-10667   0/1 nodes are available: 1 Too many pods. no new claims to deallocate, preemption: 0/1 nodes are available: 1 No preemption victims found for incoming pod.
3m44s       Warning   FailedScheduling    pod/swebench-run-24999-2963    0/1 nodes are available: 1 Too many pods. no new claims to deallocate, preemption: 0/1 nodes are available: 1 No preemption victims found for incoming pod.
4m1s        Normal    NotTriggerScaleUp   pod/swebench-run-24999-2963    Pod didn't trigger scale-up:
3m44s       Warning   FailedScheduling    pod/swebench-run-25000-22256   0/1 nodes are available: 1 Too many pods. no new claims to deallocate, preemption: 0/1 nodes are available: 1 No preemption victims found for incoming pod.
4m1s        Normal    NotTriggerScaleUp   pod/swebench-run-25000-22256   Pod didn't trigger scale-up:
3m44s       Warning   FailedScheduling    pod/swebench-run-25001-21616   0/1 nodes are available: 1 Too many pods. no new claims to deallocate, preemption: 0/1 nodes are available: 1 No preemption victims found for incoming pod.
4m12s       Normal    NotTriggerScaleUp   pod/swebench-run-25001-21616   Pod didn't trigger scale-up:
4m12s       Normal    NotTriggerScaleUp   pod/swebench-run-25002-16202   Pod didn't trigger scale-up:
3m44s       Warning   FailedScheduling    pod/swebench-run-25002-16202   0/1 nodes are available: 1 Too many pods. no new claims to deallocate, preemption: 0/1 nodes are available: 1 No preemption victims found for incoming pod.
3m44s       Warning   FailedScheduling    pod/swebench-run-25003-1629    0/1 nodes are available: 1 Too many pods. no new claims to deallocate, preemption: 0/1 nodes are available: 1 No preemption victims found for incoming pod.
4m1s        Normal    NotTriggerScaleUp   pod/swebench-run-25003-1629    Pod didn't trigger scale-up:
3m44s       Warning   FailedScheduling    pod/swebench-run-25004-12756   0/1 nodes are available: 1 Too many pods. no new claims to deallocate, preemption: 0/1 nodes are available: 1 No preemption victims found for incoming pod.
4m1s        Normal    NotTriggerScaleUp   pod/swebench-run-25004-12756   Pod didn't trigger scale-up:
3m44s       Warning   FailedScheduling    pod/swebench-run-25005-14431   0/1 nodes are available: 1 Too many pods. no new claims to deallocate, preemption: 0/1 nodes are available: 1 No preemption victims found for incoming pod.
4m1s        Normal    NotTriggerScaleUp   pod/swebench-run-25005-14431   Pod didn't trigger scale-up:
3m44s       Warning   FailedScheduling    pod/swebench-run-25006-1931    0/1 nodes are available: 1 Too many pods. no new claims to deallocate, preemption: 0/1 nodes are available: 1 No preemption victims found for incoming pod.
4m42s       Normal    NotTriggerScaleUp   pod/swebench-run-25006-1931    Pod didn't trigger scale-up:
3m44s       Warning   FailedScheduling    pod/swebench-run-25007-14542   0/1 nodes are available: 1 Too many pods. no new claims to deallocate, preemption: 0/1 nodes are available: 1 No preemption victims found for incoming pod.
4m42s       Normal    NotTriggerScaleUp   pod/swebench-run-25007-14542   Pod didn't trigger scale-up:
3m44s       Warning   FailedScheduling    pod/swebench-run-25008-29795   0/1 nodes are available: 1 Too many pods. no new claims to deallocate, preemption: 0/1 nodes are available: 1 No preemption victims found for incoming pod.
4m42s       Normal    NotTriggerScaleUp   pod/swebench-run-25008-29795   Pod didn't trigger scale-up:
3m44s       Warning   FailedScheduling    pod/swebench-run-25009-12738   0/1 nodes are available: 1 Too many pods. no new claims to deallocate, preemption: 0/1 nodes are available: 1 No preemption victims found for incoming pod.
4m42s       Normal    NotTriggerScaleUp   pod/swebench-run-25009-12738   Pod didn't trigger scale-up:
3m44s       Warning   FailedScheduling    pod/swebench-run-25010-30162   0/1 nodes are available: 1 Too many pods. no new claims to deallocate, preemption: 0/1 nodes are available: 1 No preemption victims found for incoming pod.
4m42s       Normal    NotTriggerScaleUp   pod/swebench-run-25010-30162   Pod didn't trigger scale-up:
3m44s       Warning   FailedScheduling    pod/swebench-run-25011-21265   0/1 nodes are available: 1 Too many pods. no new claims to deallocate, preemption: 0/1 nodes are available: 1 No preemption victims found for incoming pod.
4m42s       Normal    NotTriggerScaleUp   pod/swebench-run-25011-21265   Pod didn't trigger scale-up:
3m44s       Warning   FailedScheduling    pod/swebench-run-25012-8716    0/1 nodes are available: 1 Too many pods. no new claims to deallocate, preemption: 0/1 nodes are available: 1 No preemption victims found for incoming pod.
4m32s       Normal    NotTriggerScaleUp   pod/swebench-run-25012-8716    Pod didn't trigger scale-up:
3m44s       Warning   FailedScheduling    pod/swebench-run-25013-15379   0/1 nodes are available: 1 Too many pods. no new claims to deallocate, preemption: 0/1 nodes are available: 1 No preemption victims found for incoming pod.
4m32s       Normal    NotTriggerScaleUp   pod/swebench-run-25013-15379   Pod didn't trigger scale-up:
3m44s       Warning   FailedScheduling    pod/swebench-run-25014-6162    0/1 nodes are available: 1 Too many pods. no new claims to deallocate, preemption: 0/1 nodes are available: 1 No preemption victims found for incoming pod.
4m32s       Normal    NotTriggerScaleUp   pod/swebench-run-25014-6162    Pod didn't trigger scale-up:
3m44s       Warning   FailedScheduling    pod/swebench-run-25015-28084   0/1 nodes are available: 1 Too many pods. no new claims to deallocate, preemption: 0/1 nodes are available: 1 No preemption victims found for incoming pod.
4m32s       Normal    NotTriggerScaleUp   pod/swebench-run-25015-28084   Pod didn't trigger scale-up:
4m32s       Normal    NotTriggerScaleUp   pod/swebench-run-25016-12104   Pod didn't trigger scale-up:
3m44s       Warning   FailedScheduling    pod/swebench-run-25016-12104   0/1 nodes are available: 1 Too many pods. no new claims to deallocate, preemption: 0/1 nodes are available: 1 No preemption victims found for incoming pod.
3m44s       Warning   FailedScheduling    pod/swebench-run-25017-32146   0/1 nodes are available: 1 Too many pods. no new claims to deallocate, preemption: 0/1 nodes are available: 1 No preemption victims found for incoming pod.
4m32s       Normal    NotTriggerScaleUp   pod/swebench-run-25017-32146   Pod didn't trigger scale-up:
3m44s       Warning   FailedScheduling    pod/swebench-run-25018-30275   0/1 nodes are available: 1 Too many pods. no new claims to deallocate, preemption: 0/1 nodes are available: 1 No preemption victims found for incoming pod.
4m22s       Normal    NotTriggerScaleUp   pod/swebench-run-25018-30275   Pod didn't trigger scale-up:
4m32s       Normal    NotTriggerScaleUp   pod/swebench-run-25019-5666    Pod didn't trigger scale-up:
3m44s       Warning   FailedScheduling    pod/swebench-run-25019-5666    0/1 nodes are available: 1 Too many pods. no new claims to deallocate, preemption: 0/1 nodes are available: 1 No preemption victims found for incoming pod.
3m44s       Warning   FailedScheduling    pod/swebench-run-25020-2000    0/1 nodes are available: 1 Too many pods. no new claims to deallocate, preemption: 0/1 nodes are available: 1 No preemption victims found for incoming pod.
4m22s       Normal    NotTriggerScaleUp   pod/swebench-run-25020-2000    Pod didn't trigger scale-up:
3m44s       Warning   FailedScheduling    pod/swebench-run-25021-26630   0/1 nodes are available: 1 Too many pods. no new claims to deallocate, preemption: 0/1 nodes are available: 1 No preemption victims found for incoming pod.
4m12s       Normal    NotTriggerScaleUp   pod/swebench-run-25021-26630   Pod didn't trigger scale-up:
4m32s       Normal    NotTriggerScaleUp   pod/swebench-run-25022-31367   Pod didn't trigger scale-up:
3m44s       Warning   FailedScheduling    pod/swebench-run-25022-31367   0/1 nodes are available: 1 Too many pods. no new claims to deallocate, preemption: 0/1 nodes are available: 1 No preemption victims found for incoming pod.
3m44s       Warning   FailedScheduling    pod/swebench-run-25023-3951    0/1 nodes are available: 1 Too many pods. no new claims to deallocate, preemption: 0/1 nodes are available: 1 No preemption victims found for incoming pod.
4m22s       Normal    NotTriggerScaleUp   pod/swebench-run-25023-3951    Pod didn't trigger scale-up:
3m44s       Warning   FailedScheduling    pod/swebench-run-25024-30069   0/1 nodes are available: 1 Too many pods. no new claims to deallocate, preemption: 0/1 nodes are available: 1 No preemption victims found for incoming pod.
4m12s       Normal    NotTriggerScaleUp   pod/swebench-run-25024-30069   Pod didn't trigger scale-up:
3m44s       Warning   FailedScheduling    pod/swebench-run-25025-26667   0/1 nodes are available: 1 Too many pods. no new claims to deallocate, preemption: 0/1 nodes are available: 1 No preemption victims found for incoming pod.
4m12s       Normal    NotTriggerScaleUp   pod/swebench-run-25025-26667   Pod didn't trigger scale-up:
3m44s       Warning   FailedScheduling    pod/swebench-run-25026-15147   0/1 nodes are available: 1 Too many pods. no new claims to deallocate, preemption: 0/1 nodes are available: 1 No preemption victims found for incoming pod.
4m22s       Normal    NotTriggerScaleUp   pod/swebench-run-25026-15147   Pod didn't trigger scale-up:
3m44s       Warning   FailedScheduling    pod/swebench-run-25027-18700   0/1 nodes are available: 1 Too many pods. no new claims to deallocate, preemption: 0/1 nodes are available: 1 No preemption victims found for incoming pod.
4m12s       Normal    NotTriggerScaleUp   pod/swebench-run-25027-18700   Pod didn't trigger scale-up:
3m44s       Warning   FailedScheduling    pod/swebench-run-25028-8975    0/1 nodes are available: 1 Too many pods. no new claims to deallocate, preemption: 0/1 nodes are available: 1 No preemption victims found for incoming pod.
4m12s       Normal    NotTriggerScaleUp   pod/swebench-run-25028-8975    Pod didn't trigger scale-up:
4m22s       Normal    NotTriggerScaleUp   pod/swebench-run-25029-7855    Pod didn't trigger scale-up:
3m44s       Warning   FailedScheduling    pod/swebench-run-25029-7855    0/1 nodes are available: 1 Too many pods. no new claims to deallocate, preemption: 0/1 nodes are available: 1 No preemption victims found for incoming pod.
4m22s       Normal    NotTriggerScaleUp   pod/swebench-run-25030-29582   Pod didn't trigger scale-up:
3m44s       Warning   FailedScheduling    pod/swebench-run-25030-29582   0/1 nodes are available: 1 Too many pods. no new claims to deallocate, preemption: 0/1 nodes are available: 1 No preemption victims found for incoming pod.
4m22s       Normal    NotTriggerScaleUp   pod/swebench-run-25031-18905   Pod didn't trigger scale-up:
3m44s       Warning   FailedScheduling    pod/swebench-run-25031-18905   0/1 nodes are available: 1 Too many pods. no new claims to deallocate, preemption: 0/1 nodes are available: 1 No preemption victims found for incoming pod.
4m22s       Normal    NotTriggerScaleUp   pod/swebench-run-25032-24015   Pod didn't trigger scale-up:
3m44s       Warning   FailedScheduling    pod/swebench-run-25032-24015   0/1 nodes are available: 1 Too many pods. no new claims to deallocate, preemption: 0/1 nodes are available: 1 No preemption victims found for incoming pod.
4m12s       Normal    NotTriggerScaleUp   pod/swebench-run-25033-30872   Pod didn't trigger scale-up:
3m44s       Warning   FailedScheduling    pod/swebench-run-25033-30872   0/1 nodes are available: 1 Too many pods. no new claims to deallocate, preemption: 0/1 nodes are available: 1 No preemption victims found for incoming pod.
4m12s       Normal    NotTriggerScaleUp   pod/swebench-run-25034-28828   Pod didn't trigger scale-up:
3m44s       Warning   FailedScheduling    pod/swebench-run-25034-28828   0/1 nodes are available: 1 Too many pods. no new claims to deallocate, preemption: 0/1 nodes are available: 1 No preemption victims found for incoming pod.
4m12s       Normal    NotTriggerScaleUp   pod/swebench-run-25035-13988   Pod didn't trigger scale-up:
3m44s       Warning   FailedScheduling    pod/swebench-run-25035-13988   0/1 nodes are available: 1 Too many pods. no new claims to deallocate, preemption: 0/1 nodes are available: 1 No preemption victims found for incoming pod.
3m44s       Warning   FailedScheduling    pod/swebench-run-25036-24797   0/1 nodes are available: 1 Too many pods. no new claims to deallocate, preemption: 0/1 nodes are available: 1 No preemption victims found for incoming pod.
4m1s        Normal    NotTriggerScaleUp   pod/swebench-run-25036-24797   Pod didn't trigger scale-up:
3m44s       Warning   FailedScheduling    pod/swebench-run-25037-11885   0/1 nodes are available: 1 Too many pods. no new claims to deallocate, preemption: 0/1 nodes are available: 1 No preemption victims found for incoming pod.
4m1s        Normal    NotTriggerScaleUp   pod/swebench-run-25037-11885   Pod didn't trigger scale-up:
4m12s       Normal    NotTriggerScaleUp   pod/swebench-run-25038-18666   Pod didn't trigger scale-up:
3m44s       Warning   FailedScheduling    pod/swebench-run-25038-18666   0/1 nodes are available: 1 Too many pods. no new claims to deallocate, preemption: 0/1 nodes are available: 1 No preemption victims found for incoming pod.
3m44s       Warning   FailedScheduling    pod/swebench-run-25039-18404   0/1 nodes are available: 1 Too many pods. no new claims to deallocate, preemption: 0/1 nodes are available: 1 No preemption victims found for incoming pod.
4m1s        Normal    NotTriggerScaleUp   pod/swebench-run-25039-18404   Pod didn't trigger scale-up:
3m44s       Warning   FailedScheduling    pod/swebench-run-25040-25225   0/1 nodes are available: 1 Too many pods. no new claims to deallocate, preemption: 0/1 nodes are available: 1 No preemption victims found for incoming pod.
4m1s        Normal    NotTriggerScaleUp   pod/swebench-run-25040-25225   Pod didn't trigger scale-up:
4m12s       Normal    NotTriggerScaleUp   pod/swebench-run-25041-23438   Pod didn't trigger scale-up:
3m44s       Warning   FailedScheduling    pod/swebench-run-25041-23438   0/1 nodes are available: 1 Too many pods. no new claims to deallocate, preemption: 0/1 nodes are available: 1 No preemption victims found for incoming pod.
4m12s       Normal    NotTriggerScaleUp   pod/swebench-run-25042-16983   Pod didn't trigger scale-up:
3m44s       Warning   FailedScheduling    pod/swebench-run-25042-16983   0/1 nodes are available: 1 Too many pods. no new claims to deallocate, preemption: 0/1 nodes are available: 1 No preemption victims found for incoming pod.
3m44s       Warning   FailedScheduling    pod/swebench-run-25043-15622   0/1 nodes are available: 1 Too many pods. no new claims to deallocate, preemption: 0/1 nodes are available: 1 No preemption victims found for incoming pod.
4m12s       Normal    NotTriggerScaleUp   pod/swebench-run-25043-15622   Pod didn't trigger scale-up:
3m44s       Warning   FailedScheduling    pod/swebench-run-25044-6408    0/1 nodes are available: 1 Too many pods. no new claims to deallocate, preemption: 0/1 nodes are available: 1 No preemption victims found for incoming pod.
4m12s       Normal    NotTriggerScaleUp   pod/swebench-run-25044-6408    Pod didn't trigger scale-up:
3m44s       Warning   FailedScheduling    pod/swebench-run-25045-29425   0/1 nodes are available: 1 Too many pods. no new claims to deallocate, preemption: 0/1 nodes are available: 1 No preemption victims found for incoming pod.
4m1s        Normal    NotTriggerScaleUp   pod/swebench-run-25045-29425   Pod didn't trigger scale-up:
3m44s       Warning   FailedScheduling    pod/swebench-run-25046-24226   0/1 nodes are available: 1 Too many pods. no new claims to deallocate, preemption: 0/1 nodes are available: 1 No preemption victims found for incoming pod.
4m12s       Normal    NotTriggerScaleUp   pod/swebench-run-25046-24226   Pod didn't trigger scale-up:
4m12s       Normal    NotTriggerScaleUp   pod/swebench-run-25047-31981   Pod didn't trigger scale-up:
3m44s       Warning   FailedScheduling    pod/swebench-run-25047-31981   0/1 nodes are available: 1 Too many pods. no new claims to deallocate, preemption: 0/1 nodes are available: 1 No preemption victims found for incoming pod.
4m12s       Normal    NotTriggerScaleUp   pod/swebench-run-25048-2008    Pod didn't trigger scale-up:
3m44s       Warning   FailedScheduling    pod/swebench-run-25048-2008    0/1 nodes are available: 1 Too many pods. no new claims to deallocate, preemption: 0/1 nodes are available: 1 No preemption victims found for incoming pod.
3m44s       Warning   FailedScheduling    pod/swebench-run-25049-15035   0/1 nodes are available: 1 Too many pods. no new claims to deallocate, preemption: 0/1 nodes are available: 1 No preemption victims found for incoming pod.
4m1s        Normal    NotTriggerScaleUp   pod/swebench-run-25049-15035   Pod didn't trigger scale-up:
3m44s       Warning   FailedScheduling    pod/swebench-run-25050-7685    0/1 nodes are available: 1 Too many pods. no new claims to deallocate, preemption: 0/1 nodes are available: 1 No preemption victims found for incoming pod.
4m12s       Normal    NotTriggerScaleUp   pod/swebench-run-25050-7685    Pod didn't trigger scale-up:
4m12s       Normal    NotTriggerScaleUp   pod/swebench-run-25051-3475    Pod didn't trigger scale-up:
3m44s       Warning   FailedScheduling    pod/swebench-run-25051-3475    0/1 nodes are available: 1 Too many pods. no new claims to deallocate, preemption: 0/1 nodes are available: 1 No preemption victims found for incoming pod.
3m44s       Warning   FailedScheduling    pod/swebench-run-25052-20761   0/1 nodes are available: 1 Too many pods. no new claims to deallocate, preemption: 0/1 nodes are available: 1 No preemption victims found for incoming pod.
4m12s       Normal    NotTriggerScaleUp   pod/swebench-run-25052-20761   Pod didn't trigger scale-up:
3m44s       Warning   FailedScheduling    pod/swebench-run-25053-14269   0/1 nodes are available: 1 Too many pods. no new claims to deallocate, preemption: 0/1 nodes are available: 1 No preemption victims found for incoming pod.
4m12s       Normal    NotTriggerScaleUp   pod/swebench-run-25053-14269   Pod didn't trigger scale-up:
3m44s       Warning   FailedScheduling    pod/swebench-run-25054-17526   0/1 nodes are available: 1 Too many pods. no new claims to deallocate, preemption: 0/1 nodes are available: 1 No preemption victims found for incoming pod.
4m1s        Normal    NotTriggerScaleUp   pod/swebench-run-25054-17526   Pod didn't trigger scale-up:
4m12s       Normal    NotTriggerScaleUp   pod/swebench-run-25055-9356    Pod didn't trigger scale-up:
3m44s       Warning   FailedScheduling    pod/swebench-run-25055-9356    0/1 nodes are available: 1 Too many pods. no new claims to deallocate, preemption: 0/1 nodes are available: 1 No preemption victims found for incoming pod.
3m44s       Warning   FailedScheduling    pod/swebench-run-25056-8877    0/1 nodes are available: 1 Too many pods. no new claims to deallocate, preemption: 0/1 nodes are available: 1 No preemption victims found for incoming pod.
4m42s       Normal    NotTriggerScaleUp   pod/swebench-run-25056-8877    Pod didn't trigger scale-up:
3m44s       Warning   FailedScheduling    pod/swebench-run-25057-15245   0/1 nodes are available: 1 Too many pods. no new claims to deallocate, preemption: 0/1 nodes are available: 1 No preemption victims found for incoming pod.
4m42s       Normal    NotTriggerScaleUp   pod/swebench-run-25057-15245   Pod didn't trigger scale-up:
3m44s       Warning   FailedScheduling    pod/swebench-run-25058-4368    0/1 nodes are available: 1 Too many pods. no new claims to deallocate, preemption: 0/1 nodes are available: 1 No preemption victims found for incoming pod.
4m42s       Normal    NotTriggerScaleUp   pod/swebench-run-25058-4368    Pod didn't trigger scale-up:
3m44s       Warning   FailedScheduling    pod/swebench-run-25059-22039   0/1 nodes are available: 1 Too many pods. no new claims to deallocate, preemption: 0/1 nodes are available: 1 No preemption victims found for incoming pod.
4m42s       Normal    NotTriggerScaleUp   pod/swebench-run-25059-22039   Pod didn't trigger scale-up:
3m44s       Warning   FailedScheduling    pod/swebench-run-25060-29348   0/1 nodes are available: 1 Too many pods. no new claims to deallocate, preemption: 0/1 nodes are available: 1 No preemption victims found for incoming pod.
4m42s       Normal    NotTriggerScaleUp   pod/swebench-run-25060-29348   Pod didn't trigger scale-up:
3m44s       Warning   FailedScheduling    pod/swebench-run-25061-27887   0/1 nodes are available: 1 Too many pods. no new claims to deallocate, preemption: 0/1 nodes are available: 1 No preemption victims found for incoming pod.
4m42s       Normal    NotTriggerScaleUp   pod/swebench-run-25061-27887   Pod didn't trigger scale-up:
3m44s       Warning   FailedScheduling    pod/swebench-run-25062-9601    0/1 nodes are available: 1 Too many pods. no new claims to deallocate, preemption: 0/1 nodes are available: 1 No preemption victims found for incoming pod.
4m32s       Normal    NotTriggerScaleUp   pod/swebench-run-25062-9601    Pod didn't trigger scale-up:
3m44s       Warning   FailedScheduling    pod/swebench-run-25063-4033    0/1 nodes are available: 1 Too many pods. no new claims to deallocate, preemption: 0/1 nodes are available: 1 No preemption victims found for incoming pod.
4m32s       Normal    NotTriggerScaleUp   pod/swebench-run-25063-4033    Pod didn't trigger scale-up:
4m32s       Normal    NotTriggerScaleUp   pod/swebench-run-25064-24540   Pod didn't trigger scale-up:
3m44s       Warning   FailedScheduling    pod/swebench-run-25064-24540   0/1 nodes are available: 1 Too many pods. no new claims to deallocate, preemption: 0/1 nodes are available: 1 No preemption victims found for incoming pod.
3m44s       Warning   FailedScheduling    pod/swebench-run-25065-21985   0/1 nodes are available: 1 Too many pods. no new claims to deallocate, preemption: 0/1 nodes are available: 1 No preemption victims found for incoming pod.
4m32s       Normal    NotTriggerScaleUp   pod/swebench-run-25065-21985   Pod didn't trigger scale-up:
4m32s       Normal    NotTriggerScaleUp   pod/swebench-run-25066-5969    Pod didn't trigger scale-up:
3m44s       Warning   FailedScheduling    pod/swebench-run-25066-5969    0/1 nodes are available: 1 Too many pods. no new claims to deallocate, preemption: 0/1 nodes are available: 1 No preemption victims found for incoming pod.
4m32s       Normal    NotTriggerScaleUp   pod/swebench-run-25067-32236   Pod didn't trigger scale-up:
3m44s       Warning   FailedScheduling    pod/swebench-run-25067-32236   0/1 nodes are available: 1 Too many pods. no new claims to deallocate, preemption: 0/1 nodes are available: 1 No preemption victims found for incoming pod.
3m44s       Warning   FailedScheduling    pod/swebench-run-25068-3068    0/1 nodes are available: 1 Too many pods. no new claims to deallocate, preemption: 0/1 nodes are available: 1 No preemption victims found for incoming pod.
4m32s       Normal    NotTriggerScaleUp   pod/swebench-run-25068-3068    Pod didn't trigger scale-up:
4m32s       Normal    NotTriggerScaleUp   pod/swebench-run-25069-74      Pod didn't trigger scale-up:
3m44s       Warning   FailedScheduling    pod/swebench-run-25069-74      0/1 nodes are available: 1 Too many pods. no new claims to deallocate, preemption: 0/1 nodes are available: 1 No preemption victims found for incoming pod.
3m44s       Warning   FailedScheduling    pod/swebench-run-25070-29897   0/1 nodes are available: 1 Too many pods. no new claims to deallocate, preemption: 0/1 nodes are available: 1 No preemption victims found for incoming pod.
4m22s       Normal    NotTriggerScaleUp   pod/swebench-run-25070-29897   Pod didn't trigger scale-up:
3m44s       Warning   FailedScheduling    pod/swebench-run-25071-14693   0/1 nodes are available: 1 Too many pods. no new claims to deallocate, preemption: 0/1 nodes are available: 1 No preemption victims found for incoming pod.
4m22s       Normal    NotTriggerScaleUp   pod/swebench-run-25071-14693   Pod didn't trigger scale-up:
3m44s       Warning   FailedScheduling    pod/swebench-run-25072-32303   0/1 nodes are available: 1 Too many pods. no new claims to deallocate, preemption: 0/1 nodes are available: 1 No preemption victims found for incoming pod.
4m22s       Normal    NotTriggerScaleUp   pod/swebench-run-25072-32303   Pod didn't trigger scale-up:
3m44s       Warning   FailedScheduling    pod/swebench-run-25073-26563   0/1 nodes are available: 1 Too many pods. no new claims to deallocate, preemption: 0/1 nodes are available: 1 No preemption victims found for incoming pod.
4m12s       Normal    NotTriggerScaleUp   pod/swebench-run-25073-26563   Pod didn't trigger scale-up:
3m44s       Warning   FailedScheduling    pod/swebench-run-25074-15931   0/1 nodes are available: 1 Too many pods. no new claims to deallocate, preemption: 0/1 nodes are available: 1 No preemption victims found for incoming pod.
4m12s       Normal    NotTriggerScaleUp   pod/swebench-run-25074-15931   Pod didn't trigger scale-up:
3m44s       Warning   FailedScheduling    pod/swebench-run-25075-23530   0/1 nodes are available: 1 Too many pods. no new claims to deallocate, preemption: 0/1 nodes are available: 1 No preemption victims found for incoming pod.
4m22s       Normal    NotTriggerScaleUp   pod/swebench-run-25075-23530   Pod didn't trigger scale-up:
4m32s       Normal    NotTriggerScaleUp   pod/swebench-run-25076-22300   Pod didn't trigger scale-up:
3m44s       Warning   FailedScheduling    pod/swebench-run-25076-22300   0/1 nodes are available: 1 Too many pods. no new claims to deallocate, preemption: 0/1 nodes are available: 1 No preemption victims found for incoming pod.
4m22s       Normal    NotTriggerScaleUp   pod/swebench-run-25077-8231    Pod didn't trigger scale-up:
3m44s       Warning   FailedScheduling    pod/swebench-run-25077-8231    0/1 nodes are available: 1 Too many pods. no new claims to deallocate, preemption: 0/1 nodes are available: 1 No preemption victims found for incoming pod.
4m22s       Normal    NotTriggerScaleUp   pod/swebench-run-25078-14647   Pod didn't trigger scale-up:
3m44s       Warning   FailedScheduling    pod/swebench-run-25078-14647   0/1 nodes are available: 1 Too many pods. no new claims to deallocate, preemption: 0/1 nodes are available: 1 No preemption victims found for incoming pod.
4m22s       Normal    NotTriggerScaleUp   pod/swebench-run-25079-18371   Pod didn't trigger scale-up:
3m44s       Warning   FailedScheduling    pod/swebench-run-25079-18371   0/1 nodes are available: 1 Too many pods. no new claims to deallocate, preemption: 0/1 nodes are available: 1 No preemption victims found for incoming pod.
3m44s       Warning   FailedScheduling    pod/swebench-run-25080-21866   0/1 nodes are available: 1 Too many pods. no new claims to deallocate, preemption: 0/1 nodes are available: 1 No preemption victims found for incoming pod.
4m22s       Normal    NotTriggerScaleUp   pod/swebench-run-25080-21866   Pod didn't trigger scale-up:
3m44s       Warning   FailedScheduling    pod/swebench-run-25081-8513    0/1 nodes are available: 1 Too many pods. no new claims to deallocate, preemption: 0/1 nodes are available: 1 No preemption victims found for incoming pod.
4m12s       Normal    NotTriggerScaleUp   pod/swebench-run-25081-8513    Pod didn't trigger scale-up:
3m44s       Warning   FailedScheduling    pod/swebench-run-25082-12143   0/1 nodes are available: 1 Too many pods. no new claims to deallocate, preemption: 0/1 nodes are available: 1 No preemption victims found for incoming pod.
4m12s       Normal    NotTriggerScaleUp   pod/swebench-run-25082-12143   Pod didn't trigger scale-up:
3m44s       Warning   FailedScheduling    pod/swebench-run-25083-29919   0/1 nodes are available: 1 Too many pods. no new claims to deallocate, preemption: 0/1 nodes are available: 1 No preemption victims found for incoming pod.
4m12s       Normal    NotTriggerScaleUp   pod/swebench-run-25083-29919   Pod didn't trigger scale-up:
4m12s       Normal    NotTriggerScaleUp   pod/swebench-run-25084-10588   Pod didn't trigger scale-up:
3m44s       Warning   FailedScheduling    pod/swebench-run-25084-10588   0/1 nodes are available: 1 Too many pods. no new claims to deallocate, preemption: 0/1 nodes are available: 1 No preemption victims found for incoming pod.
4m12s       Normal    NotTriggerScaleUp   pod/swebench-run-25085-27556   Pod didn't trigger scale-up:
3m44s       Warning   FailedScheduling    pod/swebench-run-25085-27556   0/1 nodes are available: 1 Too many pods. no new claims to deallocate, preemption: 0/1 nodes are available: 1 No preemption victims found for incoming pod.
3m44s       Warning   FailedScheduling    pod/swebench-run-25086-12402   0/1 nodes are available: 1 Too many pods. no new claims to deallocate, preemption: 0/1 nodes are available: 1 No preemption victims found for incoming pod.
4m1s        Normal    NotTriggerScaleUp   pod/swebench-run-25086-12402   Pod didn't trigger scale-up:
4m12s       Normal    NotTriggerScaleUp   pod/swebench-run-25087-15872   Pod didn't trigger scale-up:
3m44s       Warning   FailedScheduling    pod/swebench-run-25087-15872   0/1 nodes are available: 1 Too many pods. no new claims to deallocate, preemption: 0/1 nodes are available: 1 No preemption victims found for incoming pod.
3m44s       Warning   FailedScheduling    pod/swebench-run-25088-17110   0/1 nodes are available: 1 Too many pods. no new claims to deallocate, preemption: 0/1 nodes are available: 1 No preemption victims found for incoming pod.
4m1s        Normal    NotTriggerScaleUp   pod/swebench-run-25088-17110   Pod didn't trigger scale-up:
3m44s       Warning   FailedScheduling    pod/swebench-run-25089-9933    0/1 nodes are available: 1 Too many pods. no new claims to deallocate, preemption: 0/1 nodes are available: 1 No preemption victims found for incoming pod.
4m12s       Normal    NotTriggerScaleUp   pod/swebench-run-25089-9933    Pod didn't trigger scale-up:
4m12s       Normal    NotTriggerScaleUp   pod/swebench-run-25090-15196   Pod didn't trigger scale-up:
3m44s       Warning   FailedScheduling    pod/swebench-run-25090-15196   0/1 nodes are available: 1 Too many pods. no new claims to deallocate, preemption: 0/1 nodes are available: 1 No preemption victims found for incoming pod.
4m12s       Normal    NotTriggerScaleUp   pod/swebench-run-25091-854     Pod didn't trigger scale-up:
3m44s       Warning   FailedScheduling    pod/swebench-run-25091-854     0/1 nodes are available: 1 Too many pods. no new claims to deallocate, preemption: 0/1 nodes are available: 1 No preemption victims found for incoming pod.
3m44s       Warning   FailedScheduling    pod/swebench-run-25092-32562   0/1 nodes are available: 1 Too many pods. no new claims to deallocate, preemption: 0/1 nodes are available: 1 No preemption victims found for incoming pod.
4m1s        Normal    NotTriggerScaleUp   pod/swebench-run-25092-32562   Pod didn't trigger scale-up:
3m44s       Warning   FailedScheduling    pod/swebench-run-25093-19670   0/1 nodes are available: 1 Too many pods. no new claims to deallocate, preemption: 0/1 nodes are available: 1 No preemption victims found for incoming pod.
4m1s        Normal    NotTriggerScaleUp   pod/swebench-run-25093-19670   Pod didn't trigger scale-up:
3m44s       Warning   FailedScheduling    pod/swebench-run-25094-10328   0/1 nodes are available: 1 Too many pods. no new claims to deallocate, preemption: 0/1 nodes are available: 1 No preemption victims found for incoming pod.
4m1s        Normal    NotTriggerScaleUp   pod/swebench-run-25094-10328   Pod didn't trigger scale-up:
3m44s       Warning   FailedScheduling    pod/swebench-run-25095-28988   0/1 nodes are available: 1 Too many pods. no new claims to deallocate, preemption: 0/1 nodes are available: 1 No preemption victims found for incoming pod.
4m12s       Normal    NotTriggerScaleUp   pod/swebench-run-25095-28988   Pod didn't trigger scale-up:
4m12s       Normal    NotTriggerScaleUp   pod/swebench-run-25096-27120   Pod didn't trigger scale-up:
3m44s       Warning   FailedScheduling    pod/swebench-run-25096-27120   0/1 nodes are available: 1 Too many pods. no new claims to deallocate, preemption: 0/1 nodes are available: 1 No preemption victims found for incoming pod.
3m44s       Warning   FailedScheduling    pod/swebench-run-25097-31192   0/1 nodes are available: 1 Too many pods. no new claims to deallocate, preemption: 0/1 nodes are available: 1 No preemption victims found for incoming pod.
4m1s        Normal    NotTriggerScaleUp   pod/swebench-run-25097-31192   Pod didn't trigger scale-up:
4m12s       Normal    NotTriggerScaleUp   pod/swebench-run-25098-9480    Pod didn't trigger scale-up:
3m44s       Warning   FailedScheduling    pod/swebench-run-25098-9480    0/1 nodes are available: 1 Too many pods. no new claims to deallocate, preemption: 0/1 nodes are available: 1 No preemption victims found for incoming pod.
3m44s       Warning   FailedScheduling    pod/swebench-run-25099-26604   0/1 nodes are available: 1 Too many pods. no new claims to deallocate, preemption: 0/1 nodes are available: 1 No preemption victims found for incoming pod.
4m12s       Normal    NotTriggerScaleUp   pod/swebench-run-25099-26604   Pod didn't trigger scale-up:
4m12s       Normal    NotTriggerScaleUp   pod/swebench-run-25100-6704    Pod didn't trigger scale-up:
3m44s       Warning   FailedScheduling    pod/swebench-run-25100-6704    0/1 nodes are available: 1 Too many pods. no new claims to deallocate, preemption: 0/1 nodes are available: 1 No preemption victims found for incoming pod.
3m44s       Warning   FailedScheduling    pod/swebench-run-25101-21772   0/1 nodes are available: 1 Too many pods. no new claims to deallocate, preemption: 0/1 nodes are available: 1 No preemption victims found for incoming pod.
4m1s        Normal    NotTriggerScaleUp   pod/swebench-run-25101-21772   Pod didn't trigger scale-up:
4m12s       Normal    NotTriggerScaleUp   pod/swebench-run-25102-26165   Pod didn't trigger scale-up:
3m44s       Warning   FailedScheduling    pod/swebench-run-25102-26165   0/1 nodes are available: 1 Too many pods. no new claims to deallocate, preemption: 0/1 nodes are available: 1 No preemption victims found for incoming pod.
3m44s       Warning   FailedScheduling    pod/swebench-run-25103-2936    0/1 nodes are available: 1 Too many pods. no new claims to deallocate, preemption: 0/1 nodes are available: 1 No preemption victims found for incoming pod.
4m12s       Normal    NotTriggerScaleUp   pod/swebench-run-25103-2936    Pod didn't trigger scale-up:
3m44s       Warning   FailedScheduling    pod/swebench-run-25104-13259   0/1 nodes are available: 1 Too many pods. no new claims to deallocate, preemption: 0/1 nodes are available: 1 No preemption victims found for incoming pod.
4m12s       Normal    NotTriggerScaleUp   pod/swebench-run-25104-13259   Pod didn't trigger scale-up:
4m12s       Normal    NotTriggerScaleUp   pod/swebench-run-25105-11739   Pod didn't trigger scale-up:
3m44s       Warning   FailedScheduling    pod/swebench-run-25105-11739   0/1 nodes are available: 1 Too many pods. no new claims to deallocate, preemption: 0/1 nodes are available: 1 No preemption victims found for incoming pod.
3m44s       Warning   FailedScheduling    pod/swebench-run-25106-2617    0/1 nodes are available: 1 Too many pods. no new claims to deallocate, preemption: 0/1 nodes are available: 1 No preemption victims found for incoming pod.
4m42s       Normal    NotTriggerScaleUp   pod/swebench-run-25106-2617    Pod didn't trigger scale-up:
3m44s       Warning   FailedScheduling    pod/swebench-run-25107-26752   0/1 nodes are available: 1 Too many pods. no new claims to deallocate, preemption: 0/1 nodes are available: 1 No preemption victims found for incoming pod.
4m42s       Normal    NotTriggerScaleUp   pod/swebench-run-25107-26752   Pod didn't trigger scale-up:
3m44s       Warning   FailedScheduling    pod/swebench-run-25108-20633   0/1 nodes are available: 1 Too many pods. no new claims to deallocate, preemption: 0/1 nodes are available: 1 No preemption victims found for incoming pod.
4m32s       Normal    NotTriggerScaleUp   pod/swebench-run-25108-20633   Pod didn't trigger scale-up:
3m44s       Warning   FailedScheduling    pod/swebench-run-25109-19021   0/1 nodes are available: 1 Too many pods. no new claims to deallocate, preemption: 0/1 nodes are available: 1 No preemption victims found for incoming pod.
4m42s       Normal    NotTriggerScaleUp   pod/swebench-run-25109-19021   Pod didn't trigger scale-up:
3m44s       Warning   FailedScheduling    pod/swebench-run-25110-1708    0/1 nodes are available: 1 Too many pods. no new claims to deallocate, preemption: 0/1 nodes are available: 1 No preemption victims found for incoming pod.
4m42s       Normal    NotTriggerScaleUp   pod/swebench-run-25110-1708    Pod didn't trigger scale-up:
3m44s       Warning   FailedScheduling    pod/swebench-run-25111-32626   0/1 nodes are available: 1 Too many pods. no new claims to deallocate, preemption: 0/1 nodes are available: 1 No preemption victims found for incoming pod.
4m32s       Normal    NotTriggerScaleUp   pod/swebench-run-25111-32626   Pod didn't trigger scale-up:
3m44s       Warning   FailedScheduling    pod/swebench-run-25112-32183   0/1 nodes are available: 1 Too many pods. no new claims to deallocate, preemption: 0/1 nodes are available: 1 No preemption victims found for incoming pod.
4m32s       Normal    NotTriggerScaleUp   pod/swebench-run-25112-32183   Pod didn't trigger scale-up:
4m32s       Normal    NotTriggerScaleUp   pod/swebench-run-25113-26466   Pod didn't trigger scale-up:
3m44s       Warning   FailedScheduling    pod/swebench-run-25113-26466   0/1 nodes are available: 1 Too many pods. no new claims to deallocate, preemption: 0/1 nodes are available: 1 No preemption victims found for incoming pod.
3m44s       Warning   FailedScheduling    pod/swebench-run-25114-28877   0/1 nodes are available: 1 Too many pods. no new claims to deallocate, preemption: 0/1 nodes are available: 1 No preemption victims found for incoming pod.
4m32s       Normal    NotTriggerScaleUp   pod/swebench-run-25114-28877   Pod didn't trigger scale-up:
4m32s       Normal    NotTriggerScaleUp   pod/swebench-run-25115-12367   Pod didn't trigger scale-up:
3m44s       Warning   FailedScheduling    pod/swebench-run-25115-12367   0/1 nodes are available: 1 Too many pods. no new claims to deallocate, preemption: 0/1 nodes are available: 1 No preemption victims found for incoming pod.
3m44s       Warning   FailedScheduling    pod/swebench-run-25116-16861   0/1 nodes are available: 1 Too many pods. no new claims to deallocate, preemption: 0/1 nodes are available: 1 No preemption victims found for incoming pod.
4m32s       Normal    NotTriggerScaleUp   pod/swebench-run-25116-16861   Pod didn't trigger scale-up:
3m44s       Warning   FailedScheduling    pod/swebench-run-25117-2318    0/1 nodes are available: 1 Too many pods. no new claims to deallocate, preemption: 0/1 nodes are available: 1 No preemption victims found for incoming pod.
4m32s       Normal    NotTriggerScaleUp   pod/swebench-run-25117-2318    Pod didn't trigger scale-up:
3m44s       Warning   FailedScheduling    pod/swebench-run-25118-28269   0/1 nodes are available: 1 Too many pods. no new claims to deallocate, preemption: 0/1 nodes are available: 1 No preemption victims found for incoming pod.
4m32s       Normal    NotTriggerScaleUp   pod/swebench-run-25118-28269   Pod didn't trigger scale-up:
4m32s       Normal    NotTriggerScaleUp   pod/swebench-run-25119-4209    Pod didn't trigger scale-up:
3m44s       Warning   FailedScheduling    pod/swebench-run-25119-4209    0/1 nodes are available: 1 Too many pods. no new claims to deallocate, preemption: 0/1 nodes are available: 1 No preemption victims found for incoming pod.
4m22s       Normal    NotTriggerScaleUp   pod/swebench-run-25120-14142   Pod didn't trigger scale-up:
3m44s       Warning   FailedScheduling    pod/swebench-run-25120-14142   0/1 nodes are available: 1 Too many pods. no new claims to deallocate, preemption: 0/1 nodes are available: 1 No preemption victims found for incoming pod.
3m44s       Warning   FailedScheduling    pod/swebench-run-25121-28231   0/1 nodes are available: 1 Too many pods. no new claims to deallocate, preemption: 0/1 nodes are available: 1 No preemption victims found for incoming pod.
4m22s       Normal    NotTriggerScaleUp   pod/swebench-run-25121-28231   Pod didn't trigger scale-up:
4m32s       Normal    NotTriggerScaleUp   pod/swebench-run-25122-187     Pod didn't trigger scale-up:
3m44s       Warning   FailedScheduling    pod/swebench-run-25122-187     0/1 nodes are available: 1 Too many pods. no new claims to deallocate, preemption: 0/1 nodes are available: 1 No preemption victims found for incoming pod.
3m44s       Warning   FailedScheduling    pod/swebench-run-25123-6477    0/1 nodes are available: 1 Too many pods. no new claims to deallocate, preemption: 0/1 nodes are available: 1 No preemption victims found for incoming pod.
4m12s       Normal    NotTriggerScaleUp   pod/swebench-run-25123-6477    Pod didn't trigger scale-up:
3m44s       Warning   FailedScheduling    pod/swebench-run-25124-18990   0/1 nodes are available: 1 Too many pods. no new claims to deallocate, preemption: 0/1 nodes are available: 1 No preemption victims found for incoming pod.
4m12s       Normal    NotTriggerScaleUp   pod/swebench-run-25124-18990   Pod didn't trigger scale-up:
3m44s       Warning   FailedScheduling    pod/swebench-run-25125-16102   0/1 nodes are available: 1 Too many pods. no new claims to deallocate, preemption: 0/1 nodes are available: 1 No preemption victims found for incoming pod.
4m22s       Normal    NotTriggerScaleUp   pod/swebench-run-25125-16102   Pod didn't trigger scale-up:
4m22s       Normal    NotTriggerScaleUp   pod/swebench-run-25126-16306   Pod didn't trigger scale-up:
3m44s       Warning   FailedScheduling    pod/swebench-run-25126-16306   0/1 nodes are available: 1 Too many pods. no new claims to deallocate, preemption: 0/1 nodes are available: 1 No preemption victims found for incoming pod.
4m22s       Normal    NotTriggerScaleUp   pod/swebench-run-25127-11420   Pod didn't trigger scale-up:
3m44s       Warning   FailedScheduling    pod/swebench-run-25127-11420   0/1 nodes are available: 1 Too many pods. no new claims to deallocate, preemption: 0/1 nodes are available: 1 No preemption victims found for incoming pod.
4m22s       Normal    NotTriggerScaleUp   pod/swebench-run-25128-19196   Pod didn't trigger scale-up:
3m44s       Warning   FailedScheduling    pod/swebench-run-25128-19196   0/1 nodes are available: 1 Too many pods. no new claims to deallocate, preemption: 0/1 nodes are available: 1 No preemption victims found for incoming pod.
4m22s       Normal    NotTriggerScaleUp   pod/swebench-run-25129-25834   Pod didn't trigger scale-up:
3m44s       Warning   FailedScheduling    pod/swebench-run-25129-25834   0/1 nodes are available: 1 Too many pods. no new claims to deallocate, preemption: 0/1 nodes are available: 1 No preemption victims found for incoming pod.
3m44s       Warning   FailedScheduling    pod/swebench-run-25130-912     0/1 nodes are available: 1 Too many pods. no new claims to deallocate, preemption: 0/1 nodes are available: 1 No preemption victims found for incoming pod.
4m12s       Normal    NotTriggerScaleUp   pod/swebench-run-25130-912     Pod didn't trigger scale-up:
4m12s       Normal    NotTriggerScaleUp   pod/swebench-run-25131-14035   Pod didn't trigger scale-up:
3m44s       Warning   FailedScheduling    pod/swebench-run-25131-14035   0/1 nodes are available: 1 Too many pods. no new claims to deallocate, preemption: 0/1 nodes are available: 1 No preemption victims found for incoming pod.
4m22s       Normal    NotTriggerScaleUp   pod/swebench-run-25132-10681   Pod didn't trigger scale-up:
3m44s       Warning   FailedScheduling    pod/swebench-run-25132-10681   0/1 nodes are available: 1 Too many pods. no new claims to deallocate, preemption: 0/1 nodes are available: 1 No preemption victims found for incoming pod.
4m22s       Normal    NotTriggerScaleUp   pod/swebench-run-25133-29210   Pod didn't trigger scale-up:
3m44s       Warning   FailedScheduling    pod/swebench-run-25133-29210   0/1 nodes are available: 1 Too many pods. no new claims to deallocate, preemption: 0/1 nodes are available: 1 No preemption victims found for incoming pod.
3m44s       Warning   FailedScheduling    pod/swebench-run-25134-5239    0/1 nodes are available: 1 Too many pods. no new claims to deallocate, preemption: 0/1 nodes are available: 1 No preemption victims found for incoming pod.
4m12s       Normal    NotTriggerScaleUp   pod/swebench-run-25134-5239    Pod didn't trigger scale-up:
4m12s       Normal    NotTriggerScaleUp   pod/swebench-run-25135-10518   Pod didn't trigger scale-up:
3m44s       Warning   FailedScheduling    pod/swebench-run-25135-10518   0/1 nodes are available: 1 Too many pods. no new claims to deallocate, preemption: 0/1 nodes are available: 1 No preemption victims found for incoming pod.
3m44s       Warning   FailedScheduling    pod/swebench-run-25136-10228   0/1 nodes are available: 1 Too many pods. no new claims to deallocate, preemption: 0/1 nodes are available: 1 No preemption victims found for incoming pod.
4m12s       Normal    NotTriggerScaleUp   pod/swebench-run-25136-10228   Pod didn't trigger scale-up:
4m12s       Normal    NotTriggerScaleUp   pod/swebench-run-25137-17771   Pod didn't trigger scale-up:
3m44s       Warning   FailedScheduling    pod/swebench-run-25137-17771   0/1 nodes are available: 1 Too many pods. no new claims to deallocate, preemption: 0/1 nodes are available: 1 No preemption victims found for incoming pod.
3m44s       Warning   FailedScheduling    pod/swebench-run-25138-14252   0/1 nodes are available: 1 Too many pods. no new claims to deallocate, preemption: 0/1 nodes are available: 1 No preemption victims found for incoming pod.
4m12s       Normal    NotTriggerScaleUp   pod/swebench-run-25138-14252   Pod didn't trigger scale-up:
4m12s       Normal    NotTriggerScaleUp   pod/swebench-run-25139-1975    Pod didn't trigger scale-up:
3m44s       Warning   FailedScheduling    pod/swebench-run-25139-1975    0/1 nodes are available: 1 Too many pods. no new claims to deallocate, preemption: 0/1 nodes are available: 1 No preemption victims found for incoming pod.
3m44s       Warning   FailedScheduling    pod/swebench-run-25140-16464   0/1 nodes are available: 1 Too many pods. no new claims to deallocate, preemption: 0/1 nodes are available: 1 No preemption victims found for incoming pod.
4m12s       Normal    NotTriggerScaleUp   pod/swebench-run-25140-16464   Pod didn't trigger scale-up:
3m44s       Warning   FailedScheduling    pod/swebench-run-25141-8708    0/1 nodes are available: 1 Too many pods. no new claims to deallocate, preemption: 0/1 nodes are available: 1 No preemption victims found for incoming pod.
4m12s       Normal    NotTriggerScaleUp   pod/swebench-run-25141-8708    Pod didn't trigger scale-up:
4m12s       Normal    NotTriggerScaleUp   pod/swebench-run-25142-25322   Pod didn't trigger scale-up:
3m44s       Warning   FailedScheduling    pod/swebench-run-25142-25322   0/1 nodes are available: 1 Too many pods. no new claims to deallocate, preemption: 0/1 nodes are available: 1 No preemption victims found for incoming pod.
4m12s       Normal    NotTriggerScaleUp   pod/swebench-run-25143-20064   Pod didn't trigger scale-up:
3m44s       Warning   FailedScheduling    pod/swebench-run-25143-20064   0/1 nodes are available: 1 Too many pods. no new claims to deallocate, preemption: 0/1 nodes are available: 1 No preemption victims found for incoming pod.
4m12s       Normal    NotTriggerScaleUp   pod/swebench-run-25144-19042   Pod didn't trigger scale-up:
3m44s       Warning   FailedScheduling    pod/swebench-run-25144-19042   0/1 nodes are available: 1 Too many pods. no new claims to deallocate, preemption: 0/1 nodes are available: 1 No preemption victims found for incoming pod.
4m12s       Normal    NotTriggerScaleUp   pod/swebench-run-25145-17561   Pod didn't trigger scale-up:
3m44s       Warning   FailedScheduling    pod/swebench-run-25145-17561   0/1 nodes are available: 1 Too many pods. no new claims to deallocate, preemption: 0/1 nodes are available: 1 No preemption victims found for incoming pod.
3m44s       Warning   FailedScheduling    pod/swebench-run-25146-7774    0/1 nodes are available: 1 Too many pods. no new claims to deallocate, preemption: 0/1 nodes are available: 1 No preemption victims found for incoming pod.
4m1s        Normal    NotTriggerScaleUp   pod/swebench-run-25146-7774    Pod didn't trigger scale-up:
3m44s       Warning   FailedScheduling    pod/swebench-run-25147-30051   0/1 nodes are available: 1 Too many pods. no new claims to deallocate, preemption: 0/1 nodes are available: 1 No preemption victims found for incoming pod.
4m12s       Normal    NotTriggerScaleUp   pod/swebench-run-25147-30051   Pod didn't trigger scale-up:
3m44s       Warning   FailedScheduling    pod/swebench-run-25148-14068   0/1 nodes are available: 1 Too many pods. no new claims to deallocate, preemption: 0/1 nodes are available: 1 No preemption victims found for incoming pod.
4m1s        Normal    NotTriggerScaleUp   pod/swebench-run-25148-14068   Pod didn't trigger scale-up:
3m44s       Warning   FailedScheduling    pod/swebench-run-25149-15420   0/1 nodes are available: 1 Too many pods. no new claims to deallocate, preemption: 0/1 nodes are available: 1 No preemption victims found for incoming pod.
4m1s        Normal    NotTriggerScaleUp   pod/swebench-run-25149-15420   Pod didn't trigger scale-up:
4m12s       Normal    NotTriggerScaleUp   pod/swebench-run-25150-16757   Pod didn't trigger scale-up:
3m44s       Warning   FailedScheduling    pod/swebench-run-25150-16757   0/1 nodes are available: 1 Too many pods. no new claims to deallocate, preemption: 0/1 nodes are available: 1 No preemption victims found for incoming pod.
3m44s       Warning   FailedScheduling    pod/swebench-run-25151-13477   0/1 nodes are available: 1 Too many pods. no new claims to deallocate, preemption: 0/1 nodes are available: 1 No preemption victims found for incoming pod.
4m12s       Normal    NotTriggerScaleUp   pod/swebench-run-25151-13477   Pod didn't trigger scale-up:
4m12s       Normal    NotTriggerScaleUp   pod/swebench-run-25152-9801    Pod didn't trigger scale-up:
3m44s       Warning   FailedScheduling    pod/swebench-run-25152-9801    0/1 nodes are available: 1 Too many pods. no new claims to deallocate, preemption: 0/1 nodes are available: 1 No preemption victims found for incoming pod.
3m44s       Warning   FailedScheduling    pod/swebench-run-25153-20439   0/1 nodes are available: 1 Too many pods. no new claims to deallocate, preemption: 0/1 nodes are available: 1 No preemption victims found for incoming pod.
4m1s        Normal    NotTriggerScaleUp   pod/swebench-run-25153-20439   Pod didn't trigger scale-up:
3m44s       Warning   FailedScheduling    pod/swebench-run-25154-16151   0/1 nodes are available: 1 Too many pods. no new claims to deallocate, preemption: 0/1 nodes are available: 1 No preemption victims found for incoming pod.
4m1s        Normal    NotTriggerScaleUp   pod/swebench-run-25154-16151   Pod didn't trigger scale-up:
3m44s       Warning   FailedScheduling    pod/swebench-run-25155-29686   0/1 nodes are available: 1 Too many pods. no new claims to deallocate, preemption: 0/1 nodes are available: 1 No preemption victims found for incoming pod.
4m12s       Normal    NotTriggerScaleUp   pod/swebench-run-25155-29686   Pod didn't trigger scale-up:
3m44s       Warning   FailedScheduling    pod/swebench-run-25156-24254   0/1 nodes are available: 1 Too many pods. no new claims to deallocate, preemption: 0/1 nodes are available: 1 No preemption victims found for incoming pod.
4m42s       Normal    NotTriggerScaleUp   pod/swebench-run-25156-24254   Pod didn't trigger scale-up:
3m44s       Warning   FailedScheduling    pod/swebench-run-25157-15405   0/1 nodes are available: 1 Too many pods. no new claims to deallocate, preemption: 0/1 nodes are available: 1 No preemption victims found for incoming pod.
4m42s       Normal    NotTriggerScaleUp   pod/swebench-run-25157-15405   Pod didn't trigger scale-up:
3m44s       Warning   FailedScheduling    pod/swebench-run-25158-32538   0/1 nodes are available: 1 Too many pods. no new claims to deallocate, preemption: 0/1 nodes are available: 1 No preemption victims found for incoming pod.
4m42s       Normal    NotTriggerScaleUp   pod/swebench-run-25158-32538   Pod didn't trigger scale-up:
3m44s       Warning   FailedScheduling    pod/swebench-run-25159-11781   0/1 nodes are available: 1 Too many pods. no new claims to deallocate, preemption: 0/1 nodes are available: 1 No preemption victims found for incoming pod.
4m42s       Normal    NotTriggerScaleUp   pod/swebench-run-25159-11781   Pod didn't trigger scale-up:
3m44s       Warning   FailedScheduling    pod/swebench-run-25160-4140    0/1 nodes are available: 1 Too many pods. no new claims to deallocate, preemption: 0/1 nodes are available: 1 No preemption victims found for incoming pod.
4m42s       Normal    NotTriggerScaleUp   pod/swebench-run-25160-4140    Pod didn't trigger scale-up:
3m44s       Warning   FailedScheduling    pod/swebench-run-25161-12955   0/1 nodes are available: 1 Too many pods. no new claims to deallocate, preemption: 0/1 nodes are available: 1 No preemption victims found for incoming pod.
4m42s       Normal    NotTriggerScaleUp   pod/swebench-run-25161-12955   Pod didn't trigger scale-up:
4m32s       Normal    NotTriggerScaleUp   pod/swebench-run-25162-15855   Pod didn't trigger scale-up:
3m44s       Warning   FailedScheduling    pod/swebench-run-25162-15855   0/1 nodes are available: 1 Too many pods. no new claims to deallocate, preemption: 0/1 nodes are available: 1 No preemption victims found for incoming pod.
3m44s       Warning   FailedScheduling    pod/swebench-run-25163-26312   0/1 nodes are available: 1 Too many pods. no new claims to deallocate, preemption: 0/1 nodes are available: 1 No preemption victims found for incoming pod.
4m32s       Normal    NotTriggerScaleUp   pod/swebench-run-25163-26312   Pod didn't trigger scale-up:
4m32s       Normal    NotTriggerScaleUp   pod/swebench-run-25164-23237   Pod didn't trigger scale-up:
3m44s       Warning   FailedScheduling    pod/swebench-run-25164-23237   0/1 nodes are available: 1 Too many pods. no new claims to deallocate, preemption: 0/1 nodes are available: 1 No preemption victims found for incoming pod.
3m44s       Warning   FailedScheduling    pod/swebench-run-25165-5273    0/1 nodes are available: 1 Too many pods. no new claims to deallocate, preemption: 0/1 nodes are available: 1 No preemption victims found for incoming pod.
4m32s       Normal    NotTriggerScaleUp   pod/swebench-run-25165-5273    Pod didn't trigger scale-up:
4m32s       Normal    NotTriggerScaleUp   pod/swebench-run-25166-1966    Pod didn't trigger scale-up:
3m44s       Warning   FailedScheduling    pod/swebench-run-25166-1966    0/1 nodes are available: 1 Too many pods. no new claims to deallocate, preemption: 0/1 nodes are available: 1 No preemption victims found for incoming pod.
3m44s       Warning   FailedScheduling    pod/swebench-run-25167-25539   0/1 nodes are available: 1 Too many pods. no new claims to deallocate, preemption: 0/1 nodes are available: 1 No preemption victims found for incoming pod.
4m22s       Normal    NotTriggerScaleUp   pod/swebench-run-25167-25539   Pod didn't trigger scale-up:
3m44s       Warning   FailedScheduling    pod/swebench-run-25168-17224   0/1 nodes are available: 1 Too many pods. no new claims to deallocate, preemption: 0/1 nodes are available: 1 No preemption victims found for incoming pod.
4m22s       Normal    NotTriggerScaleUp   pod/swebench-run-25168-17224   Pod didn't trigger scale-up:
3m44s       Warning   FailedScheduling    pod/swebench-run-25169-20084   0/1 nodes are available: 1 Too many pods. no new claims to deallocate, preemption: 0/1 nodes are available: 1 No preemption victims found for incoming pod.
4m22s       Normal    NotTriggerScaleUp   pod/swebench-run-25169-20084   Pod didn't trigger scale-up:
3m44s       Warning   FailedScheduling    pod/swebench-run-25170-18255   0/1 nodes are available: 1 Too many pods. no new claims to deallocate, preemption: 0/1 nodes are available: 1 No preemption victims found for incoming pod.
4m22s       Normal    NotTriggerScaleUp   pod/swebench-run-25170-18255   Pod didn't trigger scale-up:
3m44s       Warning   FailedScheduling    pod/swebench-run-25171-26773   0/1 nodes are available: 1 Too many pods. no new claims to deallocate, preemption: 0/1 nodes are available: 1 No preemption victims found for incoming pod.
4m22s       Normal    NotTriggerScaleUp   pod/swebench-run-25171-26773   Pod didn't trigger scale-up:
3m44s       Warning   FailedScheduling    pod/swebench-run-25172-25714   0/1 nodes are available: 1 Too many pods. no new claims to deallocate, preemption: 0/1 nodes are available: 1 No preemption victims found for incoming pod.
4m12s       Normal    NotTriggerScaleUp   pod/swebench-run-25172-25714   Pod didn't trigger scale-up:
4m22s       Normal    NotTriggerScaleUp   pod/swebench-run-25173-10763   Pod didn't trigger scale-up:
3m44s       Warning   FailedScheduling    pod/swebench-run-25173-10763   0/1 nodes are available: 1 Too many pods. no new claims to deallocate, preemption: 0/1 nodes are available: 1 No preemption victims found for incoming pod.
3m44s       Warning   FailedScheduling    pod/swebench-run-25174-8488    0/1 nodes are available: 1 Too many pods. no new claims to deallocate, preemption: 0/1 nodes are available: 1 No preemption victims found for incoming pod.
4m22s       Normal    NotTriggerScaleUp   pod/swebench-run-25174-8488    Pod didn't trigger scale-up:
3m44s       Warning   FailedScheduling    pod/swebench-run-25175-3886    0/1 nodes are available: 1 Too many pods. no new claims to deallocate, preemption: 0/1 nodes are available: 1 No preemption victims found for incoming pod.
4m22s       Normal    NotTriggerScaleUp   pod/swebench-run-25175-3886    Pod didn't trigger scale-up:
3m44s       Warning   FailedScheduling    pod/swebench-run-25176-4648    0/1 nodes are available: 1 Too many pods. no new claims to deallocate, preemption: 0/1 nodes are available: 1 No preemption victims found for incoming pod.
4m12s       Normal    NotTriggerScaleUp   pod/swebench-run-25176-4648    Pod didn't trigger scale-up:
3m44s       Warning   FailedScheduling    pod/swebench-run-25177-18168   0/1 nodes are available: 1 Too many pods. no new claims to deallocate, preemption: 0/1 nodes are available: 1 No preemption victims found for incoming pod.
4m22s       Normal    NotTriggerScaleUp   pod/swebench-run-25177-18168   Pod didn't trigger scale-up:
3m44s       Warning   FailedScheduling    pod/swebench-run-25178-12419   0/1 nodes are available: 1 Too many pods. no new claims to deallocate, preemption: 0/1 nodes are available: 1 No preemption victims found for incoming pod.
4m1s        Normal    NotTriggerScaleUp   pod/swebench-run-25178-12419   Pod didn't trigger scale-up:
4m12s       Normal    NotTriggerScaleUp   pod/swebench-run-25179-12829   Pod didn't trigger scale-up:
3m44s       Warning   FailedScheduling    pod/swebench-run-25179-12829   0/1 nodes are available: 1 Too many pods. no new claims to deallocate, preemption: 0/1 nodes are available: 1 No preemption victims found for incoming pod.
4m12s       Normal    NotTriggerScaleUp   pod/swebench-run-25180-16835   Pod didn't trigger scale-up:
3m44s       Warning   FailedScheduling    pod/swebench-run-25180-16835   0/1 nodes are available: 1 Too many pods. no new claims to deallocate, preemption: 0/1 nodes are available: 1 No preemption victims found for incoming pod.
4m12s       Normal    NotTriggerScaleUp   pod/swebench-run-25181-5608    Pod didn't trigger scale-up:
3m44s       Warning   FailedScheduling    pod/swebench-run-25181-5608    0/1 nodes are available: 1 Too many pods. no new claims to deallocate, preemption: 0/1 nodes are available: 1 No preemption victims found for incoming pod.
3m44s       Warning   FailedScheduling    pod/swebench-run-25182-8306    0/1 nodes are available: 1 Too many pods. no new claims to deallocate, preemption: 0/1 nodes are available: 1 No preemption victims found for incoming pod.
4m12s       Normal    NotTriggerScaleUp   pod/swebench-run-25182-8306    Pod didn't trigger scale-up:
4m12s       Normal    NotTriggerScaleUp   pod/swebench-run-25183-29883   Pod didn't trigger scale-up:
3m44s       Warning   FailedScheduling    pod/swebench-run-25183-29883   0/1 nodes are available: 1 Too many pods. no new claims to deallocate, preemption: 0/1 nodes are available: 1 No preemption victims found for incoming pod.
3m44s       Warning   FailedScheduling    pod/swebench-run-25184-6694    0/1 nodes are available: 1 Too many pods. no new claims to deallocate, preemption: 0/1 nodes are available: 1 No preemption victims found for incoming pod.
4m12s       Normal    NotTriggerScaleUp   pod/swebench-run-25184-6694    Pod didn't trigger scale-up:
3m44s       Warning   FailedScheduling    pod/swebench-run-25185-27697   0/1 nodes are available: 1 Too many pods. no new claims to deallocate, preemption: 0/1 nodes are available: 1 No preemption victims found for incoming pod.
4m12s       Normal    NotTriggerScaleUp   pod/swebench-run-25185-27697   Pod didn't trigger scale-up:
4m12s       Normal    NotTriggerScaleUp   pod/swebench-run-25186-7987    Pod didn't trigger scale-up:
3m44s       Warning   FailedScheduling    pod/swebench-run-25186-7987    0/1 nodes are available: 1 Too many pods. no new claims to deallocate, preemption: 0/1 nodes are available: 1 No preemption victims found for incoming pod.
3m44s       Warning   FailedScheduling    pod/swebench-run-25187-19136   0/1 nodes are available: 1 Too many pods. no new claims to deallocate, preemption: 0/1 nodes are available: 1 No preemption victims found for incoming pod.
4m12s       Normal    NotTriggerScaleUp   pod/swebench-run-25187-19136   Pod didn't trigger scale-up:
4m12s       Normal    NotTriggerScaleUp   pod/swebench-run-25188-21514   Pod didn't trigger scale-up:
3m44s       Warning   FailedScheduling    pod/swebench-run-25188-21514   0/1 nodes are available: 1 Too many pods. no new claims to deallocate, preemption: 0/1 nodes are available: 1 No preemption victims found for incoming pod.
3m44s       Warning   FailedScheduling    pod/swebench-run-25189-6264    0/1 nodes are available: 1 Too many pods. no new claims to deallocate, preemption: 0/1 nodes are available: 1 No preemption victims found for incoming pod.
4m12s       Normal    NotTriggerScaleUp   pod/swebench-run-25189-6264    Pod didn't trigger scale-up:
4m12s       Normal    NotTriggerScaleUp   pod/swebench-run-25190-14835   Pod didn't trigger scale-up:
3m44s       Warning   FailedScheduling    pod/swebench-run-25190-14835   0/1 nodes are available: 1 Too many pods. no new claims to deallocate, preemption: 0/1 nodes are available: 1 No preemption victims found for incoming pod.
4m12s       Normal    NotTriggerScaleUp   pod/swebench-run-25191-31429   Pod didn't trigger scale-up:
3m44s       Warning   FailedScheduling    pod/swebench-run-25191-31429   0/1 nodes are available: 1 Too many pods. no new claims to deallocate, preemption: 0/1 nodes are available: 1 No preemption victims found for incoming pod.
3m44s       Warning   FailedScheduling    pod/swebench-run-25192-9090    0/1 nodes are available: 1 Too many pods. no new claims to deallocate, preemption: 0/1 nodes are available: 1 No preemption victims found for incoming pod.
4m1s        Normal    NotTriggerScaleUp   pod/swebench-run-25192-9090    Pod didn't trigger scale-up:
3m44s       Warning   FailedScheduling    pod/swebench-run-25193-26322   0/1 nodes are available: 1 Too many pods. no new claims to deallocate, preemption: 0/1 nodes are available: 1 No preemption victims found for incoming pod.
4m1s        Normal    NotTriggerScaleUp   pod/swebench-run-25193-26322   Pod didn't trigger scale-up:
4m12s       Normal    NotTriggerScaleUp   pod/swebench-run-25194-20601   Pod didn't trigger scale-up:
3m44s       Warning   FailedScheduling    pod/swebench-run-25194-20601   0/1 nodes are available: 1 Too many pods. no new claims to deallocate, preemption: 0/1 nodes are available: 1 No preemption victims found for incoming pod.
4m12s       Normal    NotTriggerScaleUp   pod/swebench-run-25195-19575   Pod didn't trigger scale-up:
3m44s       Warning   FailedScheduling    pod/swebench-run-25195-19575   0/1 nodes are available: 1 Too many pods. no new claims to deallocate, preemption: 0/1 nodes are available: 1 No preemption victims found for incoming pod.
3m44s       Warning   FailedScheduling    pod/swebench-run-25196-9278    0/1 nodes are available: 1 Too many pods. no new claims to deallocate, preemption: 0/1 nodes are available: 1 No preemption victims found for incoming pod.
4m1s        Normal    NotTriggerScaleUp   pod/swebench-run-25196-9278    Pod didn't trigger scale-up:
3m44s       Warning   FailedScheduling    pod/swebench-run-25197-13364   0/1 nodes are available: 1 Too many pods. no new claims to deallocate, preemption: 0/1 nodes are available: 1 No preemption victims found for incoming pod.
4m1s        Normal    NotTriggerScaleUp   pod/swebench-run-25197-13364   Pod didn't trigger scale-up:
3m44s       Warning   FailedScheduling    pod/swebench-run-25198-13729   0/1 nodes are available: 1 Too many pods. no new claims to deallocate, preemption: 0/1 nodes are available: 1 No preemption victims found for incoming pod.
4m12s       Normal    NotTriggerScaleUp   pod/swebench-run-25198-13729   Pod didn't trigger scale-up:
4m12s       Normal    NotTriggerScaleUp   pod/swebench-run-25199-15281   Pod didn't trigger scale-up:
3m44s       Warning   FailedScheduling    pod/swebench-run-25199-15281   0/1 nodes are available: 1 Too many pods. no new claims to deallocate, preemption: 0/1 nodes are available: 1 No preemption victims found for incoming pod.
4m12s       Normal    NotTriggerScaleUp   pod/swebench-run-25200-11382   Pod didn't trigger scale-up:
3m44s       Warning   FailedScheduling    pod/swebench-run-25200-11382   0/1 nodes are available: 1 Too many pods. no new claims to deallocate, preemption: 0/1 nodes are available: 1 No preemption victims found for incoming pod.
3m44s       Warning   FailedScheduling    pod/swebench-run-25201-15511   0/1 nodes are available: 1 Too many pods. no new claims to deallocate, preemption: 0/1 nodes are available: 1 No preemption victims found for incoming pod.
4m1s        Normal    NotTriggerScaleUp   pod/swebench-run-25201-15511   Pod didn't trigger scale-up:
3m44s       Warning   FailedScheduling    pod/swebench-run-25202-12128   0/1 nodes are available: 1 Too many pods. no new claims to deallocate, preemption: 0/1 nodes are available: 1 No preemption victims found for incoming pod.
4m12s       Normal    NotTriggerScaleUp   pod/swebench-run-25202-12128   Pod didn't trigger scale-up:
4m12s       Normal    NotTriggerScaleUp   pod/swebench-run-25203-6332    Pod didn't trigger scale-up:
3m44s       Warning   FailedScheduling    pod/swebench-run-25203-6332    0/1 nodes are available: 1 Too many pods. no new claims to deallocate, preemption: 0/1 nodes are available: 1 No preemption victims found for incoming pod.
3m44s       Warning   FailedScheduling    pod/swebench-run-25204-15314   0/1 nodes are available: 1 Too many pods. no new claims to deallocate, preemption: 0/1 nodes are available: 1 No preemption victims found for incoming pod.
4m1s        Normal    NotTriggerScaleUp   pod/swebench-run-25204-15314   Pod didn't trigger scale-up:
3m44s       Warning   FailedScheduling    pod/swebench-run-25205-8983    0/1 nodes are available: 1 Too many pods. no new claims to deallocate, preemption: 0/1 nodes are available: 1 No preemption victims found for incoming pod.
4m12s       Normal    NotTriggerScaleUp   pod/swebench-run-25205-8983    Pod didn't trigger scale-up:
